Workbook

Sheet 国内総計
C1: 2024 | D1: 45322 | E1: 45350 | F1: 45382 | G1: 45412 | H1: 45443 | I1: 45473 | J1: 45504 | K1: 2025 | L1: 45535 | M1: 45565 | N1: 45596 | O1: 45626 | P1: 45657 | Q1: 45688 | R1: 45716 | S1: 45747 | T1: 45777 | U1: 45808 | V1: 45838 | W1: 45869 | X1: 2026 | Y1: 45900 | Z1: 45901 | AA1: 45931 | AB1: 45962 | AC1: 45992 | AD1: 46023 | AE1: 46054 | AF1: 46082 | AG1: 46113 | AH1: 46143 | AI1: 46174 | AJ1: 46204
A2: 総計
A3: 取得価格 | B3: 円 | C3: =SUM('SEA A棟1508:海老名Ⅱ1431'!C3) -> 2836236947 | D3: =SUM('SEA A棟1508:海老名Ⅱ1431'!D3) -> 0 | E3: =SUM('SEA A棟1508:海老名Ⅱ1431'!E3) -> 0 | F3: =SUM('SEA A棟1508:海老名Ⅱ1431'!F3) -> 0 | G3: =SUM('SEA A棟1508:海老名Ⅱ1431'!G3) -> 0 | H3: =SUM('SEA A棟1508:海老名Ⅱ1431'!H3) -> 0 | I3: =SUM('SEA A棟1508:海老名Ⅱ1431'!I3) -> 0 | J3: =SUM('SEA A棟1508:海老名Ⅱ1431'!J3) -> 0 | L3: =SUM('SEA A棟1508:海老名Ⅱ1431'!L3) -> 0 | M3: =SUM('SEA A棟1508:海老名Ⅱ1431'!M3) -> 0 | N3: =SUM('SEA A棟1508:海老名Ⅱ1431'!N3) -> 0 | O3: =SUM('SEA A棟1508:海老名Ⅱ1431'!O3) -> 0 | P3: =SUM('SEA A棟1508:海老名Ⅱ1431'!P3) -> 0 | Q3: =SUM('SEA A棟1508:海老名Ⅱ1431'!Q3) -> 0 | R3: =SUM('SEA A棟1508:海老名Ⅱ1431'!R3) -> 0 | S3: =SUM('SEA A棟1508:海老名Ⅱ1431'!S3) -> 0 | ... W3: =SUM('SEA A棟1508:海老名Ⅱ1431'!W3) -> 0 | Y3: =SUM('SEA A棟1508:海老名Ⅱ1431'!Y3) -> 0 | Z3: =SUM('SEA A棟1508:海老名Ⅱ1431'!Z3) -> 0 | AA3: =SUM('SEA A棟1508:海老名Ⅱ1431'!AA3) -> 0 | AB3: =SUM('SEA A棟1508:海老名Ⅱ1431'!AB3) -> 0 | AC3: =SUM('SEA A棟1508:海老名Ⅱ1431'!AC3) -> 0 | AD3: =SUM('SEA A棟1508:海老名Ⅱ1431'!AD3) -> 0 | AE3: =SUM('SEA A棟1508:海老名Ⅱ1431'!AE3) -> 0 | AF3: =SUM('SEA A棟1508:海老名Ⅱ1431'!AF3) -> 0 | ... AJ3: =SUM('SEA A棟1508:海老名Ⅱ1431'!AJ3) -> 0
A4: 賃料収入 | B4: 円 | C4: =SUM('SEA A棟1508:海老名Ⅱ1431'!C4) -> 3972000 | D4: =SUM('SEA A棟1508:海老名Ⅱ1431'!D4) -> 0 | E4: =SUM('SEA A棟1508:海老名Ⅱ1431'!E4) -> 0 | F4: =SUM('SEA A棟1508:海老名Ⅱ1431'!F4) -> 197419 | G4: =SUM('SEA A棟1508:海老名Ⅱ1431'!G4) -> 255000 | H4: =SUM('SEA A棟1508:海老名Ⅱ1431'!H4) -> 255000 | I4: =SUM('SEA A棟1508:海老名Ⅱ1431'!I4) -> 319333 | J4: =SUM('SEA A棟1508:海老名Ⅱ1431'!J4) -> 2182136 | L4: =SUM('SEA A棟1508:海老名Ⅱ1431'!L4) -> 1903851 | M4: =SUM('SEA A棟1508:海老名Ⅱ1431'!M4) -> 1899067 | N4: =SUM('SEA A棟1508:海老名Ⅱ1431'!N4) -> 2810593 | O4: =SUM('SEA A棟1508:海老名Ⅱ1431'!O4) -> 2420400 | P4: =SUM('SEA A棟1508:海老名Ⅱ1431'!P4) -> 3512835 | Q4: =SUM('SEA A棟1508:海老名Ⅱ1431'!Q4) -> 3329200 | R4: =SUM('SEA A棟1508:海老名Ⅱ1431'!R4) -> 4580400 | S4: =SUM('SEA A棟1508:海老名Ⅱ1431'!S4) -> 4017100 | ... W4: =SUM('SEA A棟1508:海老名Ⅱ1431'!W4) -> 4017100 | Y4: =SUM('SEA A棟1508:海老名Ⅱ1431'!Y4) -> 4017100 | Z4: =SUM('SEA A棟1508:海老名Ⅱ1431'!Z4) -> 4617100 | AA4: =SUM('SEA A棟1508:海老名Ⅱ1431'!AA4) -> 4617100 | AB4: =SUM('SEA A棟1508:海老名Ⅱ1431'!AB4) -> 4617100 | AC4: =SUM('SEA A棟1508:海老名Ⅱ1431'!AC4) -> 5085133 | AD4: =SUM('SEA A棟1508:海老名Ⅱ1431'!AD4) -> 4852200 | AE4: =SUM('SEA A棟1508:海老名Ⅱ1431'!AE4) -> 4852200 | AF4: =SUM('SEA A棟1508:海老名Ⅱ1431'!AF4) -> 4059200 | ... AJ4: =SUM('SEA A棟1508:海老名Ⅱ1431'!AJ4) -> 0
A5: 減価償却費 | B5: 円 | C5: =SUM('SEA A棟1508:海老名Ⅱ1431'!C5) -> 0 | D5: =SUM('SEA A棟1508:海老名Ⅱ1431'!D5) -> 413465 | E5: =SUM('SEA A棟1508:海老名Ⅱ1431'!E5) -> 413460 | F5: =SUM('SEA A棟1508:海老名Ⅱ1431'!F5) -> 484384 | G5: =SUM('SEA A棟1508:海老名Ⅱ1431'!G5) -> 711183 | H5: =SUM('SEA A棟1508:海老名Ⅱ1431'!H5) -> 711183 | I5: =SUM('SEA A棟1508:海老名Ⅱ1431'!I5) -> 969520 | J5: =SUM('SEA A棟1508:海老名Ⅱ1431'!J5) -> 969536 | L5: =SUM('SEA A棟1508:海老名Ⅱ1431'!L5) -> 1078839 | M5: =SUM('SEA A棟1508:海老名Ⅱ1431'!M5) -> 1138595 | N5: =SUM('SEA A棟1508:海老名Ⅱ1431'!N5) -> 1138595 | O5: =SUM('SEA A棟1508:海老名Ⅱ1431'!O5) -> 1138595 | P5: =SUM('SEA A棟1508:海老名Ⅱ1431'!P5) -> 1329584 | Q5: =SUM('SEA A棟1508:海老名Ⅱ1431'!Q5) -> 1329618 | R5: =SUM('SEA A棟1508:海老名Ⅱ1431'!R5) -> 1329584 | S5: =SUM('SEA A棟1508:海老名Ⅱ1431'!S5) -> 1329584 | ... W5: =SUM('SEA A棟1508:海老名Ⅱ1431'!W5) -> 1329627 | Y5: =SUM('SEA A棟1508:海老名Ⅱ1431'!Y5) -> 1575340 | Z5: =SUM('SEA A棟1508:海老名Ⅱ1431'!Z5) -> 2456033 | AA5: =SUM('SEA A棟1508:海老名Ⅱ1431'!AA5) -> 2456033 | AB5: =SUM('SEA A棟1508:海老名Ⅱ1431'!AB5) -> 2456033 | AC5: =SUM('SEA A棟1508:海老名Ⅱ1431'!AC5) -> 2456033 | AD5: =SUM('SEA A棟1508:海老名Ⅱ1431'!AD5) -> 2571908 | AE5: =SUM('SEA A棟1508:海老名Ⅱ1431'!AE5) -> 2571865 | AF5: =SUM('SEA A棟1508:海老名Ⅱ1431'!AF5) -> 2571865 | ... AJ5: =SUM('SEA A棟1508:海老名Ⅱ1431'!AJ5) -> 2571918
A6: 残存簿価 | B6: 円 | C6: =SUM('SEA A棟1508:海老名Ⅱ1431'!C6) -> 1287562557 | D6: =SUM('SEA A棟1508:海老名Ⅱ1431'!D6) -> 225111028 | E6: =SUM('SEA A棟1508:海老名Ⅱ1431'!E6) -> 224697568 | F6: =SUM('SEA A棟1508:海老名Ⅱ1431'!F6) -> 262899342 | G6: =SUM('SEA A棟1508:海老名Ⅱ1431'!G6) -> 385898402 | H6: =SUM('SEA A棟1508:海老名Ⅱ1431'!H6) -> 385187219 | I6: =SUM('SEA A棟1508:海老名Ⅱ1431'!I6) -> 525129128 | J6: =SUM('SEA A棟1508:海老名Ⅱ1431'!J6) -> 524159592 | L6: =SUM('SEA A棟1508:海老名Ⅱ1431'!L6) -> 582709676 | M6: =SUM('SEA A棟1508:海老名Ⅱ1431'!M6) -> 614165364 | N6: =SUM('SEA A棟1508:海老名Ⅱ1431'!N6) -> 613026769 | O6: =SUM('SEA A棟1508:海老名Ⅱ1431'!O6) -> 611888174 | P6: =SUM('SEA A棟1508:海老名Ⅱ1431'!P6) -> 714734546 | Q6: =SUM('SEA A棟1508:海老名Ⅱ1431'!Q6) -> 713404928 | R6: =SUM('SEA A棟1508:海老名Ⅱ1431'!R6) -> 712075344 | S6: =SUM('SEA A棟1508:海老名Ⅱ1431'!S6) -> 710745760 | ... W6: =SUM('SEA A棟1508:海老名Ⅱ1431'!W6) -> 767878202 | Y6: =SUM('SEA A棟1508:海老名Ⅱ1431'!Y6) -> 1265365902 | Z6: =SUM('SEA A棟1508:海老名Ⅱ1431'!Z6) -> 1262909869 | AA6: =SUM('SEA A棟1508:海老名Ⅱ1431'!AA6) -> 1260453836 | AB6: =SUM('SEA A棟1508:海老名Ⅱ1431'!AB6) -> 1257997803 | AC6: =SUM('SEA A棟1508:海老名Ⅱ1431'!AC6) -> 1255541770 | AD6: =SUM('SEA A棟1508:海老名Ⅱ1431'!AD6) -> 1252969862 | AE6: =SUM('SEA A棟1508:海老名Ⅱ1431'!AE6) -> 1250397997 | AF6: =SUM('SEA A棟1508:海老名Ⅱ1431'!AF6) -> 1247826132 | ... AJ6: =SUM('SEA A棟1508:海老名Ⅱ1431'!AJ6) -> 1237538619
A7: 管理費・修繕積立金等 | B7: 円 | C7: =SUM('SEA A棟1508:海老名Ⅱ1431'!C7) -> 701401 | D7: =SUM('SEA A棟1508:海老名Ⅱ1431'!D7) -> 82476 | E7: =SUM('SEA A棟1508:海老名Ⅱ1431'!E7) -> 198660 | F7: =SUM('SEA A棟1508:海老名Ⅱ1431'!F7) -> 230177 | G7: =SUM('SEA A棟1508:海老名Ⅱ1431'!G7) -> 239370 | H7: =SUM('SEA A棟1508:海老名Ⅱ1431'!H7) -> 406890 | I7: =SUM('SEA A棟1508:海老名Ⅱ1431'!I7) -> 424548 | J7: =SUM('SEA A棟1508:海老名Ⅱ1431'!J7) -> 472262 | L7: =SUM('SEA A棟1508:海老名Ⅱ1431'!L7) -> 496842 | M7: =SUM('SEA A棟1508:海老名Ⅱ1431'!M7) -> 516516 | N7: =SUM('SEA A棟1508:海老名Ⅱ1431'!N7) -> 527160 | O7: =SUM('SEA A棟1508:海老名Ⅱ1431'!O7) -> 527160 | P7: =SUM('SEA A棟1508:海老名Ⅱ1431'!P7) -> 527160 | Q7: =SUM('SEA A棟1508:海老名Ⅱ1431'!Q7) -> 597235 | R7: =SUM('SEA A棟1508:海老名Ⅱ1431'!R7) -> 610711 | S7: =SUM('SEA A棟1508:海老名Ⅱ1431'!S7) -> 779682 | ... W7: =SUM('SEA A棟1508:海老名Ⅱ1431'!W7) -> 685541 | Y7: =SUM('SEA A棟1508:海老名Ⅱ1431'!Y7) -> 695031 | Z7: =SUM('SEA A棟1508:海老名Ⅱ1431'!Z7) -> 695031 | AA7: =SUM('SEA A棟1508:海老名Ⅱ1431'!AA7) -> 717411 | AB7: =SUM('SEA A棟1508:海老名Ⅱ1431'!AB7) -> 722011 | AC7: =SUM('SEA A棟1508:海老名Ⅱ1431'!AC7) -> 1060411 | AD7: =SUM('SEA A棟1508:海老名Ⅱ1431'!AD7) -> 1060411 | AE7: =SUM('SEA A棟1508:海老名Ⅱ1431'!AE7) -> 722011 | AF7: =SUM('SEA A棟1508:海老名Ⅱ1431'!AF7) -> 767579 | ... AJ7: =SUM('SEA A棟1508:海老名Ⅱ1431'!AJ7) -> 699631
A8: 管理委託手数料 | B8: 円 | C8: =SUM('SEA A棟1508:海老名Ⅱ1431'!C8) -> 0 | D8: =SUM('SEA A棟1508:海老名Ⅱ1431'!D8) -> 0 | E8: =SUM('SEA A棟1508:海老名Ⅱ1431'!E8) -> 0 | F8: =SUM('SEA A棟1508:海老名Ⅱ1431'!F8) -> 0 | G8: =SUM('SEA A棟1508:海老名Ⅱ1431'!G8) -> 0 | H8: =SUM('SEA A棟1508:海老名Ⅱ1431'!H8) -> 0 | I8: =SUM('SEA A棟1508:海老名Ⅱ1431'!I8) -> 0 | J8: =SUM('SEA A棟1508:海老名Ⅱ1431'!J8) -> 3285 | L8: =SUM('SEA A棟1508:海老名Ⅱ1431'!L8) -> 26950 | M8: =SUM('SEA A棟1508:海老名Ⅱ1431'!M8) -> 33040 | N8: =SUM('SEA A棟1508:海老名Ⅱ1431'!N8) -> 47673 | O8: =SUM('SEA A棟1508:海老名Ⅱ1431'!O8) -> 48946 | P8: =SUM('SEA A棟1508:海老名Ⅱ1431'!P8) -> 53200 | Q8: =SUM('SEA A棟1508:海老名Ⅱ1431'!Q8) -> 68922 | R8: =SUM('SEA A棟1508:海老名Ⅱ1431'!R8) -> 81519 | S8: =SUM('SEA A棟1508:海老名Ⅱ1431'!S8) -> 84038 | ... W8: =SUM('SEA A棟1508:海老名Ⅱ1431'!W8) -> 84038 | Y8: =SUM('SEA A棟1508:海老名Ⅱ1431'!Y8) -> 84038 | Z8: =SUM('SEA A棟1508:海老名Ⅱ1431'!Z8) -> 84038 | AA8: =SUM('SEA A棟1508:海老名Ⅱ1431'!AA8) -> 84038 | AB8: =SUM('SEA A棟1508:海老名Ⅱ1431'!AB8) -> 84038 | AC8: =SUM('SEA A棟1508:海老名Ⅱ1431'!AC8) -> 89384 | AD8: =SUM('SEA A棟1508:海老名Ⅱ1431'!AD8) -> 89210 | AE8: =SUM('SEA A棟1508:海老名Ⅱ1431'!AE8) -> 89210 | AF8: =SUM('SEA A棟1508:海老名Ⅱ1431'!AF8) -> 89210 | ... AJ8: =SUM('SEA A棟1508:海老名Ⅱ1431'!AJ8) -> 0
A9: 諸経費（税金、募集経費等） | B9: 円 | C9: =SUM('SEA A棟1508:海老名Ⅱ1431'!C9) -> 95310527 | D9: =SUM('SEA A棟1508:海老名Ⅱ1431'!D9) -> 1342000 | E9: =SUM('SEA A棟1508:海老名Ⅱ1431'!E9) -> 0 | F9: =SUM('SEA A棟1508:海老名Ⅱ1431'!F9) -> 143712 | G9: =SUM('SEA A棟1508:海老名Ⅱ1431'!G9) -> 1276000 | H9: =SUM('SEA A棟1508:海老名Ⅱ1431'!H9) -> 976800 | I9: =SUM('SEA A棟1508:海老名Ⅱ1431'!I9) -> 148877 | J9: =SUM('SEA A棟1508:海老名Ⅱ1431'!J9) -> 854700 | L9: =SUM('SEA A棟1508:海老名Ⅱ1431'!L9) -> 519266 | M9: =SUM('SEA A棟1508:海老名Ⅱ1431'!M9) -> 484002 | N9: =SUM('SEA A棟1508:海老名Ⅱ1431'!N9) -> 1038071 | O9: =SUM('SEA A棟1508:海老名Ⅱ1431'!O9) -> 3139 | P9: =SUM('SEA A棟1508:海老名Ⅱ1431'!P9) -> 1385516 | Q9: =SUM('SEA A棟1508:海老名Ⅱ1431'!Q9) -> 235771 | R9: =SUM('SEA A棟1508:海老名Ⅱ1431'!R9) -> 507013 | S9: =SUM('SEA A棟1508:海老名Ⅱ1431'!S9) -> 183606 | ... W9: =SUM('SEA A棟1508:海老名Ⅱ1431'!W9) -> 7269 | Y9: =SUM('SEA A棟1508:海老名Ⅱ1431'!Y9) -> 8024 | Z9: =SUM('SEA A棟1508:海老名Ⅱ1431'!Z9) -> 3710 | AA9: =SUM('SEA A棟1508:海老名Ⅱ1431'!AA9) -> 11896 | AB9: =SUM('SEA A棟1508:海老名Ⅱ1431'!AB9) -> 12594 | AC9: =SUM('SEA A棟1508:海老名Ⅱ1431'!AC9) -> 16395 | AD9: =SUM('SEA A棟1508:海老名Ⅱ1431'!AD9) -> 12309 | AE9: =SUM('SEA A棟1508:海老名Ⅱ1431'!AE9) -> 15451 | AF9: =SUM('SEA A棟1508:海老名Ⅱ1431'!AF9) -> 3189811 | ... AJ9: =SUM('SEA A棟1508:海老名Ⅱ1431'!AJ9) -> 0
A10: ネット賃貸収入利回り | B10: 円 | C10: =SUM('SEA A棟1508:海老名Ⅱ1431'!C10) -> 0 | D10: =SUM('SEA A棟1508:海老名Ⅱ1431'!D10) -> 0 | E10: =SUM('SEA A棟1508:海老名Ⅱ1431'!E10) -> 0 | F10: =SUM('SEA A棟1508:海老名Ⅱ1431'!F10) -> 0 | G10: =SUM('SEA A棟1508:海老名Ⅱ1431'!G10) -> 0 | H10: =SUM('SEA A棟1508:海老名Ⅱ1431'!H10) -> 0 | I10: =SUM('SEA A棟1508:海老名Ⅱ1431'!I10) -> 0 | J10: =SUM('SEA A棟1508:海老名Ⅱ1431'!J10) -> 0 | L10: =SUM('SEA A棟1508:海老名Ⅱ1431'!L10) -> 0 | M10: =SUM('SEA A棟1508:海老名Ⅱ1431'!M10) -> 0 | N10: =SUM('SEA A棟1508:海老名Ⅱ1431'!N10) -> 0 | O10: =SUM('SEA A棟1508:海老名Ⅱ1431'!O10) -> 0 | P10: =SUM('SEA A棟1508:海老名Ⅱ1431'!P10) -> 0 | Q10: =SUM('SEA A棟1508:海老名Ⅱ1431'!Q10) -> 0 | R10: =SUM('SEA A棟1508:海老名Ⅱ1431'!R10) -> 0 | S10: =SUM('SEA A棟1508:海老名Ⅱ1431'!S10) -> 0 | ... W10: =SUM('SEA A棟1508:海老名Ⅱ1431'!W10) -> 0 | Y10: =SUM('SEA A棟1508:海老名Ⅱ1431'!Y10) -> 0 | Z10: =SUM('SEA A棟1508:海老名Ⅱ1431'!Z10) -> 0 | AA10: =SUM('SEA A棟1508:海老名Ⅱ1431'!AA10) -> 0 | AB10: =SUM('SEA A棟1508:海老名Ⅱ1431'!AB10) -> 0 | AC10: =SUM('SEA A棟1508:海老名Ⅱ1431'!AC10) -> 0 | AD10: =SUM('SEA A棟1508:海老名Ⅱ1431'!AD10) -> 0 | AE10: =SUM('SEA A棟1508:海老名Ⅱ1431'!AE10) -> 0 | AF10: =SUM('SEA A棟1508:海老名Ⅱ1431'!AF10) -> 0 | ... AJ10: =SUM('SEA A棟1508:海老名Ⅱ1431'!AJ10) -> 0
A11: 取得時簿価利回り | B11: 円 | C11: =SUM('SEA A棟1508:海老名Ⅱ1431'!C11) -> 0 | D11: =SUM(D13*12/C3) -> -0.0060268984 | E11: =SUM(E13*12/C3) -> -0.00084052216 | F11: =SUM(F13*12/C3) -> -0.0007466372 | G11: =SUM(G13*12/C3) -> -0.0053325728 | H11: =SUM(H13*12/C3) -> -0.0047754402 | I11: =SUM(I13*12/C3) -> -0.0010750526 | J11: =SUM(J13*12/C3) -> 0.0036043068 | L11: =SUM(L13*12/C3) -> 0.0036419792 | M11: =SUM(M13*12/C3) -> 0.0036619324 | N11: =SUM(N13*12/C3) -> 0.0050673721 | O11: =SUM(O13*12/C3) -> 0.0077898499 | P11: =SUM(P13*12/C3) -> 0.0065451189 | Q11: =SUM(Q13*12/C3) -> 0.010269686 | R11: =SUM(R13*12/C3) -> 0.014305534 | S11: =SUM(S13*12/C3) -> 0.01256499 | T11: =SUM(T13*12/C3) -> 0.014018527 | U11: =SUM(U13*12/C3) -> 0.0043231846 | V11: =SUM(V13*12/C3) -> 0.013709472 | W11: =SUM(W13*12/C3) -> 0.013709371 | Y11: =SUM(Y13*12/C3) -> 0.013666025 | Z11: =SUM(Z13*12/C3) -> 0.016222852 | AA11: =SUM(AA13*12/C3) -> 0.016093528 | AB11: =SUM(AB13*12/C3) -> 0.016071113 | AC11: =SUM(AC13*12/C3) -> 0.016580884 | AD11: =SUM(AD13*12/C3) -> 0.015613378 | AE11: =SUM(AE13*12/C3) -> 0.017031841 | AF11: =SUM(AF13*12/C3) -> 5.3310073e-05 | AG11: =SUM(AG13*12/C3) -> 0.014660714 | AH11: =SUM(AH13*12/C3) -> -0.0029601095 | AI11: =SUM(AI13*12/C3) -> -0.0029601095 | AJ11: =SUM(AJ13*12/C3) -> -0.0029601095
A12: 残存簿価利回り | B12: 円 | C12: =SUM('SEA A棟1508:海老名Ⅱ1431'!C12) -> 0 | D12: =SUM(D13*12/D6) -> -0.075934583 | E12: =SUM(E13*12/E6) -> -0.010609461 | F12: =SUM(F13*12/F6) -> -0.008054946 | G12: =SUM(G13*12/G6) -> -0.039192803 | H12: =SUM(H13*12/H6) -> -0.035162849 | I12: =SUM(I13*12/I6) -> -0.005806389 | J12: =SUM(J13*12/J6) -> 0.019502968 | L12: =SUM(L13*12/L6) -> 0.017726694 | M12: =SUM(M13*12/M6) -> 0.016910931 | N12: =SUM(N13*12/N6) -> 0.023444764 | O12: =SUM(O13*12/O6) -> 0.036107676 | P12: =SUM(P13*12/P6) -> 0.025972591 | Q12: =SUM(Q13*12/Q6) -> 0.040828515 | R12: =SUM(R13*12/R6) -> 0.056979763 | S12: =SUM(S13*12/S6) -> 0.050140697 | ... W12: =SUM(W13*12/W6) -> 0.050636968 | Y12: =SUM(Y13*12/Y6) -> 0.030631522 | Z12: =SUM(Z13*12/Z6) -> 0.036433203 | AA12: =SUM(AA13*12/AA6) -> 0.036213195 | AB12: =SUM(AB13*12/AB6) -> 0.036233357 | AC12: =SUM(AC13*12/AC6) -> 0.037455796 | AD12: =SUM(AD13*12/AD6) -> 0.035342622 | AE12: =SUM(AE13*12/AE6) -> 0.038632768 | AF12: =SUM(AF13*12/AF6) -> 0.00012117073 | ... AJ12: =SUM(AJ13*12/AJ6) -> -0.0067840889
A13: CF | B13: 円 | C13: =SUM('SEA A棟1508:海老名Ⅱ1431'!C13) -> 0 | D13: =SUM('SEA A棟1508:海老名Ⅱ1431'!D13) -> -1424476 | E13: =SUM('SEA A棟1508:海老名Ⅱ1431'!E13) -> -198660 | F13: =SUM('SEA A棟1508:海老名Ⅱ1431'!F13) -> -176470 | G13: =SUM('SEA A棟1508:海老名Ⅱ1431'!G13) -> -1260370 | H13: =SUM('SEA A棟1508:海老名Ⅱ1431'!H13) -> -1128690 | I13: =SUM('SEA A棟1508:海老名Ⅱ1431'!I13) -> -254092 | J13: =SUM('SEA A棟1508:海老名Ⅱ1431'!J13) -> 851889 | K13: =SUM(D13:J13) -> -3590869 | L13: =SUM('SEA A棟1508:海老名Ⅱ1431'!L13) -> 860793 | M13: =SUM('SEA A棟1508:海老名Ⅱ1431'!M13) -> 865509 | N13: =SUM('SEA A棟1508:海老名Ⅱ1431'!N13) -> 1197689 | O13: =SUM('SEA A棟1508:海老名Ⅱ1431'!O13) -> 1841155 | P13: =SUM('SEA A棟1508:海老名Ⅱ1431'!P13) -> 1546959 | Q13: =SUM('SEA A棟1508:海老名Ⅱ1431'!Q13) -> 2427272 | R13: =SUM('SEA A棟1508:海老名Ⅱ1431'!R13) -> 3381157 | S13: =SUM('SEA A棟1508:海老名Ⅱ1431'!S13) -> 2969774 | ... W13: =SUM('SEA A棟1508:海老名Ⅱ1431'!W13) -> 3240252 | X13: =SUM(K13:W13) -> 22315087 | Y13: =SUM('SEA A棟1508:海老名Ⅱ1431'!Y13) -> 3230007 | Z13: =SUM('SEA A棟1508:海老名Ⅱ1431'!Z13) -> 3834321 | AA13: =SUM('SEA A棟1508:海老名Ⅱ1431'!AA13) -> 3803755 | AB13: =SUM('SEA A棟1508:海老名Ⅱ1431'!AB13) -> 3798457 | AC13: =SUM('SEA A棟1508:海老名Ⅱ1431'!AC13) -> 3918943 | AD13: =SUM('SEA A棟1508:海老名Ⅱ1431'!AD13) -> 3690270 | AE13: =SUM('SEA A棟1508:海老名Ⅱ1431'!AE13) -> 4025528 | AF13: =SUM('SEA A棟1508:海老名Ⅱ1431'!AF13) -> 12600 | ... AJ13: =SUM('SEA A棟1508:海老名Ⅱ1431'!AJ13) -> -699631 | AK13: =SUM(X13:AJ13) -> 49995180
A14: PL | B14: 円 | C14: =SUM('SEA A棟1508:海老名Ⅱ1431'!C14) -> 0 | D14: =SUM('SEA A棟1508:海老名Ⅱ1431'!D14) -> 0 | E14: =SUM('SEA A棟1508:海老名Ⅱ1431'!E14) -> 0 | F14: =SUM('SEA A棟1508:海老名Ⅱ1431'!F14) -> 0 | G14: =SUM('SEA A棟1508:海老名Ⅱ1431'!G14) -> 0 | H14: =SUM('SEA A棟1508:海老名Ⅱ1431'!H14) -> 0 | I14: =SUM('SEA A棟1508:海老名Ⅱ1431'!I14) -> 0 | J14: =SUM('SEA A棟1508:海老名Ⅱ1431'!J14) -> 0 | L14: =SUM('SEA A棟1508:海老名Ⅱ1431'!L14) -> 0 | M14: =SUM('SEA A棟1508:海老名Ⅱ1431'!M14) -> 0 | N14: =SUM('SEA A棟1508:海老名Ⅱ1431'!N14) -> 0 | O14: =SUM('SEA A棟1508:海老名Ⅱ1431'!O14) -> 0 | P14: =SUM('SEA A棟1508:海老名Ⅱ1431'!P14) -> 0 | Q14: =SUM('SEA A棟1508:海老名Ⅱ1431'!Q14) -> 0 | R14: =SUM('SEA A棟1508:海老名Ⅱ1431'!R14) -> 0 | S14: =SUM('SEA A棟1508:海老名Ⅱ1431'!S14) -> 0 | ... W14: =SUM('SEA A棟1508:海老名Ⅱ1431'!W14) -> 0 | Y14: =SUM('SEA A棟1508:海老名Ⅱ1431'!Y14) -> 0 | Z14: =SUM('SEA A棟1508:海老名Ⅱ1431'!Z14) -> 0 | AA14: =SUM('SEA A棟1508:海老名Ⅱ1431'!AA14) -> 0 | AB14: =SUM('SEA A棟1508:海老名Ⅱ1431'!AB14) -> 0 | AC14: =SUM('SEA A棟1508:海老名Ⅱ1431'!AC14) -> 0 | AD14: =SUM('SEA A棟1508:海老名Ⅱ1431'!AD14) -> 0 | AE14: =SUM('SEA A棟1508:海老名Ⅱ1431'!AE14) -> 0 | AF14: =SUM('SEA A棟1508:海老名Ⅱ1431'!AF14) -> 0 | ... AJ14: =SUM('SEA A棟1508:海老名Ⅱ1431'!AJ14) -> 0

Sheet SEA A棟1508
C1: 2024 | D1: 45322 | E1: 45350 | F1: 45382 | G1: 45412 | H1: 45443 | I1: 45473 | J1: 45504 | K1: 2025 | L1: 45535 | M1: 45565 | N1: 45596 | O1: 45626 | P1: 45657 | Q1: 45688 | R1: 45716 | S1: 45747 | T1: 45777 | U1: 45808 | V1: 45838 | W1: 45869 | X1: 2026 | Y1: 45900 | Z1: 45930 | AA1: 45961 | AB1: 45991 | AC1: 46022 | AD1: 46053 | AE1: 46081 | AF1: 46112 | AG1: 46142 | AH1: 46173 | AI1: 46203 | AJ1: 46234
A2: HARUMI FLAG SEAVILLAGE A棟 1508 | C2: 45310
A3: 取得価格 | B3: 円 | C3: 83200000
A4: 賃料収入 | B4: 円 | C4: 448000 | D4: 0 | E4: 0 | F4: 0 | G4: 0 | H4: 0 | I4: 0 | J4: 0 | L4: 0 | M4: 0 | N4: 838193 | O4: 448000 | P4: 448000 | Q4: 448000 | R4: 448000 | S4: 448000 | T4: 448000 | U4: 448000 | V4: 448000 | W4: 448000 | Y4: 448000 | Z4: 448000 | AA4: 448000 | AB4: 448000 | AC4: 448000 | AD4: 448000 | AE4: 448000 | AF4: 448000 | AG4: 448000
A5: 減価償却費 | B5: 円 | D5: 128778 | E5: 128775 | F5: 128775 | G5: 128775 | H5: 128775 | I5: 128775 | J5: 128778 | L5: 128775 | M5: 128775 | N5: 128775 | O5: 128775 | P5: 128775 | Q5: 128780 | R5: 128775 | S5: 128775 | T5: 128775 | U5: 128775 | V5: 128775 | W5: 128781 | Y5: 128775 | Z5: 128775 | AA5: 128775 | AB5: 128775 | AC5: 128775 | AD5: 128780 | AE5: 128775 | AF5: 128775 | AG5: 128775 | AH5: 128775 | AI5: 128775 | AJ5: 128781
A6: 残存簿価 | B6: 円 | C6: 70241437 | D6: =C6-D5 -> 70112659 | E6: =D6-E5 -> 69983884 | F6: =E6-F5 -> 69855109 | G6: =F6-G5 -> 69726334 | H6: =G6-H5 -> 69597559 | I6: =H6-I5 -> 69468784 | J6: =I6-J5 -> 69340006 | L6: =J6-L5 -> 69211231 | M6: =L6-M5 -> 69082456 | N6: =M6-N5 -> 68953681 | O6: =N6-O5 -> 68824906 | P6: =O6-P5 -> 68696131 | Q6: =P6-Q5 -> 68567351 | R6: =Q6-R5 -> 68438576 | S6: =R6-S5 -> 68309801 | T6: =S6-T5 -> 68181026 | ... W6: =V6-W5 -> 67794695 | Y6: =W6-Y5 -> 67665920 | Z6: =Y6-Z5 -> 67537145 | AA6: =Z6-AA5 -> 67408370 | AB6: =AA6-AB5 -> 67279595 | AC6: =AB6-AC5 -> 67150820 | AD6: =AC6-AD5 -> 67022040 | AE6: =AD6-AE5 -> 66893265 | AF6: =AE6-AF5 -> 66764490 | AG6: =AF6-AG5 -> 66635715 | ... AJ6: =AI6-AJ5 -> 66249384
A7: 管理費・修繕積立金等 | B7: 円 | C7: 77250 | D7: 32117 | E7: 77250 | F7: 77250 | G7: 77250 | H7: 77250 | I7: 77250 | J7: 77250 | L7: 77250 | M7: 77250 | N7: 77250 | O7: 77250 | P7: 77250 | Q7: 77250 | R7: 77250 | S7: 77250 | T7: 77250 | U7: 77250 | V7: 77250 | W7: 77250 | Y7: 77250 | Z7: 77250 | AA7: 77250 | AB7: 77250 | AC7: 77250 | AD7: 77250 | AE7: 77250 | AF7: 77250 | AG7: 77250 | AH7: 77250 | AI7: 77250 | AJ7: 77250
A8: 管理委託手数料 | B8: 円 | D8: 0 | E8: 0 | F8: 0 | G8: 0 | H8: 0 | I8: 0 | J8: 0 | L8: 0 | M8: 0 | N8: 8583 | O8: 9856 | P8: 9856 | Q8: 9856 | R8: 9856 | S8: 9856 | T8: 9856 | U8: 9856 | V8: 9856 | W8: 9856 | Y8: 9856 | Z8: 9856 | AA8: 9856 | AB8: 9856 | AC8: 9856 | AD8: 9856 | AE8: 9856 | AF8: 9856 | AG8: 9856
A9: 諸経費（税金、募集経費等） | B9: 円 | C9: 2333600 | D9: 451000 | E9: 0 | F9: 0 | G9: 0 | H9: 0 | I9: 0 | J9: 0 | L9: 0 | M9: 127000 | N9: 492800 | O9: 0 | P9: 0 | Q9: 0 | R9: 0 | S9: 0 | T9: 0 | U9: 238537 | V9: 0 | W9: 0
A10: ネット賃貸収入利回り | B10: 円
A11: 取得時簿価利回り | B11: 円
A12: 残存簿価利回り | B12: 円
A13: CF | B13: 円 | D13: =SUM(D4-D7-D8-D9) -> -483117 | E13: =SUM(E4-E7-E8-E9) -> -77250 | F13: =SUM(F4-F7-F8-F9) -> -77250 | G13: =SUM(G4-G7-G8-G9) -> -77250 | H13: =SUM(H4-H7-H8-H9) -> -77250 | I13: =SUM(I4-I7-I8-I9) -> -77250 | J13: =SUM(J4-J7-J8-J9) -> -77250 | L13: =SUM(L4-L7-L8-L9) -> -77250 | M13: =SUM(M4-M7-M8-M9) -> -204250 | N13: =SUM(N4-N7-N8-N9) -> 259560 | O13: =SUM(O4-O7-O8-O9) -> 360894 | P13: =SUM(P4-P7-P8-P9) -> 360894 | Q13: =SUM(Q4-Q7-Q8-Q9) -> 360894 | R13: =SUM(R4-R7-R8-R9) -> 360894 | S13: =SUM(S4-S7-S8-S9) -> 360894 | ... W13: =SUM(W4-W7-W8-W9) -> 360894 | Y13: =SUM(Y4-Y7-Y8-Y9) -> 360894 | Z13: =SUM(Z4-Z7-Z8-Z9) -> 360894 | AA13: =SUM(AA4-AA7-AA8-AA9) -> 360894 | AB13: =SUM(AB4-AB7-AB8-AB9) -> 360894 | AC13: =SUM(AC4-AC7-AC8-AC9) -> 360894 | AD13: =SUM(AD4-AD7-AD8-AD9) -> 360894 | AE13: =SUM(AE4-AE7-AE8-AE9) -> 360894 | AF13: =SUM(AF4-AF7-AF8-AF9) -> 360894 | ... AJ13: =SUM(AJ4-AJ7-AJ8-AJ9) -> -77250
A14: PL | B14: 円
A15: 山中 唯義 | N15: 10/5契約
N16: 山中唯義

Sheet SEA E棟1302
C1: 2024 | D1: 45322 | E1: 45350 | F1: 45382 | G1: 45412 | H1: 45443 | I1: 45473 | J1: 45504 | K1: 2025 | L1: 45535 | M1: 45565 | N1: 45596 | O1: 45626 | P1: 45657 | Q1: 45688 | R1: 45716 | S1: 45747 | T1: 45777 | U1: 45808 | V1: 45838 | W1: 45869 | X1: 2026 | Y1: 45900 | Z1: 45930 | AA1: 45961 | AB1: 45991 | AC1: 46022 | AD1: 46053 | AE1: 46081 | AF1: 46112 | AG1: 46142 | AH1: 46173 | AI1: 46203 | AJ1: 46234
A2: HARUMI FLAG SEAVILLAGE E棟 1302 | C2: 45310
A3: 取得価格 | B3: 円 | C3: 81600000
A4: 賃料収入 | B4: 円 | C4: 400000 | D4: 0 | E4: 0 | F4: 0 | G4: 0 | H4: 0 | I4: 0 | J4: 0 | L4: 0 | M4: 0 | N4: 0 | O4: 0 | P4: 477419 | Q4: 400000 | R4: 400000 | S4: 400000 | T4: 400000 | U4: 400000 | V4: 400000 | W4: 400000 | Y4: 400000 | Z4: 400000 | AA4: 400000 | AB4: 400000 | AC4: 400000 | AD4: 400000 | AE4: 400000 | AF4: 400000 | AG4: 400000
A5: 減価償却費 | B5: 円 | D5: 126186 | E5: 126186 | F5: 126186 | G5: 126186 | H5: 126186 | I5: 126186 | J5: 126186 | L5: 126186 | M5: 126186 | N5: 126186 | O5: 126186 | P5: 126186 | Q5: 126186 | R5: 126186 | S5: 126186 | T5: 126186 | U5: 126186 | V5: 126186 | W5: 126186 | Y5: 126186 | Z5: 126186 | AA5: 126186 | AB5: 126186 | AC5: 126186 | AD5: 126186 | AE5: 126186 | AF5: 126186 | AG5: 126186 | AH5: 126186 | AI5: 126186 | AJ5: 126186
A6: 残存簿価 | B6: 円 | C6: 68828736 | D6: =SUM(C6-D5) -> 68702550 | E6: =SUM(D6-E5) -> 68576364 | F6: =SUM(E6-F5) -> 68450178 | G6: =SUM(F6-G5) -> 68323992 | H6: =SUM(G6-H5) -> 68197806 | I6: =SUM(H6-I5) -> 68071620 | J6: =SUM(I6-J5) -> 67945434 | L6: =SUM(J6-L5) -> 67819248 | M6: =SUM(L6-M5) -> 67693062 | N6: =SUM(M6-N5) -> 67566876 | O6: =SUM(N6-O5) -> 67440690 | P6: =SUM(O6-P5) -> 67314504 | Q6: =SUM(P6-Q5) -> 67188318 | R6: =SUM(Q6-R5) -> 67062132 | S6: =SUM(R6-S5) -> 66935946 | T6: =SUM(S6-T5) -> 66809760 | ... W6: =SUM(V6-W5) -> 66431202 | Y6: =SUM(W6-Y5) -> 66305016 | Z6: =SUM(Y6-Z5) -> 66178830 | AA6: =SUM(Z6-AA5) -> 66052644 | AB6: =SUM(AA6-AB5) -> 65926458 | AC6: =SUM(AB6-AC5) -> 65800272 | AD6: =SUM(AC6-AD5) -> 65674086 | AE6: =SUM(AD6-AE5) -> 65547900 | AF6: =SUM(AE6-AF5) -> 65421714 | AG6: =SUM(AF6-AG5) -> 65295528 | ... AJ6: =SUM(AI6-AJ5) -> 64916970
A7: 管理費・修繕積立金等 | B7: 円 | C7: 47020 | D7: 19441 | E7: 47020 | F7: 47020 | G7: 47020 | H7: 47020 | I7: 47020 | J7: 47020 | L7: 47020 | M7: 47020 | N7: 47020 | O7: 47020 | P7: 47020 | Q7: 47020 | R7: 47020 | S7: 47020 | T7: 47020 | U7: 47020 | V7: 47020 | W7: 47020 | Y7: 47020 | Z7: 47020 | AA7: 47020 | AB7: 47020 | AC7: 47020 | AD7: 47020 | AE7: 47020 | AF7: 47020 | AG7: 47020 | AH7: 47020 | AI7: 47020 | AJ7: 47020
A8: 管理委託手数料 | B8: 円 | D8: 0 | E8: 0 | F8: 0 | G8: 0 | H8: 0 | I8: 0 | J8: 0 | L8: 0 | M8: 0 | N8: 0 | O8: 0 | P8: 1702 | Q8: 8800 | R8: 8800 | S8: 8800 | T8: 8800 | U8: 8800 | V8: 8800 | W8: 8800 | Y8: 8800 | Z8: 8800 | AA8: 8800 | AB8: 8800 | AC8: 8800 | AD8: 8800 | AE8: 8800 | AF8: 8800 | AG8: 8800
A9: 諸経費（税金、募集経費等） | B9: 円 | C9: 2322800 | D9: 451000 | E9: 0 | F9: 0 | G9: 0 | H9: 0 | I9: 0 | J9: 0 | L9: 0 | M9: 0 | N9: 127000 | O9: 1273 | P9: 443108 | Q9: 0 | R9: 0 | S9: 0 | T9: 0 | U9: 238489 | V9: 0 | W9: 0 | Y9: 0 | Z9: 0
A10: ネット賃貸収入利回り | B10: 円
A11: 取得時簿価利回り | B11: 円
A12: 残存簿価利回り | B12: 円
A13: CF | B13: 円 | D13: =SUM(D4-D7-D8-D9) -> -470441 | E13: =SUM(E4-E7-E8-E9) -> -47020 | F13: =SUM(F4-F7-F8-F9) -> -47020 | G13: =SUM(G4-G7-G8-G9) -> -47020 | H13: =SUM(H4-H7-H8-H9) -> -47020 | I13: =SUM(I4-I7-I8-I9) -> -47020 | J13: =SUM(J4-J7-J8-J9) -> -47020 | L13: =SUM(L4-L7-L8-L9) -> -47020 | M13: =SUM(M4-M7-M8-M9) -> -47020 | N13: =SUM(N4-N7-N8-N9) -> -174020 | O13: =SUM(O4-O7-O8-O9) -> -48293 | P13: =SUM(P4-P7-P8-P9) -> -14411 | Q13: =SUM(Q4-Q7-Q8-Q9) -> 344180 | R13: =SUM(R4-R7-R8-R9) -> 344180 | S13: =SUM(S4-S7-S8-S9) -> 344180 | ... W13: =SUM(W4-W7-W8-W9) -> 344180 | Y13: =SUM(Y4-Y7-Y8-Y9) -> 344180 | Z13: =SUM(Z4-Z7-Z8-Z9) -> 344180 | AA13: =SUM(AA4-AA7-AA8-AA9) -> 344180 | AB13: =SUM(AB4-AB7-AB8-AB9) -> 344180 | AC13: =SUM(AC4-AC7-AC8-AC9) -> 344180 | AD13: =SUM(AD4-AD7-AD8-AD9) -> 344180 | AE13: =SUM(AE4-AE7-AE8-AE9) -> 344180 | AF13: =SUM(AF4-AF7-AF8-AF9) -> 344180 | ... AJ13: =SUM(AJ4-AJ7-AJ8-AJ9) -> -47020
A14: PL | B14: 円
A15: 三戸淳也 | P15: 12//26契約
P16: 三戸淳也

Sheet SUN A棟1106
C1: 2024 | D1: 45322 | E1: 45350 | F1: 45382 | G1: 45412 | H1: 45443 | I1: 45473 | J1: 45504 | K1: 2025 | L1: 45535 | M1: 45565 | N1: 45596 | O1: 45626 | P1: 45657 | Q1: 45688 | R1: 45716 | S1: 45747 | T1: 45777 | U1: 45808 | V1: 45838 | W1: 45869 | X1: 2026 | Y1: 45900 | Z1: 45930 | AA1: 45961 | AB1: 45991 | AC1: 46022 | AD1: 46053 | AE1: 46081 | AF1: 46112 | AG1: 46142 | AH1: 46173 | AI1: 46203 | AJ1: 46234
A2: HARUMI FLAG SUNVILLAGE A棟 1106 | C2: 45310
A3: 取得価格 | B3: 円 | C3: 99300000
A4: 賃料収入 | B4: 円 | C4: 458000 | D4: 0 | E4: 0 | F4: 0 | G4: 0 | H4: 0 | I4: 0 | J4: 0 | L4: 0 | M4: 0 | N4: 0 | O4: 0 | P4: 0 | Q4: 0 | R4: 801500 | S4: 458000 | T4: 458000 | U4: 458000 | V4: 458000 | W4: 458000 | Y4: 458000 | Z4: 458000 | AA4: 458000 | AB4: 458000 | AC4: 458000 | AD4: 458000 | AE4: 458000 | AF4: 458000 | AG4: 458000
A5: 減価償却費 | B5: 円 | D5: 158501 | E5: 158499 | F5: 158499 | G5: 158499 | H5: 158499 | I5: 158499 | J5: 158501 | L5: 158499 | M5: 158499 | N5: 158499 | O5: 158499 | P5: 158499 | Q5: 158502 | R5: 158499 | S5: 158499 | T5: 158499 | U5: 158499 | V5: 158499 | W5: 158503 | Y5: 158499 | Z5: 158499 | AA5: 158499 | AB5: 158499 | AC5: 158499 | AD5: 158502 | AE5: 158499 | AF5: 158499 | AG5: 158499 | AH5: 158499 | AI5: 158499 | AJ5: 158503
A6: 残存簿価 | B6: 円 | C6: 86454320 | D6: =SUM(C6-D5) -> 86295819 | E6: =SUM(D6-E5) -> 86137320 | F6: =SUM(E6-F5) -> 85978821 | G6: =SUM(F6-G5) -> 85820322 | H6: =SUM(G6-H5) -> 85661823 | I6: =SUM(H6-I5) -> 85503324 | J6: =SUM(I6-J5) -> 85344823 | L6: =SUM(J6-L5) -> 85186324 | M6: =SUM(L6-M5) -> 85027825 | N6: =SUM(M6-N5) -> 84869326 | O6: =SUM(N6-O5) -> 84710827 | P6: =SUM(O6-P5) -> 84552328 | Q6: =SUM(P6-Q5) -> 84393826 | R6: =SUM(Q6-R5) -> 84235327 | S6: =SUM(R6-S5) -> 84076828 | T6: =SUM(S6-T5) -> 83918329 | ... W6: =SUM(V6-W5) -> 83442828 | Y6: =SUM(W6-Y5) -> 83284329 | Z6: =SUM(Y6-Z5) -> 83125830 | AA6: =SUM(Z6-AA5) -> 82967331 | AB6: =SUM(AA6-AB5) -> 82808832 | AC6: =SUM(AB6-AC5) -> 82650333 | AD6: =SUM(AC6-AD5) -> 82491831 | AE6: =SUM(AD6-AE5) -> 82333332 | AF6: =SUM(AE6-AF5) -> 82174833 | AG6: =SUM(AF6-AG5) -> 82016334 | ... AJ6: =SUM(AI6-AJ5) -> 81540833
A7: 管理費・修繕積立金等 | B7: 円 | C7: 74390 | D7: 30918 | E7: 74390 | F7: 74390 | G7: 74390 | H7: 74390 | I7: 74390 | J7: 74390 | L7: 74390 | M7: 74390 | N7: 74390 | O7: 74390 | P7: 74390 | Q7: 74390 | R7: 74390 | S7: 74390 | T7: 74390 | U7: 74390 | V7: 74390 | W7: 74390 | Y7: 74390 | Z7: 74390 | AA7: 74390 | AB7: 74390 | AC7: 74390 | AD7: 74390 | AE7: 74390 | AF7: 74390 | AG7: 74390 | AH7: 74390 | AI7: 74390 | AJ7: 74390
A8: 管理委託手数料 | B8: 円 | D8: 0 | E8: 0 | F8: 0 | G8: 0 | H8: 0 | I8: 0 | J8: 0 | L8: 0 | M8: 0 | N8: 0 | O8: 0 | P8: 0 | Q8: 0 | R8: 7557 | S8: 10076 | T8: 10076 | U8: 10076 | V8: 10076 | W8: 10076 | Y8: 10076 | Z8: 10076 | AA8: 10076 | AB8: 10076 | AC8: 10076 | AD8: 10076 | AE8: 10076 | AF8: 10076 | AG8: 10076
A9: 諸経費（税金、募集経費等） | B9: 円 | C9: 1844400 | D9: 440000 | E9: 0 | F9: 0 | G9: 0 | H9: 0 | I9: 0 | J9: 0 | L9: 0 | M9: 0 | N9: 127000 | O9: 0 | P9: 1896 | Q9: 5076 | R9: 504795 | T9: 0 | U9: 196177 | V9: 0 | W9: 0 | Y9: 0 | Z9: 0
A10: ネット賃貸収入利回り | B10: 円
A11: 取得時簿価利回り | B11: 円
A12: 残存簿価利回り | B12: 円
A13: CF | B13: 円 | D13: =SUM(D4-D7-D8-D9) -> -470918 | E13: =SUM(E4-E7-E8-E9) -> -74390 | F13: =SUM(F4-F7-F8-F9) -> -74390 | G13: =SUM(G4-G7-G8-G9) -> -74390 | H13: =SUM(H4-H7-H8-H9) -> -74390 | I13: =SUM(I4-I7-I8-I9) -> -74390 | J13: =SUM(J4-J7-J8-J9) -> -74390 | L13: =SUM(L4-L7-L8-L9) -> -74390 | M13: =SUM(M4-M7-M8-M9) -> -74390 | N13: =SUM(N4-N7-N8-N9) -> -201390 | O13: =SUM(O4-O7-O8-O9) -> -74390 | P13: =SUM(P4-P7-P8-P9) -> -76286 | Q13: =SUM(Q4-Q7-Q8-Q9) -> -79466 | R13: =SUM(R4-R7-R8-R9) -> 214758 | S13: =SUM(S4-S7-S8-S9) -> 373534 | ... W13: =SUM(W4-W7-W8-W9) -> 373534 | Y13: =SUM(Y4-Y7-Y8-Y9) -> 373534 | Z13: =SUM(Z4-Z7-Z8-Z9) -> 373534 | AA13: =SUM(AA4-AA7-AA8-AA9) -> 373534 | AB13: =SUM(AB4-AB7-AB8-AB9) -> 373534 | AC13: =SUM(AC4-AC7-AC8-AC9) -> 373534 | AD13: =SUM(AD4-AD7-AD8-AD9) -> 373534 | AE13: =SUM(AE4-AE7-AE8-AE9) -> 373534 | AF13: =SUM(AF4-AF7-AF8-AF9) -> 373534 | ... AJ13: =SUM(AJ4-AJ7-AJ8-AJ9) -> -74390
A14: PL | B14: 円
A15: 中川年和 | R15: 2/8契約
R16: 中川年和

Sheet オリゾン1110
C1: 2024 | D1: 45322 | E1: 45350 | F1: 45382 | G1: 45412 | H1: 45443 | I1: 45473 | J1: 45504 | K1: 2025 | L1: 45535 | M1: 45565 | N1: 45596 | O1: 45626 | P1: 45657 | Q1: 45688 | R1: 45716 | S1: 45747 | T1: 45777 | U1: 45808 | V1: 45838 | W1: 45869 | X1: 2026 | Y1: 45900 | Z1: 45930 | AA1: 45961 | AB1: 45991 | AC1: 46022 | AD1: 46053 | AE1: 46081 | AF1: 46112 | AG1: 46142 | AH1: 46173 | AI1: 46203 | AJ1: 46234
A2: オリゾンマーレ 1110 | C2: 45359
A3: 取得価格 | B3: 円 | C3: 61200000
A4: 賃料収入 | B4: 円 | C4: 275000 | D4: 0 | E4: 0 | F4: 197419 | G4: 255000 | H4: 255000 | I4: 255000 | J4: 255000 | L4: 0 | M4: 0 | N4: 0 | O4: 0 | P4: 345967 | Q4: 275000 | R4: 275000 | S4: 275000 | T4: 275000 | U4: 275000 | V4: 275000 | W4: 275000 | Y4: 275000 | Z4: 275000 | AA4: 275000 | AB4: 275000 | AC4: 275000 | AD4: 275000 | AE4: 275000 | AF4: 275000 | AG4: 275000
A5: 減価償却費 | B5: 円 | F5: 70924 | G5: 70924 | H5: 70924 | I5: 70924 | J5: 70926 | L5: 70924 | M5: 70924 | N5: 70924 | O5: 70924 | P5: 70924 | Q5: 70927 | R5: 70924 | S5: 70924 | T5: 70924 | U5: 70924 | V5: 70924 | W5: 70928 | Y5: 70924 | Z5: 70924 | AA5: 70924 | AB5: 70924 | AC5: 70924 | AD5: 70927 | AE5: 70924 | AF5: 70924 | AG5: 70924 | AH5: 70924 | AI5: 70924 | AJ5: 70928
A6: 残存簿価 | B6: 円 | C6: 38686158 | F6: =SUM(C6-F5) -> 38615234 | G6: =SUM(F6-G5) -> 38544310 | H6: =SUM(G6-H5) -> 38473386 | I6: =SUM(H6-I5) -> 38402462 | J6: =SUM(I6-J5) -> 38331536 | L6: =SUM(J6-L5) -> 38260612 | M6: =SUM(L6-M5) -> 38189688 | N6: =SUM(M6-N5) -> 38118764 | O6: =SUM(N6-O5) -> 38047840 | P6: =SUM(O6-P5) -> 37976916 | Q6: =SUM(P6-Q5) -> 37905989 | R6: =SUM(Q6-R5) -> 37835065 | S6: =SUM(R6-S5) -> 37764141 | T6: =SUM(S6-T5) -> 37693217 | ... W6: =SUM(V6-W5) -> 37480441 | Y6: =SUM(W6-Y5) -> 37409517 | Z6: =SUM(Y6-Z5) -> 37338593 | AA6: =SUM(Z6-AA5) -> 37267669 | AB6: =SUM(AA6-AB5) -> 37196745 | AC6: =SUM(AB6-AC5) -> 37125821 | AD6: =SUM(AC6-AD5) -> 37054894 | AE6: =SUM(AD6-AE5) -> 36983970 | AF6: =SUM(AE6-AF5) -> 36913046 | AG6: =SUM(AF6-AG5) -> 36842122 | ... AJ6: =SUM(AI6-AJ5) -> 36629346
A7: 管理費・修繕積立金等 | B7: 円 | C7: 40710 | F7: 31517 | G7: 40710 | H7: 40710 | I7: 40710 | J7: 40710 | L7: 40710 | M7: 40710 | N7: 40710 | O7: 40710 | P7: 40710 | Q7: 40710 | R7: 40710 | S7: 40710 | T7: 40710 | U7: 40710 | V7: 40710 | W7: 40710 | Y7: 40310 | Z7: 40310 | AA7: 40310 | AB7: 40310 | AC7: 40310 | AD7: 40310 | AE7: 40310 | AF7: 40310 | AG7: 40310 | AH7: 40310 | AI7: 40310 | AJ7: 40310
A8: 管理委託手数料 | B8: 円 | F8: 0 | G8: 0 | H8: 0 | I8: 0 | J8: 0 | L8: 0 | M8: 0 | N8: 0 | O8: 0 | P8: 1560 | Q8: 6050 | R8: 6050 | S8: 6050 | T8: 6050 | U8: 6050 | V8: 6050 | W8: 6050 | Y8: 6050 | Z8: 6050 | AA8: 6050 | AB8: 6050 | AC8: 6050 | AD8: 6050 | AE8: 6050 | AF8: 6050 | AG8: 6050
A9: 諸経費（税金、募集経費等） | B9: 円 | C9: 2725092 | D9: 0 | E9: 0 | F9: 143712 | G9: 0 | H9: 0 | I9: 0 | J9: 0 | L9: 0 | M9: 139800 | N9: 291271 | O9: 1866 | P9: 704012 | Q9: 0 | R9: 0 | S9: 0 | T9: 0 | U9: 354115 | V9: 0 | W9: 0 | Y9: 0 | Z9: 0
A10: ネット賃貸収入利回り | B10: 円
A11: 取得時簿価利回り | B11: 円
A12: 残存簿価利回り | B12: 円
A13: CF | B13: 円 | D13: =SUM(D4-D7-D8-D9) -> 0 | E13: =SUM(E4-E7-E8-E9) -> 0 | F13: =SUM(F4-F7-F8-F9) -> 22190 | G13: =SUM(G4-G7-G8-G9) -> 214290 | H13: =SUM(H4-H7-H8-H9) -> 214290 | I13: =SUM(I4-I7-I8-I9) -> 214290 | J13: =SUM(J4-J7-J8-J9) -> 214290 | L13: =SUM(L4-L7-L8-L9) -> -40710 | M13: =SUM(M4-M7-M8-M9) -> -180510 | N13: =SUM(N4-N7-N8-N9) -> -331981 | O13: =SUM(O4-O7-O8-O9) -> -42576 | P13: =SUM(P4-P7-P8-P9) -> -400315 | Q13: =SUM(Q4-Q7-Q8-Q9) -> 228240 | R13: =SUM(R4-R7-R8-R9) -> 228240 | S13: =SUM(S4-S7-S8-S9) -> 228240 | ... W13: =SUM(W4-W7-W8-W9) -> 228240 | Y13: =SUM(Y4-Y7-Y8-Y9) -> 228640 | Z13: =SUM(Z4-Z7-Z8-Z9) -> 228640 | AA13: =SUM(AA4-AA7-AA8-AA9) -> 228640 | AB13: =SUM(AB4-AB7-AB8-AB9) -> 228640 | AC13: =SUM(AC4-AC7-AC8-AC9) -> 228640 | AD13: =SUM(AD4-AD7-AD8-AD9) -> 228640 | AE13: =SUM(AE4-AE7-AE8-AE9) -> 228640 | AF13: =SUM(AF4-AF7-AF8-AF9) -> 228640 | ... AJ13: =SUM(AJ4-AJ7-AJ8-AJ9) -> -40310
A14: PL | B14: 円
A15: 永田聖一朗 | P15: 12/24契約
P16: 永田聖一朗

Sheet 亀戸Xゲート1213
C1: 2024 | D1: 45322 | E1: 45350 | F1: 45382 | G1: 45412 | H1: 45443 | I1: 45473 | J1: 45504 | K1: 2025 | L1: 45535 | M1: 45565 | N1: 45596 | O1: 45626 | P1: 45657 | Q1: 45688 | R1: 45716 | S1: 45747 | T1: 45777 | U1: 45808 | V1: 45838 | W1: 45869 | X1: 2026 | Y1: 45900 | Z1: 45930 | AA1: 45961 | AB1: 45991 | AC1: 46022 | AD1: 46053 | AE1: 46081 | AF1: 46112 | AG1: 46142 | AH1: 46173 | AI1: 46203 | AJ1: 46234
A2: プラウドタワー亀戸クロスゲートタワー 1213 | C2: 45464
A3: 取得価格 | B3: 円 | C3: 61000000
A4: 賃料収入 | B4: 円 | C4: 193000 | D4: 0 | E4: 0 | F4: 0 | G4: 0 | H4: 0 | I4: 64333 | J4: 193000 | L4: 193000 | M4: 193000 | N4: 193000 | O4: 193000 | P4: 193000 | Q4: 193000 | R4: 193000 | S4: 193000 | T4: 193000 | U4: 193000 | V4: 193000 | W4: 193000 | Y4: 193000 | Z4: 193000 | AA4: 193000 | AB4: 193000 | AC4: 193000 | AD4: 193000 | AE4: 193000
A5: 減価償却費 | B5: 円 | I5: 71029 | J5: 71029 | L5: 71029 | M5: 71029 | N5: 71029 | O5: 71029 | P5: 71029 | Q5: 71031 | R5: 71029 | S5: 71029 | T5: 71029 | U5: 71029 | V5: 71029 | W5: 71032 | Y5: 71029 | Z5: 71029 | AA5: 71029 | AB5: 71029 | AC5: 71029 | AD5: 71031 | AE5: 71029 | AF5: 71029 | AG5: 71029 | AH5: 71029 | AI5: 71029 | AJ5: 71032
A6: 残存簿価 | B6: 円 | C6: 38743323 | I6: =SUM(C6-I5) -> 38672294 | J6: =SUM(I6-J5) -> 38601265 | L6: =SUM(J6-L5) -> 38530236 | M6: =SUM(L6-M5) -> 38459207 | N6: =SUM(M6-N5) -> 38388178 | O6: =SUM(N6-O5) -> 38317149 | P6: =SUM(O6-P5) -> 38246120 | Q6: =SUM(P6-Q5) -> 38175089 | R6: =SUM(Q6-R5) -> 38104060 | S6: =SUM(R6-S5) -> 38033031 | T6: =SUM(S6-T5) -> 37962002 | ... W6: =SUM(V6-W5) -> 37748912 | Y6: =SUM(W6-Y5) -> 37677883 | Z6: =SUM(Y6-Z5) -> 37606854 | AA6: =SUM(Z6-AA5) -> 37535825 | AB6: =SUM(AA6-AB5) -> 37464796 | AC6: =SUM(AB6-AC5) -> 37393767 | AD6: =SUM(AC6-AD5) -> 37322736 | AE6: =SUM(AD6-AE5) -> 37251707 | AF6: =SUM(AE6-AF5) -> 37180678 | AG6: =SUM(AF6-AG5) -> 37109649 | ... AJ6: =SUM(AI6-AJ5) -> 36896559
A7: 管理費・修繕積立金等 | B7: 円 | C7: 24052 | I7: 8017 | J7: 24052 | L7: 24052 | M7: 24052 | N7: 24052 | O7: 24052 | P7: 24052 | Q7: 24052 | R7: 24052 | S7: 24052 | T7: 24052 | U7: 24052 | V7: 24052 | W7: 24052 | Y7: 24052 | Z7: 24052 | AA7: 24052 | AB7: 24052 | AC7: 24052 | AD7: 24052 | AE7: 24052 | AF7: 24052 | AG7: 24052 | AH7: 24052 | AI7: 24052 | AJ7: 24052
A8: 管理委託手数料 | B8: 円 | I8: 0 | J8: 0 | L8: 0 | M8: 0 | N8: 0 | O8: 0 | P8: 0 | Q8: 0 | R8: 0 | S8: 0 | T8: 0 | U8: 0 | V8: 0 | W8: 0 | Y8: 0 | Z8: 0 | AA8: 0 | AB8: 0 | AC8: 0 | AD8: 0 | AE8: 0 | AF8: 0 | AG8: 0 | AH8: 0 | AI8: 0 | AJ8: 0
A9: 諸経費（税金、募集経費等） | B9: 円 | C9: 2432689 | D9: 0 | E9: 0 | F9: 0 | G9: 0 | H9: 0 | I9: 49098 | J9: 0 | L9: 0 | M9: 0 | N9: 0 | O9: 0 | P9: 0 | Q9: 0 | R9: 0 | S9: 0 | T9: 0 | U9: 93407 | V9: 0 | W9: 0 | Y9: 0 | Z9: 0 | AA9: 0 | AB9: 0 | AC9: 0 | AD9: 0 | AE9: 0 | AF9: 0 | AG9: 0 | AH9: 0 | AI9: 0 | AJ9: 0
A10: ネット賃貸収入利回り | B10: 円
A11: 取得時簿価利回り | B11: 円
A12: 残存簿価利回り | B12: 円
A13: CF | B13: 円 | D13: =SUM(D4-D7-D8-D9) -> 0 | E13: =SUM(E4-E7-E8-E9) -> 0 | F13: =SUM(F4-F7-F8-F9) -> 0 | G13: =SUM(G4-G7-G8-G9) -> 0 | H13: =SUM(H4-H7-H8-H9) -> 0 | I13: =SUM(I4-I7-I8-I9) -> 7218 | J13: =SUM(J4-J7-J8-J9) -> 168948 | L13: =SUM(L4-L7-L8-L9) -> 168948 | M13: =SUM(M4-M7-M8-M9) -> 168948 | N13: =SUM(N4-N7-N8-N9) -> 168948 | O13: =SUM(O4-O7-O8-O9) -> 168948 | P13: =SUM(P4-P7-P8-P9) -> 168948 | Q13: =SUM(Q4-Q7-Q8-Q9) -> 168948 | R13: =SUM(R4-R7-R8-R9) -> 168948 | S13: =SUM(S4-S7-S8-S9) -> 168948 | ... W13: =SUM(W4-W7-W8-W9) -> 168948 | Y13: =SUM(Y4-Y7-Y8-Y9) -> 168948 | Z13: =SUM(Z4-Z7-Z8-Z9) -> 168948 | AA13: =SUM(AA4-AA7-AA8-AA9) -> 168948 | AB13: =SUM(AB4-AB7-AB8-AB9) -> 168948 | AC13: =SUM(AC4-AC7-AC8-AC9) -> 168948 | AD13: =SUM(AD4-AD7-AD8-AD9) -> 168948 | AE13: =SUM(AE4-AE7-AE8-AE9) -> 168948 | AF13: =SUM(AF4-AF7-AF8-AF9) -> -24052 | ... AJ13: =SUM(AJ4-AJ7-AJ8-AJ9) -> -24052
A14: PL | B14: 円
A15: ランクアップスタイル株式会社

Sheet PC文京小石川807
C1: 2024 | D1: 45322 | E1: 45350 | F1: 45382 | G1: 45412 | H1: 45443 | I1: 45473 | J1: 45504 | K1: 2025 | L1: 45535 | M1: 45565 | N1: 45596 | O1: 45626 | P1: 45657 | Q1: 45688 | R1: 45716 | S1: 45747 | T1: 45777 | U1: 45808 | V1: 45838 | W1: 45869 | X1: 2026 | Y1: 45900 | Z1: 45930 | AA1: 45961 | AB1: 45991 | AC1: 46022 | AD1: 46053 | AE1: 46081 | AF1: 46112 | AG1: 46142 | AH1: 46173 | AI1: 46203 | AJ1: 46234
A2: パークコート文京小石川ザタワー 807 | C2: 45467
A3: 取得価格 | B3: 円 | C3: 179000000
A4: 賃料収入 | B4: 円 | C4: 400000 | D4: 0 | E4: 0 | F4: 0 | G4: 0 | H4: 0 | I4: 0 | J4: 0 | L4: 606451 | M4: 400000 | N4: 400000 | O4: 400000 | P4: 400000 | Q4: 400000 | R4: 400000 | S4: 400000 | T4: 400000 | U4: 400000 | V4: 400000 | W4: 400000 | Y4: 400000 | Z4: 400000 | AA4: 400000 | AB4: 400000 | AC4: 400000 | AD4: 400000 | AE4: 400000 | AF4: 400000 | AG4: 400000
A5: 減価償却費 | B5: 円 | I5: 187308 | J5: 187308 | L5: 187308 | M5: 187308 | N5: 187308 | O5: 187308 | P5: 187308 | Q5: 187309 | R5: 187308 | S5: 187308 | T5: 187308 | U5: 187308 | V5: 187308 | W5: 187309 | Y5: 187308 | Z5: 187308 | AA5: 187308 | AB5: 187308 | AC5: 187308 | AD5: 187309 | AE5: 187308 | AF5: 187308 | AG5: 187308 | AH5: 187308 | AI5: 187308 | AJ5: 187309
A6: 残存簿価 | B6: 円 | C6: 102168106 | I6: =SUM(C6-I5) -> 101980798 | J6: =SUM(I6-J5) -> 101793490 | L6: =SUM(J6-L5) -> 101606182 | M6: =SUM(L6-M5) -> 101418874 | N6: =SUM(M6-N5) -> 101231566 | O6: =SUM(N6-O5) -> 101044258 | P6: =SUM(O6-P5) -> 100856950 | Q6: =SUM(P6-Q5) -> 100669641 | R6: =SUM(Q6-R5) -> 100482333 | S6: =SUM(R6-S5) -> 100295025 | T6: =SUM(S6-T5) -> 100107717 | ... W6: =SUM(V6-W5) -> 99545792 | Y6: =SUM(W6-Y5) -> 99358484 | Z6: =SUM(Y6-Z5) -> 99171176 | AA6: =SUM(Z6-AA5) -> 98983868 | AB6: =SUM(AA6-AB5) -> 98796560 | AC6: =SUM(AB6-AC5) -> 98609252 | AD6: =SUM(AC6-AD5) -> 98421943 | AE6: =SUM(AD6-AE5) -> 98234635 | AF6: =SUM(AE6-AF5) -> 98047327 | AG6: =SUM(AF6-AG5) -> 97860019 | ... AJ6: =SUM(AI6-AJ5) -> 97298094
A7: 管理費・修繕積立金等 | B7: 円 | C7: 41320 | I7: 9641 | J7: 41320 | L7: 41320 | M7: 41320 | N7: 41320 | O7: 41320 | P7: 41320 | Q7: 41320 | R7: 41320 | S7: 41320 | T7: 41320 | U7: 41320 | V7: 41320 | W7: 41320 | Y7: 44760 | Z7: 44760 | AA7: 44760 | AB7: 44760 | AC7: 44760 | AD7: 44760 | AE7: 44760 | AF7: 44760 | AG7: 44760 | AH7: 44760 | AI7: 44760 | AJ7: 44760
A8: 管理委託手数料 | B8: 円 | I8: 0 | J8: 0 | L8: 4541 | M8: 8800 | N8: 8800 | O8: 8800 | P8: 8800 | Q8: 8800 | R8: 8800 | S8: 8800 | T8: 8800 | U8: 8800 | V8: 8800 | W8: 8800 | Y8: 8800 | Z8: 8800 | AA8: 8800 | AB8: 8800 | AC8: 8800 | AD8: 8800 | AE8: 8800 | AF8: 8800 | AG8: 8800
A9: 諸経費（税金、募集経費等） | B9: 円 | C9: 6039282 | D9: 0 | E9: 0 | F9: 0 | G9: 0 | H9: 0 | I9: 99779 | J9: 0 | L9: 440000 | M9: 160000 | N9: 0 | O9: 0 | P9: 0 | Q9: 0 | R9: 0 | S9: 0 | T9: 0 | U9: 193404 | V9: 0 | W9: 0 | Y9: 0 | Z9: 0
A10: ネット賃貸収入利回り | B10: 円
A11: 取得時簿価利回り | B11: 円
A12: 残存簿価利回り | B12: 円
A13: CF | B13: 円 | D13: =SUM(D4-D7-D8-D9) -> 0 | E13: =SUM(E4-E7-E8-E9) -> 0 | F13: =SUM(F4-F7-F8-F9) -> 0 | G13: =SUM(G4-G7-G8-G9) -> 0 | H13: =SUM(H4-H7-H8-H9) -> 0 | I13: =SUM(I4-I7-I8-I9) -> -109420 | J13: =SUM(J4-J7-J8-J9) -> -41320 | L13: =SUM(L4-L7-L8-L9) -> 120590 | M13: =SUM(M4-M7-M8-M9) -> 189880 | N13: =SUM(N4-N7-N8-N9) -> 349880 | O13: =SUM(O4-O7-O8-O9) -> 349880 | P13: =SUM(P4-P7-P8-P9) -> 349880 | Q13: =SUM(Q4-Q7-Q8-Q9) -> 349880 | R13: =SUM(R4-R7-R8-R9) -> 349880 | S13: =SUM(S4-S7-S8-S9) -> 349880 | ... W13: =SUM(W4-W7-W8-W9) -> 349880 | Y13: =SUM(Y4-Y7-Y8-Y9) -> 346440 | Z13: =SUM(Z4-Z7-Z8-Z9) -> 346440 | AA13: =SUM(AA4-AA7-AA8-AA9) -> 346440 | AB13: =SUM(AB4-AB7-AB8-AB9) -> 346440 | AC13: =SUM(AC4-AC7-AC8-AC9) -> 346440 | AD13: =SUM(AD4-AD7-AD8-AD9) -> 346440 | AE13: =SUM(AE4-AE7-AE8-AE9) -> 346440 | AF13: =SUM(AF4-AF7-AF8-AF9) -> 346440 | ... AJ13: =SUM(AJ4-AJ7-AJ8-AJ9) -> -44760
A14: PL | B14: 円
A15: ベインキャピタル・プライベート・エクイティ・ジャパン | L15: 8/16契約
L16: ベインキャピタル・プライベート・エクイティ・ジャパン

Sheet PC麻布十番404
C1: 2024 | D1: 45322 | E1: 45350 | F1: 45382 | G1: 45412 | H1: 45443 | I1: 45473 | J1: 45504 | K1: 2025 | L1: 45535 | M1: 45565 | N1: 45596 | O1: 45626 | P1: 45657 | Q1: 45688 | R1: 45716 | S1: 45747 | T1: 45777 | U1: 45808 | V1: 45838 | W1: 45869 | X1: 2026 | Y1: 45900 | Z1: 45930 | AA1: 45961 | AB1: 45991 | AC1: 46022 | AD1: 46053 | AE1: 46081 | AF1: 46112 | AG1: 46142 | AH1: 46173 | AI1: 46203 | AJ1: 46234
A2: パークコート麻布十番ザタワー 404 | C2: 45505
A3: 取得価格 | B3: 円 | C3: 120000000
A4: 賃料収入 | B4: 円 | C4: 260000 | D4: 0 | E4: 0 | F4: 0 | G4: 0 | H4: 0 | I4: 0 | J4: 0 | L4: 260000 | M4: 260000 | N4: 260000 | O4: 260000 | P4: 260000 | Q4: 260000 | R4: 260000 | S4: 260000 | T4: 260000 | U4: 260000 | V4: 260000 | W4: 260000 | Y4: 260000 | Z4: 260000 | AA4: 260000 | AB4: 260000 | AC4: 260000 | AD4: 260000 | AE4: 260000 | AF4: 260000 | AG4: 260000
A5: 減価償却費 | B5: 円 | L5: 109319 | M5: 109319 | N5: 109319 | O5: 109319 | P5: 109319 | Q5: 109323 | R5: 109319 | S5: 109319 | T5: 109319 | U5: 109319 | V5: 109319 | W5: 109323 | Y5: 109319 | Z5: 109319 | AA5: 109319 | AB5: 109319 | AC5: 109319 | AD5: 109323 | AE5: 109319 | AF5: 109319 | AG5: 109319 | AH5: 109319 | AI5: 109319 | AJ5: 109323
A6: 残存簿価 | B6: 円 | C6: 59628923 | D6: =SUM(C5-D5) -> 0 | E6: =SUM(D6-E5) -> 0 | F6: =SUM(E6-F5) -> 0 | G6: =SUM(F6-G5) -> 0 | H6: =SUM(G6-H5) -> 0 | I6: =SUM(H6-I5) -> 0 | J6: =SUM(I6-J5) -> 0 | L6: =SUM(C6-L5) -> 59519604 | M6: =SUM(L6-M5) -> 59410285 | N6: =SUM(M6-N5) -> 59300966 | O6: =SUM(N6-O5) -> 59191647 | P6: =SUM(O6-P5) -> 59082328 | Q6: =SUM(P6-Q5) -> 58973005 | R6: =SUM(Q6-R5) -> 58863686 | S6: =SUM(R6-S5) -> 58754367 | T6: =SUM(S6-T5) -> 58645048 | ... W6: =SUM(V6-W5) -> 58317087 | Y6: =SUM(W6-Y5) -> 58207768 | Z6: =SUM(Y6-Z5) -> 58098449 | AA6: =SUM(Z6-AA5) -> 57989130 | AB6: =SUM(AA6-AB5) -> 57879811 | AC6: =SUM(AB6-AC5) -> 57770492 | AD6: =SUM(AC6-AD5) -> 57661169 | AE6: =SUM(AD6-AE5) -> 57551850 | AF6: =SUM(AE6-AF5) -> 57442531 | AG6: =SUM(AF6-AG5) -> 57333212 | ... AJ6: =SUM(AI6-AJ5) -> 57005251
A7: 管理費・修繕積立金等 | B7: 円 | C7: 24580 | L7: 24580 | M7: 24580 | N7: 24580 | O7: 24580 | P7: 24580 | Q7: 24580 | R7: 24580 | S7: 24580 | T7: 24580 | U7: 24580 | V7: 24580 | W7: 24580 | Y7: 28650 | Z7: 28650 | AA7: 28650 | AB7: 33250 | AC7: 33250 | AD7: 33250 | AE7: 33250 | AF7: 33250 | AG7: 33250 | AH7: 33250 | AI7: 33250 | AJ7: 33250
A8: 管理委託手数料 | B8: 円 | L8: 0 | M8: 5720 | N8: 5720 | O8: 5720 | P8: 5720 | Q8: 5720 | R8: 5720 | S8: 5720 | T8: 5720 | U8: 5720 | V8: 5720 | W8: 5720 | Y8: 5720 | Z8: 5720 | AA8: 5720 | AB8: 5720 | AC8: 5720 | AD8: 5720 | AE8: 5720 | AF8: 5720 | AG8: 5720
A9: 諸経費（税金、募集経費等） | B9: 円 | C9: 3841265 | D9: 0 | E9: 0 | F9: 0 | G9: 0 | H9: 0 | I9: 0 | J9: 0 | L9: 79266 | M9: 0 | N9: 0 | O9: 0 | P9: 0 | Q9: 0 | R9: 0 | S9: 0 | T9: 0 | U9: 174651 | V9: 0 | W9: 0 | Y9: 0 | Z9: 0
A10: ネット賃貸収入利回り | B10: 円
A11: 取得時簿価利回り | B11: 円
A12: 残存簿価利回り | B12: 円
A13: CF | B13: 円 | D13: =SUM(D4-D7-D8-D9) -> 0 | E13: =SUM(E4-E7-E8-E9) -> 0 | F13: =SUM(F4-F7-F8-F9) -> 0 | G13: =SUM(G4-G7-G8-G9) -> 0 | H13: =SUM(H4-H7-H8-H9) -> 0 | I13: =SUM(I4-I7-I8-I9) -> 0 | J13: =SUM(J4-J7-J8-J9) -> 0 | L13: =SUM(L4-L7-L8-L9) -> 156154 | M13: =SUM(M4-M7-M8-M9) -> 229700 | N13: =SUM(N4-N7-N8-N9) -> 229700 | O13: =SUM(O4-O7-O8-O9) -> 229700 | P13: =SUM(P4-P7-P8-P9) -> 229700 | Q13: =SUM(Q4-Q7-Q8-Q9) -> 229700 | R13: =SUM(R4-R7-R8-R9) -> 229700 | S13: =SUM(S4-S7-S8-S9) -> 229700 | ... W13: =SUM(W4-W7-W8-W9) -> 229700 | Y13: =SUM(Y4-Y7-Y8-Y9) -> 225630 | Z13: =SUM(Z4-Z7-Z8-Z9) -> 225630 | AA13: =SUM(AA4-AA7-AA8-AA9) -> 225630 | AB13: =SUM(AB4-AB7-AB8-AB9) -> 221030 | AC13: =SUM(AC4-AC7-AC8-AC9) -> 221030 | AD13: =SUM(AD4-AD7-AD8-AD9) -> 221030 | AE13: =SUM(AE4-AE7-AE8-AE9) -> 221030 | AF13: =SUM(AF4-AF7-AF8-AF9) -> 221030 | ... AJ13: =SUM(AJ4-AJ7-AJ8-AJ9) -> -33250
A14: PL | B14: 円
A15: 堀井成巳 | L15: 8/1入居者継続
L16: 堀井成巳

Sheet Gスイート南麻布1404
C1: 2024 | D1: 45322 | E1: 45350 | F1: 45382 | G1: 45412 | H1: 45443 | I1: 45473 | J1: 45504 | K1: 2025 | L1: 45535 | M1: 45565 | N1: 45596 | O1: 45626 | P1: 45657 | Q1: 45688 | R1: 45716 | S1: 45747 | T1: 45777 | U1: 45808 | V1: 45838 | W1: 45869 | X1: 2026 | Y1: 45900 | Z1: 45930 | AA1: 45961 | AB1: 45991 | AC1: 46022 | AD1: 46053 | AE1: 46081 | AF1: 46112 | AG1: 46142 | AH1: 46173 | AI1: 46203 | AJ1: 46234
A2: グランスイート南麻布 1404 | C2: 45544
A3: 取得価格 | B3: 円 | C3: 110000000
A4: 賃料収入 | B4: 円 | C4: 275000 | D4: 0 | E4: 0 | F4: 0 | G4: 0 | H4: 0 | I4: 0 | J4: 0 | L4: 0 | M4: 201667 | N4: 275000 | O4: 275000 | P4: 275000 | Q4: 275000 | R4: 275000 | S4: 275000 | T4: 275000 | U4: 275000 | V4: 275000 | W4: 275000 | Y4: 275000 | Z4: 275000 | AA4: 275000 | AB4: 275000 | AC4: 275000 | AD4: 275000 | AE4: 275000 | AF4: 275000 | AG4: 275000
A5: 減価償却費 | B5: 円 | L5: 0 | M5: 59756 | N5: 59756 | O5: 59756 | P5: 59756 | Q5: 59756 | R5: 59756 | S5: 59756 | T5: 59756 | U5: 59756 | V5: 59756 | W5: 59757 | Y5: 59756 | Z5: 59756 | AA5: 59756 | AB5: 59756 | AC5: 59756 | AD5: 59757 | AE5: 59756 | AF5: 59756 | AG5: 59756 | AH5: 59756 | AI5: 59756 | AJ5: 59757
A6: 残存簿価 | B6: 円 | C6: 32594283 | M6: =SUM(C6-M5) -> 32534527 | N6: =SUM(M6-N5) -> 32474771 | O6: =SUM(N6-O5) -> 32415015 | P6: =SUM(O6-P5) -> 32355259 | Q6: =SUM(P6-Q5) -> 32295503 | R6: =SUM(Q6-R5) -> 32235747 | S6: =SUM(R6-S5) -> 32175991 | T6: =SUM(S6-T5) -> 32116235 | U6: =SUM(T6-U5) -> 32056479 | ... W6: =SUM(V6-W5) -> 31936966 | Y6: =SUM(W6-Y5) -> 31877210 | Z6: =SUM(Y6-Z5) -> 31817454 | AA6: =SUM(Z6-AA5) -> 31757698 | AB6: =SUM(AA6-AB5) -> 31697942 | AC6: =SUM(AB6-AC5) -> 31638186 | AD6: =SUM(AC6-AD5) -> 31578429 | AE6: =SUM(AD6-AE5) -> 31518673 | AF6: =SUM(AE6-AF5) -> 31458917 | AG6: =SUM(AF6-AG5) -> 31399161 | ... AJ6: =SUM(AI6-AJ5) -> 31219892
A7: 管理費・修繕積立金等 | B7: 円 | M7: 19674 | N7: 30318 | O7: 30318 | P7: 30318 | Q7: 30318 | R7: 30318 | S7: 30318 | T7: 30318 | U7: 30318 | V7: 30318 | W7: 30318 | Y7: 30318 | Z7: 30318 | AA7: 30318 | AB7: 30318 | AC7: 30318 | AD7: 30318 | AE7: 30318 | AF7: 30318 | AG7: 30318 | AH7: 30318 | AI7: 30318 | AJ7: 30318
A8: 管理委託手数料 | B8: 円 | N8: 6050 | O8: 6050 | P8: 6050 | Q8: 6050 | R8: 6050 | S8: 6050 | T8: 6050 | U8: 6050 | V8: 6050 | W8: 6050 | Y8: 6050 | Z8: 6050 | AA8: 6050 | AB8: 6050 | AC8: 6050 | AD8: 6050 | AE8: 6050 | AF8: 6050 | AG8: 6050
A9: 諸経費（税金、募集経費等） | B9: 円 | C9: 3724290 | D9: 0 | E9: 0 | F9: 0 | G9: 0 | H9: 0 | I9: 0 | J9: 0 | L9: 0 | M9: 57202 | N9: 0 | O9: 0 | P9: 0 | Q9: 0 | R9: 0 | S9: 0 | T9: 0 | U9: 171141 | V9: 0 | W9: 0 | Y9: 0 | Z9: 0 | AA9: 0 | AB9: 0
A10: ネット賃貸収入利回り | B10: 円
A11: 取得時簿価利回り | B11: 円
A12: 残存簿価利回り | B12: 円
A13: CF | B13: 円 | D13: =SUM(D4-D7-D8-D9) -> 0 | E13: =SUM(E4-E7-E8-E9) -> 0 | F13: =SUM(F4-F7-F8-F9) -> 0 | G13: =SUM(G4-G7-G8-G9) -> 0 | H13: =SUM(H4-H7-H8-H9) -> 0 | I13: =SUM(I4-I7-I8-I9) -> 0 | J13: =SUM(J4-J7-J8-J9) -> 0 | L13: =SUM(L4-L7-L8-L9) -> 0 | M13: =SUM(M4-M7-M8-M9) -> 124791 | N13: =SUM(N4-N7-N8-N9) -> 238632 | O13: =SUM(O4-O7-O8-O9) -> 238632 | P13: =SUM(P4-P7-P8-P9) -> 238632 | Q13: =SUM(Q4-Q7-Q8-Q9) -> 238632 | R13: =SUM(R4-R7-R8-R9) -> 238632 | S13: =SUM(S4-S7-S8-S9) -> 238632 | ... W13: =SUM(W4-W7-W8-W9) -> 238632 | Y13: =SUM(Y4-Y7-Y8-Y9) -> 238632 | Z13: =SUM(Z4-Z7-Z8-Z9) -> 238632 | AA13: =SUM(AA4-AA7-AA8-AA9) -> 238632 | AB13: =SUM(AB4-AB7-AB8-AB9) -> 238632 | AC13: =SUM(AC4-AC7-AC8-AC9) -> 238632 | AD13: =SUM(AD4-AD7-AD8-AD9) -> 238632 | AE13: =SUM(AE4-AE7-AE8-AE9) -> 238632 | AF13: =SUM(AF4-AF7-AF8-AF9) -> 238632 | ... AJ13: =SUM(AJ4-AJ7-AJ8-AJ9) -> -30318
A14: PL | B14: 円
A15: YU YUMIN | M15: 9/9入居者継続
M16: YU YUMIN

Sheet PH南麻布501
C1: 2024 | D1: 45322 | E1: 45350 | F1: 45382 | G1: 45412 | H1: 45443 | I1: 45473 | J1: 45504 | K1: 2025 | L1: 45535 | M1: 45565 | N1: 45596 | O1: 45626 | P1: 45657 | Q1: 45688 | R1: 45716 | S1: 45747 | T1: 45777 | U1: 45808 | V1: 45838 | W1: 45869 | X1: 2026 | Y1: 45900 | Z1: 45930 | AA1: 45961 | AB1: 45991 | AC1: 46022 | AD1: 46053 | AE1: 46081 | AF1: 46112 | AG1: 46142 | AH1: 46173 | AI1: 46203 | AJ1: 46234
A2: ザ・パークハウス南麻布 501 | C2: 45663
A3: 取得価格 | B3: 円 | C3: 101056947
A4: 賃料収入 | B4: 円 | D4: 0 | E4: 0 | F4: 0 | G4: 0 | H4: 0 | I4: 0 | J4: 0 | L4: 0 | Z4: 600000 | AA4: 600000 | AB4: 600000 | AC4: 600000 | AD4: 600000 | AE4: 600000
A5: 減価償却費 | B5: 円 | L5: 0 | P5: 190989 | Q5: 190990 | R5: 190989 | S5: 190989 | T5: 190989 | U5: 190989 | V5: 190989 | W5: 190990 | Y5: 190989 | Z5: 190989 | AA5: 190989 | AB5: 190989 | AC5: 190989 | AD5: 190990 | AE5: 190989 | AF5: 190989 | AG5: 190989 | AH5: 190989 | AI5: 190989 | AJ5: 190991
A6: 残存簿価 | B6: 円 | C6: 104175956 | P6: =C6-P5 -> 103984967 | Q6: =SUM(P6-Q5) -> 103793977 | R6: =SUM(Q6-R5) -> 103602988 | S6: =SUM(R6-S5) -> 103411999 | T6: =SUM(S6-T5) -> 103221010 | U6: =SUM(T6-U5) -> 103030021 | V6: =SUM(U6-V5) -> 102839032 | W6: =SUM(V6-W5) -> 102648042 | Y6: =W6-Y5 -> 102457053 | Z6: =Y6-Z5 -> 102266064 | AA6: =Z6-AA5 -> 102075075 | AB6: =AA6-AB5 -> 101884086 | AC6: =AB6-AC5 -> 101693097 | AD6: =AC6-AD5 -> 101502107 | AE6: =AD6-AE5 -> 101311118 | AF6: =AE6-AF5 -> 101120129 | AG6: =AF6-AG5 -> 100929140 | ... AJ6: =AI6-AJ5 -> 100356171
A7: 管理費・修繕積立金等 | B7: 円 | C7: 83551 | Q7: 70075 | R7: 83551 | S7: 83551 | T7: 83551 | U7: 83551 | V7: 83551 | W7: 83551 | Y7: 83551 | Z7: 83551 | AA7: 83551 | AB7: 83551 | AC7: 83551 | AD7: 83551 | AE7: 83551 | AF7: 83551 | AG7: 83551 | AH7: 83551 | AI7: 83551 | AJ7: 83551
A8: 管理委託手数料 | B8: 円
A9: 諸経費（税金、募集経費等） | B9: 円 | C9: 55179520 | D9: 0 | E9: 0 | F9: 0 | G9: 0 | H9: 0 | I9: 0 | J9: 0 | L9: 0 | M9: 0 | N9: 0 | O9: 0 | P9: 0 | Q9: -1405 | R9: 2218 | S9: 1294 | T9: 5933 | U9: 136130 | V9: 1766 | W9: 2612 | Y9: 2687
A10: ネット賃貸収入利回り | B10: 円
A11: 取得時簿価利回り | B11: 円
A12: 残存簿価利回り | B12: 円
A13: CF | B13: 円 | D13: =SUM(D4-D7-D8-D9) -> 0 | E13: =SUM(E4-E7-E8-E9) -> 0 | F13: =SUM(F4-F7-F8-F9) -> 0 | G13: =SUM(G4-G7-G8-G9) -> 0 | H13: =SUM(H4-H7-H8-H9) -> 0 | I13: =SUM(I4-I7-I8-I9) -> 0 | J13: =SUM(J4-J7-J8-J9) -> 0 | L13: =SUM(L4-L7-L8-L9) -> 0 | M13: =SUM(M4-M7-M8-M9) -> 0 | N13: =SUM(N4-N7-N8-N9) -> 0 | O13: =SUM(O4-O7-O8-O9) -> 0 | P13: =SUM(P4-P7-P8-P9) -> 0 | Q13: =SUM(Q4-Q7-Q8-Q9) -> -68670 | R13: =SUM(R4-R7-R8-R9) -> -85769 | S13: =SUM(S4-S7-S8-S9) -> -84845 | ... W13: =SUM(W4-W7-W8-W9) -> -86163 | Y13: =SUM(Y4-Y7-Y8-Y9) -> -86238 | Z13: =SUM(Z4-Z7-Z8-Z9) -> 516449 | AA13: =SUM(AA4-AA7-AA8-AA9) -> 516449 | AB13: =SUM(AB4-AB7-AB8-AB9) -> 516449 | AC13: =SUM(AC4-AC7-AC8-AC9) -> 516449 | AD13: =SUM(AD4-AD7-AD8-AD9) -> 516449 | AE13: =SUM(AE4-AE7-AE8-AE9) -> 516449 | AF13: =SUM(AF4-AF7-AF8-AF9) -> -83551 | ... AJ13: =SUM(AJ4-AJ7-AJ8-AJ9) -> -83551
A14: PL | B14: 円
A15: 株式会社SO | Y15: 2025/08/17契約

Sheet パークリュクス白金
C1: 2024 | D1: 45322 | E1: 45350 | F1: 45382 | G1: 45412 | H1: 45443 | I1: 45473 | J1: 45504 | K1: 2025 | L1: 45535 | M1: 45565 | N1: 45596 | O1: 45626 | P1: 45657 | Q1: 45688 | R1: 45716 | S1: 45747 | T1: 45777 | U1: 45808 | V1: 45838 | W1: 45869 | X1: 2026 | Y1: 45900 | Z1: 45930 | AA1: 45961 | AB1: 45991 | AC1: 46022 | AD1: 46053 | AE1: 46081 | AF1: 46112 | AG1: 46142 | AH1: 46173 | AI1: 46203 | AJ1: 46234
A2: パークリュクス白金monoグレージュ801 | C2: 46038
A3: 取得価格 | B3: 円 | C3: 150000000
A4: 賃料収入 | B4: 円 | Y4: 0 | Z4: 0 | AA4: 0 | AB4: 0 | AC4: 0 | AD4: 0 | AE4: 0
A5: 減価償却費 | B5: 円 | Y5: 0 | AD5: 115832 | AE5: 115832 | AF5: 115832 | AG5: 115832 | AH5: 115832 | AI5: 115832 | AJ5: 115832
A6: 残存簿価 | B6: 円 | C6: 49642320 | Y6: =C6-Y5 -> 49642320 | Z6: =Y6-Z5 -> 49642320 | AA6: =Z6-AA5 -> 49642320 | AB6: =AA6-AB5 -> 49642320 | AC6: 49642320 | AD6: =AC6-AD5 -> 49526488 | AE6: =AD6-AE5 -> 49410656 | AF6: =AE6-AF5 -> 49294824 | AG6: =AF6-AG5 -> 49178992 | AH6: =AG6-AH5 -> 49063160 | AI6: =AH6-AI5 -> 48947328 | AJ6: =AI6-AJ5 -> 48831496
A7: 管理費・修繕積立金等 | B7: 円 | C7: 45568 | AF7: 45568
A8: 管理委託手数料 | B8: 円
A9: 諸経費（税金、募集経費等） | B9: 円 | C9: 5295115
A10: ネット賃貸収入利回り | B10: 円
A11: 取得時簿価利回り | B11: 円
A12: 残存簿価利回り | B12: 円
A13: CF | B13: 円 | D13: =SUM(D4-D7-D8-D9) -> 0 | E13: =SUM(E4-E7-E8-E9) -> 0 | F13: =SUM(F4-F7-F8-F9) -> 0 | G13: =SUM(G4-G7-G8-G9) -> 0 | H13: =SUM(H4-H7-H8-H9) -> 0 | I13: =SUM(I4-I7-I8-I9) -> 0 | J13: =SUM(J4-J7-J8-J9) -> 0 | L13: =SUM(L4-L7-L8-L9) -> 0 | M13: =SUM(M4-M7-M8-M9) -> 0 | N13: =SUM(N4-N7-N8-N9) -> 0 | O13: =SUM(O4-O7-O8-O9) -> 0 | P13: =SUM(P4-P7-P8-P9) -> 0 | Q13: =SUM(Q4-Q7-Q8-Q9) -> 0 | R13: =SUM(R4-R7-R8-R9) -> 0 | S13: =SUM(S4-S7-S8-S9) -> 0 | ... W13: =SUM(W4-W7-W8-W9) -> 0 | Y13: =SUM(Y4-Y7-Y8-Y9) -> 0 | Z13: =SUM(Z4-Z7-Z8-Z9) -> 0 | AA13: =SUM(AA4-AA7-AA8-AA9) -> 0 | AB13: =SUM(AB4-AB7-AB8-AB9) -> 0 | AC13: =SUM(AC4-AC7-AC8-AC9) -> 0 | AD13: =SUM(AD4-AD7-AD8-AD9) -> 0 | AE13: =SUM(AE4-AE7-AE8-AE9) -> 0 | AF13: =SUM(AF4-AF7-AF8-AF9) -> -45568 | ... AJ13: =SUM(AJ4-AJ7-AJ8-AJ9) -> 0
A14: PL | B14: 円

Sheet 広尾ガーデンフォレストA棟509
C1: 2024 | D1: 45322 | E1: 45350 | F1: 45382 | G1: 45412 | H1: 45443 | I1: 45473 | J1: 45504 | K1: 2025 | L1: 45535 | M1: 45565 | N1: 45596 | O1: 45626 | P1: 45657 | Q1: 45688 | R1: 45716 | S1: 45747 | T1: 45777 | U1: 45808 | V1: 45838 | W1: 45869 | X1: 2026 | Y1: 45900 | Z1: 45930 | AA1: 45961 | AB1: 45991 | AC1: 46022 | AD1: 46053 | AE1: 46081 | AF1: 46112 | AG1: 46142 | AH1: 46173 | AI1: 46203 | AJ1: 46234
A2: 広尾ガーデンフォレストA棟509 | C2: 45740
A3: 取得価格 | B3: 円 | C3: 160000000
A4: 賃料収入 | B4: 円 | Y4: 0 | Z4: 0 | AA4: 0 | AB4: 0 | AC4: 0 | AD4: 0 | AE4: 0
A5: 減価償却費 | B5: 円 | Y5: 163442 | Z5: 163442 | AA5: 163442 | AB5: 163442 | AC5: 163442 | AD5: 163444 | AE5: 163442 | AF5: 163442 | AG5: 163442 | AH5: 163442 | AI5: 163442 | AJ5: 163444
A6: 残存簿価 | B6: 円 | C6: 63268032 | W6: 62450821 | Y6: =W6-Y5 -> 62287379 | Z6: =Y6-Z5 -> 62123937 | AA6: =Z6-AA5 -> 61960495 | AB6: =AA6-AB5 -> 61797053 | AC6: =AB6-AC5 -> 61633611 | AD6: =AC6-AD5 -> 61470167 | AE6: =AD6-AE5 -> 61306725 | AF6: =AE6-AF5 -> 61143283 | AG6: =AF6-AG5 -> 60979841 | ... AJ6: =AI6-AJ5 -> 60489513
A7: 管理費・修繕積立金等 | B7: 円 | C7: 74830 | S7: 168971 | V7: 74830 | W7: 74830 | Y7: 77210 | Z7: 77210 | AA7: 77210 | AB7: 77210 | AC7: 77210 | AD7: 77210 | AE7: 77210 | AF7: 77210 | AG7: 77210 | AH7: 77210 | AI7: 77210 | AJ7: 77210
A8: 管理委託手数料 | B8: 円 | Y8: 0 | Z8: 0 | AA8: 0 | AB8: 0 | AC8: 0 | AD8: 0 | AE8: 0
A9: 諸経費（税金、募集経費等） | B9: 円 | C9: 5472474 | S9: 182312 | T9: 3096 | U9: 1124 | V9: 5479 | W9: 4657 | Y9: 5337 | Z9: 3710 | AA9: 5109 | AB9: 4669 | AC9: 8497 | AD9: 4281 | AE9: 7517 | AF9: 3711 | AG9: 8047
A10: ネット賃貸収入利回り | B10: 円
A11: 取得時簿価利回り | B11: 円
A12: 残存簿価利回り | B12: 円
A13: CF | B13: 円 | D13: =SUM(D4-D7-D8-D9) -> 0 | E13: =SUM(E4-E7-E8-E9) -> 0 | F13: =SUM(F4-F7-F8-F9) -> 0 | G13: =SUM(G4-G7-G8-G9) -> 0 | H13: =SUM(H4-H7-H8-H9) -> 0 | I13: =SUM(I4-I7-I8-I9) -> 0 | J13: =SUM(J4-J7-J8-J9) -> 0 | L13: =SUM(L4-L7-L8-L9) -> 0 | M13: =SUM(M4-M7-M8-M9) -> 0 | N13: =SUM(N4-N7-N8-N9) -> 0 | O13: =SUM(O4-O7-O8-O9) -> 0 | P13: =SUM(P4-P7-P8-P9) -> 0 | Q13: =SUM(Q4-Q7-Q8-Q9) -> 0 | R13: =SUM(R4-R7-R8-R9) -> 0 | S13: =SUM(S4-S7-S8-S9) -> -351283 | ... W13: =SUM(W4-W7-W8-W9) -> -79487 | Y13: =SUM(Y4-Y7-Y8-Y9) -> -82547 | Z13: =SUM(Z4-Z7-Z8-Z9) -> -80920 | AA13: =SUM(AA4-AA7-AA8-AA9) -> -82319 | AB13: =SUM(AB4-AB7-AB8-AB9) -> -81879 | AC13: =SUM(AC4-AC7-AC8-AC9) -> -85707 | AD13: =SUM(AD4-AD7-AD8-AD9) -> -81491 | AE13: =SUM(AE4-AE7-AE8-AE9) -> -84727 | AF13: =SUM(AF4-AF7-AF8-AF9) -> -80921 | ... AJ13: =SUM(AJ4-AJ7-AJ8-AJ9) -> -77210
A14: PL | B14: 円

Sheet プラウド白金台601
C1: 2024 | D1: 45322 | E1: 45350 | F1: 45382 | G1: 45412 | H1: 45443 | I1: 45473 | J1: 45504 | K1: 2025 | L1: 45535 | M1: 45565 | N1: 45596 | O1: 45626 | P1: 45657 | Q1: 45688 | R1: 45716 | S1: 45747 | T1: 45777 | U1: 45808 | V1: 45838 | W1: 45869 | X1: 2026 | Y1: 45900 | Z1: 45930 | AA1: 45961 | AB1: 45991 | AC1: 46022 | AD1: 46053 | AE1: 46081 | AF1: 46112 | AG1: 46142 | AH1: 46173 | AI1: 46203 | AJ1: 46234
A2: プラウド白金台601 | C2: 45930
A3: 取得価格 | B3: 円 | C3: 1250000000
A4: 賃料収入 | B4: 円 | Y4: 0 | Z4: 0 | AA4: 0 | AB4: 0 | AC4: 0 | AD4: 0 | AE4: 0
A5: 減価償却費 | B5: 円 | Y5: 0 | Z5: 880693 | AA5: 880693 | AB5: 880693 | AC5: 880693 | AD5: 880696 | AE5: 880693 | AF5: 880693 | AG5: 880693 | AH5: 880693 | AI5: 880693 | AJ5: 880697
A6: 残存簿価 | B6: 円 | C6: 406474003 | Y6: =C6-Y5 -> 406474003 | Z6: =Y6-Z5 -> 405593310 | AA6: =Z6-AA5 -> 404712617 | AB6: =AA6-AB5 -> 403831924 | AC6: =AB6-AC5 -> 402951231 | AD6: =AC6-AD5 -> 402070535 | AE6: =AD6-AE5 -> 401189842 | AF6: =AE6-AF5 -> 400309149 | AG6: =AF6-AG5 -> 399428456 | ... AJ6: =AI6-AJ5 -> 396786373
A7: 管理費・修繕積立金等 | B7: 円 | AC7: 338400 | AD7: 338400
A8: 管理委託手数料 | B8: 円
A9: 諸経費（税金、募集経費等） | B9: 円 | AA9: 6787 | AB9: 7925 | AC9: 7898 | AD9: 8028 | AE9: 7934 | AF9: 3186100 | AG9: 7953
A10: ネット賃貸収入利回り | B10: 円
A11: 取得時簿価利回り | B11: 円
A12: 残存簿価利回り | B12: 円
A13: CF | B13: 円 | D13: =SUM(D4-D7-D8-D9) -> 0 | E13: =SUM(E4-E7-E8-E9) -> 0 | F13: =SUM(F4-F7-F8-F9) -> 0 | G13: =SUM(G4-G7-G8-G9) -> 0 | H13: =SUM(H4-H7-H8-H9) -> 0 | I13: =SUM(I4-I7-I8-I9) -> 0 | J13: =SUM(J4-J7-J8-J9) -> 0 | L13: =SUM(L4-L7-L8-L9) -> 0 | M13: =SUM(M4-M7-M8-M9) -> 0 | N13: =SUM(N4-N7-N8-N9) -> 0 | O13: =SUM(O4-O7-O8-O9) -> 0 | P13: =SUM(P4-P7-P8-P9) -> 0 | Q13: =SUM(Q4-Q7-Q8-Q9) -> 0 | R13: =SUM(R4-R7-R8-R9) -> 0 | S13: =SUM(S4-S7-S8-S9) -> 0 | ... W13: =SUM(W4-W7-W8-W9) -> 0 | Y13: =SUM(Y4-Y7-Y8-Y9) -> 0 | Z13: =SUM(Z4-Z7-Z8-Z9) -> 0 | AA13: =SUM(AA4-AA7-AA8-AA9) -> -6787 | AB13: =SUM(AB4-AB7-AB8-AB9) -> -7925 | AC13: =SUM(AC4-AC7-AC8-AC9) -> -346298 | AD13: =SUM(AD4-AD7-AD8-AD9) -> -346428 | AE13: =SUM(AE4-AE7-AE8-AE9) -> -7934 | AF13: =SUM(AF4-AF7-AF8-AF9) -> -3186100 | ... AJ13: =SUM(AJ4-AJ7-AJ8-AJ9) -> 0
A14: PL | B14: 円

Sheet 海老名Ⅱ723
C1: 2024 | D1: 45322 | E1: 45350 | F1: 45382 | G1: 45412 | H1: 45443 | I1: 45473 | J1: 45504 | K1: 2025 | L1: 45535 | M1: 45565 | N1: 45596 | O1: 45626 | P1: 45657 | Q1: 45688 | R1: 45716 | S1: 45747 | T1: 45777 | U1: 45808 | V1: 45838 | W1: 45869 | X1: 2026 | Y1: 45900 | Z1: 45930 | AA1: 45961 | AB1: 45991 | AC1: 46022 | AD1: 46053 | AE1: 46081 | AF1: 46112 | AG1: 46142 | AH1: 46173 | AI1: 46203 | AJ1: 46234
A2: セントガーデン海老名Ⅱ街区 723 | C2: 45387
A3: 取得価格 | B3: 円 | C3: 54580000
A4: 賃料収入 | B4: 円 | C4: 221000 | D4: 0 | E4: 0 | F4: 0 | G4: 0 | H4: 0 | I4: 0 | J4: 0 | L4: 0 | M4: 0 | N4: 0 | O4: 0 | P4: 0 | Q4: 0 | R4: 449700 | S4: 229900 | T4: 229900 | U4: 229900 | V4: 229900 | W4: 229900 | Y4: 229900 | Z4: 229900 | AA4: 229900 | AB4: 229900 | AC4: 229900 | AD4: 229900 | AE4: 229900 | AF4: 229900 | AG4: 229900
A5: 減価償却費 | B5: 円 | G5: 38896 | H5: 38896 | I5: 38896 | J5: 38899 | L5: 38896 | M5: 38896 | N5: 38896 | O5: 38896 | P5: 38896 | Q5: 38901 | R5: 38896 | S5: 38896 | T5: 38896 | U5: 38896 | V5: 38896 | W5: 38902 | Y5: 38896 | Z5: 38896 | AA5: 38896 | AB5: 38896 | AC5: 38896 | AD5: 38901 | AE5: 38896 | AF5: 38896 | AG5: 38896 | AH5: 38896 | AI5: 38896 | AJ5: 38902
A6: 残存簿価 | B6: 円 | C6: 21216534 | G6: =SUM(C6-G5) -> 21177638 | H6: =SUM(G6-H5) -> 21138742 | I6: =SUM(H6-I5) -> 21099846 | J6: =SUM(I6-J5) -> 21060947 | L6: =SUM(J6-L5) -> 21022051 | M6: =SUM(L6-M5) -> 20983155 | N6: =SUM(M6-N5) -> 20944259 | O6: =SUM(N6-O5) -> 20905363 | P6: =SUM(O6-P5) -> 20866467 | Q6: =SUM(P6-Q5) -> 20827566 | R6: =SUM(Q6-R5) -> 20788670 | S6: =SUM(R6-S5) -> 20749774 | T6: =SUM(S6-T5) -> 20710878 | ... W6: =SUM(V6-W5) -> 20594184 | Y6: =SUM(W6-Y5) -> 20555288 | Z6: =SUM(Y6-Z5) -> 20516392 | AA6: =SUM(Z6-AA5) -> 20477496 | AB6: =SUM(AA6-AB5) -> 20438600 | AC6: =SUM(AB6-AC5) -> 20399704 | AD6: =SUM(AC6-AD5) -> 20360803 | AE6: =SUM(AD6-AE5) -> 20321907 | AF6: =SUM(AE6-AF5) -> 20283011 | AG6: =SUM(AF6-AG5) -> 20244115 | ... AJ6: =SUM(AI6-AJ5) -> 20127421
A7: 管理費・修繕積立金等 | B7: 円 | C7: 30570 | G7: 0 | H7: 30570 | I7: 30570 | J7: 30570 | L7: 30570 | M7: 30570 | N7: 30570 | O7: 30570 | P7: 30570 | Q7: 30570 | R7: 30570 | S7: 30570 | T7: 30570 | U7: 30570 | V7: 30570 | W7: 30570 | Y7: 30570 | Z7: 30570 | AA7: 30570 | AB7: 30570 | AC7: 30570 | AD7: 30570 | AE7: 30570 | AF7: 30570 | AG7: 30570 | AH7: 30570 | AI7: 30570 | AJ7: 30570
A8: 管理委託手数料 | B8: 円 | G8: 0 | H8: 0 | I8: 0 | J8: 0 | L8: 0 | M8: 0 | N8: 0 | O8: 0 | P8: 0 | Q8: 0 | R8: 5038 | S8: 5038 | T8: 5038 | U8: 5038 | V8: 5038 | W8: 5038 | Y8: 5038 | Z8: 5038 | AA8: 5038 | AB8: 5038 | AC8: 5038 | AD8: 5038 | AE8: 5038 | AF8: 5038 | AG8: 5038
A9: 諸経費（税金、募集経費等） | B9: 円 | C9: 721000 | D9: 0 | E9: 0 | F9: 0 | G9: 216000 | H9: 162800 | I9: 0 | J9: 0 | L9: 0 | M9: 0 | N9: 0 | O9: 0 | P9: 0 | Q9: 232100 | R9: 0 | S9: 0 | T9: 0 | U9: 89648 | V9: 0 | W9: 0 | Y9: 0 | Z9: 0
A10: ネット賃貸収入利回り | B10: 円
A11: 取得時簿価利回り | B11: 円
A12: 残存簿価利回り | B12: 円
