Workbook

Sheet NY不動産(総計)
A1: 総計 | B1: 2024 | C1: 45412 | D1: 45443 | E1: 45473 | F1: 45504 | G1: 2025 | H1: 45535 | I1: 45565 | J1: 45596 | K1: 45626 | L1: 45657 | M1: 45688 | N1: 45716 | O1: 45747 | P1: 45777 | Q1: 45808 | R1: 45838 | S1: 45869 | T1: 2026 | U1: 45900 | V1: 45930 | W1: 45961 | X1: 45991 | Y1: 46022 | Z1: 46053 | AA1: 46081 | AB1: 46112 | AC1: 46142 | AD1: 46173 | AE1: 46203 | AF1: 46234
A2: 取得簿価(円) | B2: =B3*150 -> 4049634000
A3: 取得簿価(ドル) | B3: =SUM('1Wall#831:248-250W102nd'!B3) -> 26997560
A4: 賃料収入(円) | B4: =SUM(B6*B5) -> 25541112 | C4: =SUM(C6*C5) -> 0 | D4: =SUM(D6*D5) -> 103473.48 | E4: =SUM(E6*E5) -> 729647.1 | F4: =SUM(F6*F5) -> 1864640 | H4: =SUM(H6*H5) -> 2156131.4 | I4: =SUM(I6*I5) -> 3158809 | J4: =SUM(J6*J5) -> 3858278.4 | K4: =SUM(K6*K5) -> 4643609 | L4: =SUM(L6*L5) -> 6271974.6 | M4: =SUM(M6*M5) -> 8600148 | N4: =SUM(N6*N5) -> 10893807 | O4: =SUM(O6*O5) -> 9594219.9 | ... S4: =SUM(S6*S5) -> 19852788 | U4: =SUM(U6*U5) -> 19973369 | V4: =SUM(V6*V5) -> 20026065 | W4: =SUM(W6*W5) -> 24261207 | X4: =SUM(X6*X5) -> 25523643 | Y4: =SUM(Y6*Y5) -> 24479747 | Z4: =SUM(Z6*Z5) -> 24411990 | AA4: =SUM(AA6*AA5) -> 25966651 | AB4: =SUM(AB6*AB5) -> 25381773 | ... AF4: =SUM(AF6*AF5) -> 0
A5: 為替レート(ドル円)TTM | B5: 150 | C5: 156.9 | D5: 156.74 | E5: 161.07 | F5: 152.44 | H5: 144.8 | I5: 142.73 | J5: 153.64 | K5: 150.74 | L5: 158.18 | M5: 154.43 | N5: 149.67 | O5: 149.52 | P5: 142.57 | Q5: 143.87 | R5: 144.81 | S5: 149.39 | U5: 146.92 | V5: 148.88 | W5: 154.1 | X5: 156.63 | Y5: 156.56 | Z5: 153.66 | AA5: 155.81 | AB5: 159.88 | AC5: 160.39 | AG5: ※月末TTMベース
A6: 賃料収入(ドル) | B6: =SUM('1Wall#831:248-250W102nd'!B6) -> 170274.08 | C6: =SUM('1Wall#831:248-250W102nd'!C6) -> 0 | D6: =SUM('1Wall#831:248-250W102nd'!D6) -> 660.16 | E6: =SUM('1Wall#831:248-250W102nd'!E6) -> 4530 | F6: =SUM('1Wall#831:248-250W102nd'!F6) -> 12231.96 | H6: =SUM('1Wall#831:248-250W102nd'!H6) -> 14890.41 | I6: =SUM('1Wall#831:248-250W102nd'!I6) -> 22131.36 | J6: =SUM('1Wall#831:248-250W102nd'!J6) -> 25112.46 | K6: =SUM('1Wall#831:248-250W102nd'!K6) -> 30805.42 | L6: =SUM('1Wall#831:248-250W102nd'!L6) -> 39650.87 | M6: =SUM('1Wall#831:248-250W102nd'!M6) -> 55689.62 | N6: =SUM('1Wall#831:248-250W102nd'!N6) -> 72785.51 | O6: =SUM('1Wall#831:248-250W102nd'!O6) -> 64166.8 | ... S6: =SUM('1Wall#831:248-250W102nd'!S6) -> 132892.35 | U6: =SUM('1Wall#831:248-250W102nd'!U6) -> 135947.24 | V6: =SUM('1Wall#831:248-250W102nd'!V6) -> 134511.45 | W6: =SUM('1Wall#831:248-250W102nd'!W6) -> 157438.07 | X6: =SUM('1Wall#831:248-250W102nd'!X6) -> 162955.01 | Y6: =SUM('1Wall#831:248-250W102nd'!Y6) -> 156360.16 | Z6: =SUM('1Wall#831:248-250W102nd'!Z6) -> 158870.17 | AA6: =SUM('1Wall#831:248-250W102nd'!AA6) -> 166655.87 | AB6: =SUM('1Wall#831:248-250W102nd'!AB6) -> 158755.15 | ... AF6: =SUM('1Wall#831:248-250W102nd'!AF6) -> 0
A7: 減価償却費(円) | B7: =SUM('1Wall#831:248-250W102nd'!B7) -> 3059113726 | C7: =SUM('1Wall#831:248-250W102nd'!C7) -> 3668273 | D7: =SUM('1Wall#831:248-250W102nd'!D7) -> 4938140 | E7: =SUM('1Wall#831:248-250W102nd'!E7) -> 4938140 | F7: =SUM('1Wall#831:248-250W102nd'!F7) -> 6177180 | H7: =SUM('1Wall#831:248-250W102nd'!H7) -> 6177172 | I7: =SUM('1Wall#831:248-250W102nd'!I7) -> 8862692 | J7: =SUM('1Wall#831:248-250W102nd'!J7) -> 8862692 | K7: =SUM('1Wall#831:248-250W102nd'!K7) -> 10536573 | L7: =SUM('1Wall#831:248-250W102nd'!L7) -> 11807263 | M7: =SUM('1Wall#831:248-250W102nd'!M7) -> 28855758 | N7: =SUM('1Wall#831:248-250W102nd'!N7) -> 28855724 | O7: =SUM('1Wall#831:248-250W102nd'!O7) -> 28855724 | ... S7: =SUM('1Wall#831:248-250W102nd'!S7) -> 40483129 | U7: =SUM('1Wall#831:248-250W102nd'!U7) -> 46486085 | V7: =SUM('1Wall#831:248-250W102nd'!V7) -> 46486085 | W7: =SUM('1Wall#831:248-250W102nd'!W7) -> 48253271 | X7: =SUM('1Wall#831:248-250W102nd'!X7) -> 48253271 | Y7: =SUM('1Wall#831:248-250W102nd'!Y7) -> 48253271 | Z7: =SUM('1Wall#831:248-250W102nd'!Z7) -> 48253325 | AA7: =SUM('1Wall#831:248-250W102nd'!AA7) -> 48253271 | AB7: =SUM('1Wall#831:248-250W102nd'!AB7) -> 48253271 | ... AF7: =SUM('1Wall#831:248-250W102nd'!AF7) -> 48253335
A8: 減価償却費(ドル)
A9: 残存簿価(円) | B9: =SUM('1Wall#831:248-250W102nd'!B9) -> 3056520279 | C9: =SUM('1Wall#831:248-250W102nd'!C9) -> 386767709 | D9: =SUM('1Wall#831:248-250W102nd'!D9) -> 517886837 | E9: =SUM('1Wall#831:248-250W102nd'!E9) -> 512948697 | F9: =SUM('1Wall#831:248-250W102nd'!F9) -> 639525030 | H9: =SUM('1Wall#831:248-250W102nd'!H9) -> 633347858 | I9: =SUM('1Wall#831:248-250W102nd'!I9) -> 912219591 | J9: =SUM('1Wall#831:248-250W102nd'!J9) -> 903356899 | K9: =SUM('1Wall#831:248-250W102nd'!K9) -> 1072164906 | L9: =SUM('1Wall#831:248-250W102nd'!L9) -> 1196503072 | M9: =SUM('1Wall#831:248-250W102nd'!M9) -> 1985973482 | N9: =SUM('1Wall#831:248-250W102nd'!N9) -> 1957117758 | O9: =SUM('1Wall#831:248-250W102nd'!O9) -> 1928262034 | ... S9: =SUM('1Wall#831:248-250W102nd'!S9) -> 3147295398 | U9: =SUM('1Wall#831:248-250W102nd'!U9) -> 3100809313 | V9: =SUM('1Wall#831:248-250W102nd'!V9) -> 3181306658 | W9: =SUM('1Wall#831:248-250W102nd'!W9) -> 3133053387 | X9: =SUM('1Wall#831:248-250W102nd'!X9) -> 3084800116 | Y9: =SUM('1Wall#831:248-250W102nd'!Y9) -> 3036546845 | Z9: =SUM('1Wall#831:248-250W102nd'!Z9) -> 2988293520 | AA9: =SUM('1Wall#831:248-250W102nd'!AA9) -> 2940040249 | AB9: =SUM('1Wall#831:248-250W102nd'!AB9) -> 2891786978 | ... AF9: =SUM('1Wall#831:248-250W102nd'!AF9) -> 2698773830
A10: 残存簿価(ドル)
A11: 管理費(ドル) | C11: =SUM('1Wall#831:248-250W102nd'!C11) -> 1263.27 | D11: =SUM('1Wall#831:248-250W102nd'!D11) -> 300 | E11: =SUM('1Wall#831:248-250W102nd'!E11) -> 300 | F11: =SUM('1Wall#831:248-250W102nd'!F11) -> 1228 | H11: =SUM('1Wall#831:248-250W102nd'!H11) -> 6944 | I11: =SUM('1Wall#831:248-250W102nd'!I11) -> 8024.5 | J11: =SUM('1Wall#831:248-250W102nd'!J11) -> 3140.45 | K11: =SUM('1Wall#831:248-250W102nd'!K11) -> 14560.22 | L11: =SUM('1Wall#831:248-250W102nd'!L11) -> 3080.66 | M11: =SUM('1Wall#831:248-250W102nd'!M11) -> 3949.2 | N11: =SUM('1Wall#831:248-250W102nd'!N11) -> 4685.5 | O11: =SUM('1Wall#831:248-250W102nd'!O11) -> 4487.5 | ... S11: =SUM('1Wall#831:248-250W102nd'!S11) -> 7972.87 | U11: =SUM('1Wall#831:248-250W102nd'!U11) -> 8011.55 | V11: =SUM('1Wall#831:248-250W102nd'!V11) -> 7939.96 | W11: =SUM('1Wall#831:248-250W102nd'!W11) -> 9416.4 | X11: =SUM('1Wall#831:248-250W102nd'!X11) -> 9401.96 | Y11: =SUM('1Wall#831:248-250W102nd'!Y11) -> 7783.89 | Z11: =SUM('1Wall#831:248-250W102nd'!Z11) -> 9363.12 | AA11: =SUM('1Wall#831:248-250W102nd'!AA11) -> 9482.16 | AB11: =SUM('1Wall#831:248-250W102nd'!AB11) -> 9705.87 | ... AF11: =SUM('1Wall#831:248-250W102nd'!AF11) -> 0
A12: 諸経費(税金、募集経費等)(ドル) | B12: =SUM('1Wall#831:248-250W102nd'!B12) -> 933135.06 | C12: =SUM('1Wall#831:248-250W102nd'!C12) -> 2980.36 | D12: =SUM('1Wall#831:248-250W102nd'!D12) -> 15580.58 | E12: =SUM('1Wall#831:248-250W102nd'!E12) -> 10500.52 | F12: =SUM('1Wall#831:248-250W102nd'!F12) -> 11039.94 | H12: =SUM('1Wall#831:248-250W102nd'!H12) -> 13185.91 | I12: =SUM('1Wall#831:248-250W102nd'!I12) -> 52022.08 | J12: =SUM('1Wall#831:248-250W102nd'!J12) -> 19726.18 | K12: =SUM('1Wall#831:248-250W102nd'!K12) -> 15135.99 | L12: =SUM('1Wall#831:248-250W102nd'!L12) -> 36335.8 | M12: =SUM('1Wall#831:248-250W102nd'!M12) -> 15063.16 | N12: =SUM('1Wall#831:248-250W102nd'!N12) -> 25078.89 | O12: =SUM('1Wall#831:248-250W102nd'!O12) -> 32325.54 | ... S12: =SUM('1Wall#831:248-250W102nd'!S12) -> 157874.59 | U12: =SUM('1Wall#831:248-250W102nd'!U12) -> 54594.46 | V12: =SUM('1Wall#831:248-250W102nd'!V12) -> 69155.82 | W12: =SUM('1Wall#831:248-250W102nd'!W12) -> 72882.19 | X12: =SUM('1Wall#831:248-250W102nd'!X12) -> 39175.31 | Y12: =SUM('1Wall#831:248-250W102nd'!Y12) -> 48187.08 | Z12: =SUM('1Wall#831:248-250W102nd'!Z12) -> 54711.57 | AA12: =SUM('1Wall#831:248-250W102nd'!AA12) -> 46105.46 | AB12: =SUM('1Wall#831:248-250W102nd'!AB12) -> 57886.17 | ... AF12: =SUM('1Wall#831:248-250W102nd'!AF12) -> 0
A13: ネット賃貸収入利回り(円)
A14: ネット賃貸収入利回り(ドル)
A15: 取得時簿価利回り(円)
A16: 取得時簿価利回り(ドル)
A17: 残存簿価利回り(円)
A18: 残存簿価利回り(ドル)
A19: CF(円) | C19: =SUM(C5*C20) -> -665825.55 | D19: =SUM(D5*D20) -> -2385648.6 | E19: =SUM(E5*E20) -> -1009992.7 | F19: =SUM(F5*F20) -> -5484.7912 | G19: =SUM(C19:F19) -> -4066951.6 | H19: =SUM(H5*H20) -> -758679.6 | I19: =SUM(I5*I20) -> -5411639.4 | J19: =SUM(J5*J20) -> 345049.32 | K19: =SUM(K5*K20) -> 167202.32 | L19: =SUM(L5*L20) -> 37078.974 | M19: =SUM(M5*M20) -> 5664069.3 | N19: =SUM(N5*N20) -> 6438971 | O19: =SUM(O5*O20) -> 4089934.2 | ... S19: =SUM(S5*S20) -> -4923163.9 | T19: =SUM(G19:S19) -> 5608030.4 | U19: =SUM(U5*U20) -> 10775294 | V19: =SUM(V5*V20) -> 8548044.9 | W19: =SUM(W5*W20) -> 11578994 | X19: =SUM(X5*X20) -> 17914985 | Y19: =SUM(Y5*Y20) -> 15716932 | Z19: =SUM(Z5*Z20) -> 14566273 | AA19: =SUM(AA5*AA20) -> 17305544 | AB19: =SUM(AB5*AB20) -> 14575158 | ... AF19: =SUM(AF5*AF20) -> 0 | AG19: =SUM(T19:AF19) -> 1.1845867e+08
A20: CF(ドル) | C20: =SUM('1Wall#831:248-250W102nd'!C20) -> -4243.63 | D20: =SUM('1Wall#831:248-250W102nd'!D20) -> -15220.42 | E20: =SUM('1Wall#831:248-250W102nd'!E20) -> -6270.52 | F20: =SUM('1Wall#831:248-250W102nd'!F20) -> -35.98 | G20: =SUM(C20:F20) -> -25770.55 | H20: =SUM('1Wall#831:248-250W102nd'!H20) -> -5239.5 | I20: =SUM('1Wall#831:248-250W102nd'!I20) -> -37915.22 | J20: =SUM('1Wall#831:248-250W102nd'!J20) -> 2245.83 | K20: =SUM('1Wall#831:248-250W102nd'!K20) -> 1109.21 | L20: =SUM('1Wall#831:248-250W102nd'!L20) -> 234.41 | M20: =SUM('1Wall#831:248-250W102nd'!M20) -> 36677.26 | N20: =SUM('1Wall#831:248-250W102nd'!N20) -> 43021.12 | O20: =SUM('1Wall#831:248-250W102nd'!O20) -> 27353.76 | ... S20: =SUM('1Wall#831:248-250W102nd'!S20) -> -32955.11 | T20: =SUM(G20:S20) -> 37700.3 | U20: =SUM('1Wall#831:248-250W102nd'!U20) -> 73341.23 | V20: =SUM('1Wall#831:248-250W102nd'!V20) -> 57415.67 | W20: =SUM('1Wall#831:248-250W102nd'!W20) -> 75139.48 | X20: =SUM('1Wall#831:248-250W102nd'!X20) -> 114377.74 | Y20: =SUM('1Wall#831:248-250W102nd'!Y20) -> 100389.19 | Z20: =SUM('1Wall#831:248-250W102nd'!Z20) -> 94795.48 | AA20: =SUM('1Wall#831:248-250W102nd'!AA20) -> 111068.25 | AB20: =SUM('1Wall#831:248-250W102nd'!AB20) -> 91163.11 | ... AF20: =SUM('1Wall#831:248-250W102nd'!AF20) -> 0 | AG20: =SUM(T20:AF20) -> 770032.03
A21: PL(円)
A22: PL(ドル)
A24: 購入日
A25: 下記表は固都税を各月の諸経費に分散して計上した表です
A26: 総計 | B26: 2024 | C26: 45412 | D26: 45443 | E26: 45473 | F26: 45504 | G26: 2025 | H26: 45535 | I26: 45565 | J26: 45596 | K26: 45626 | L26: 45657 | M26: 45688 | N26: 45716 | O26: 45747 | P26: 45777 | Q26: 45808 | R26: 45838 | S26: 45869 | T26: 2026 | U26: 45900 | V26: 45930 | W26: 45961 | X26: 45991 | Y26: 46022 | Z26: 46053 | AA26: 46081 | AB26: 46112 | AC26: 46142 | AD26: 46173 | AE26: 46203 | AF26: 46234
A27: 取得簿価(円) | B27: =B28*150 -> 4049634000
A28: 取得簿価(ドル) | B28: =SUM('1Wall#831:248-250W102nd'!B28) -> 26997560
A29: 賃料収入(円) | B29: =SUM(B31*B30) -> 11733750 | C29: =SUM(C31*C30) -> 0 | D29: =SUM(D31*D30) -> 103473.48 | E29: =SUM(E31*E30) -> 729647.1 | F29: =SUM(F31*F30) -> 1864640 | H29: =SUM(H31*H30) -> 2156131.4 | I29: =SUM(I31*I30) -> 3158809 | J29: =SUM(J31*J30) -> 3858278.4 | K29: =SUM(K31*K30) -> 4643609 | L29: =SUM(L31*L30) -> 6271974.6 | M29: =SUM(M31*M30) -> 8600148 | N29: =SUM(N31*N30) -> 10893807 | O29: =SUM(O31*O30) -> 9594219.9 | ... S29: =SUM(S31*S30) -> 19852788 | U29: =SUM(U31*U30) -> 19973369 | V29: =SUM(V31*V30) -> 20026065 | W29: =SUM(W31*W30) -> 24261207 | X29: =SUM(X31*X30) -> 25523643 | Y29: =SUM(Y31*Y30) -> 24479747 | Z29: =SUM(Z31*Z30) -> 24411990 | AA29: =SUM(AA31*AA30) -> 25966651 | AB29: =SUM(AB31*AB30) -> 23994076 | ... AF29: =SUM(AF31*AF30) -> 0
A30: 為替レート(ドル円)TTM | B30: 150 | C30: 156.9 | D30: 156.74 | E30: 161.07 | F30: 152.44 | H30: 144.8 | I30: 142.73 | J30: 153.64 | K30: 150.74 | L30: 158.18 | M30: 154.43 | N30: 149.67 | O30: 149.52 | P30: 142.57 | Q30: 143.87 | R30: 144.81 | S30: 149.39 | U30: 146.92 | V30: 148.88 | W30: 154.1 | X30: 156.63 | Y30: 156.56 | Z30: 153.66 | AA30: 155.81 | AB30: 159.88 | AC30: 160.39 | AG30: ※月末TTMベース
A31: 賃料収入(ドル) | B31: =SUM('1Wall#831:248-250W102nd'!B31) -> 78225 | C31: =SUM('1Wall#831:248-250W102nd'!C31) -> 0 | D31: =SUM('1Wall#831:248-250W102nd'!D31) -> 660.16 | E31: =SUM('1Wall#831:248-250W102nd'!E31) -> 4530 | F31: =SUM('1Wall#831:248-250W102nd'!F31) -> 12231.96 | H31: =SUM('1Wall#831:248-250W102nd'!H31) -> 14890.41 | I31: =SUM('1Wall#831:248-250W102nd'!I31) -> 22131.36 | J31: =SUM('1Wall#831:248-250W102nd'!J31) -> 25112.46 | K31: =SUM('1Wall#831:248-250W102nd'!K31) -> 30805.42 | L31: =SUM('1Wall#831:248-250W102nd'!L31) -> 39650.87 | M31: =SUM('1Wall#831:248-250W102nd'!M31) -> 55689.62 | N31: =SUM('1Wall#831:248-250W102nd'!N31) -> 72785.51 | O31: =SUM('1Wall#831:248-250W102nd'!O31) -> 64166.8 | ... S31: =SUM('1Wall#831:248-250W102nd'!S31) -> 132892.35 | U31: =SUM('1Wall#831:248-250W102nd'!U31) -> 135947.24 | V31: =SUM('1Wall#831:248-250W102nd'!V31) -> 134511.45 | W31: =SUM('1Wall#831:248-250W102nd'!W31) -> 157438.07 | X31: =SUM('1Wall#831:248-250W102nd'!X31) -> 162955.01 | Y31: =SUM('1Wall#831:248-250W102nd'!Y31) -> 156360.16 | Z31: =SUM('1Wall#831:248-250W102nd'!Z31) -> 158870.17 | AA31: =SUM('1Wall#831:248-250W102nd'!AA31) -> 166655.87 | AB31: =SUM('1Wall#831:248-250W102nd'!AB31) -> 150075.53 | ... AF31: =SUM('1Wall#831:248-250W102nd'!AF31) -> 0
A32: 減価償却費(円) | B32: =SUM('1Wall#831:248-250W102nd'!B32) -> 3059113726 | C32: =SUM('1Wall#831:248-250W102nd'!C32) -> 3668273 | D32: =SUM('1Wall#831:248-250W102nd'!D32) -> 4938140 | E32: =SUM('1Wall#831:248-250W102nd'!E32) -> 4938140 | F32: =SUM('1Wall#831:248-250W102nd'!F32) -> 6177180 | H32: =SUM('1Wall#831:248-250W102nd'!H32) -> 6177172 | I32: =SUM('1Wall#831:248-250W102nd'!I32) -> 8862692 | J32: =SUM('1Wall#831:248-250W102nd'!J32) -> 8862692 | K32: =SUM('1Wall#831:248-250W102nd'!K32) -> 10536573 | L32: =SUM('1Wall#831:248-250W102nd'!L32) -> 11807263 | M32: =SUM('1Wall#831:248-250W102nd'!M32) -> 28855758 | N32: =SUM('1Wall#831:248-250W102nd'!N32) -> 28855724 | O32: =SUM('1Wall#831:248-250W102nd'!O32) -> 28855724 | ... S32: =SUM('1Wall#831:248-250W102nd'!S32) -> 40483129 | U32: =SUM('1Wall#831:248-250W102nd'!U32) -> 46486085 | V32: =SUM('1Wall#831:248-250W102nd'!V32) -> 46486085 | W32: =SUM('1Wall#831:248-250W102nd'!W32) -> 46486085 | X32: =SUM('1Wall#831:248-250W102nd'!X32) -> 46486085 | Y32: =SUM('1Wall#831:248-250W102nd'!Y32) -> 46486085 | Z32: =SUM('1Wall#831:248-250W102nd'!Z32) -> 46486139 | AA32: =SUM('1Wall#831:248-250W102nd'!AA32) -> 46486085 | AB32: =SUM('1Wall#831:248-250W102nd'!AB32) -> 46486085 | ... AF32: =SUM('1Wall#831:248-250W102nd'!AF32) -> 46486149
A33: 減価償却費(ドル)
A34: 残存簿価(円) | B34: =SUM('1Wall#831:248-250W102nd'!B34) -> 3056520279 | C34: =SUM('1Wall#831:248-250W102nd'!C34) -> 386767709 | D34: =SUM('1Wall#831:248-250W102nd'!D34) -> 517886837 | E34: =SUM('1Wall#831:248-250W102nd'!E34) -> 512948697 | F34: =SUM('1Wall#831:248-250W102nd'!F34) -> 639525030 | H34: =SUM('1Wall#831:248-250W102nd'!H34) -> 633347858 | I34: =SUM('1Wall#831:248-250W102nd'!I34) -> 912219591 | J34: =SUM('1Wall#831:248-250W102nd'!J34) -> 903356899 | K34: =SUM('1Wall#831:248-250W102nd'!K34) -> 1072164906 | L34: =SUM('1Wall#831:248-250W102nd'!L34) -> 1196503072 | M34: =SUM('1Wall#831:248-250W102nd'!M34) -> 1985973482 | N34: =SUM('1Wall#831:248-250W102nd'!N34) -> 1957117758 | O34: =SUM('1Wall#831:248-250W102nd'!O34) -> 1928262034 | ... S34: =SUM('1Wall#831:248-250W102nd'!S34) -> 3147295398 | U34: =SUM('1Wall#831:248-250W102nd'!U34) -> 3100809313 | V34: =SUM('1Wall#831:248-250W102nd'!V34) -> 3054323228 | W34: =SUM('1Wall#831:248-250W102nd'!W34) -> 3007837143 | X34: =SUM('1Wall#831:248-250W102nd'!X34) -> 2961351058 | Y34: =SUM('1Wall#831:248-250W102nd'!Y34) -> 2914864973 | Z34: =SUM('1Wall#831:248-250W102nd'!Z34) -> 2868378834 | AA34: =SUM('1Wall#831:248-250W102nd'!AA34) -> 2821892749 | AB34: =SUM('1Wall#831:248-250W102nd'!AB34) -> 2775406664 | ... AF34: =SUM('1Wall#831:248-250W102nd'!AF34) -> 2589462260
A35: 残存簿価(ドル)
A36: 管理費(ドル) | C36: =SUM('1Wall#831:248-250W102nd'!C36) -> 1263.27 | D36: =SUM('1Wall#831:248-250W102nd'!D36) -> 300 | E36: =SUM('1Wall#831:248-250W102nd'!E36) -> 300 | F36: =SUM('1Wall#831:248-250W102nd'!F36) -> 1228 | H36: =SUM('1Wall#831:248-250W102nd'!H36) -> 6944 | I36: =SUM('1Wall#831:248-250W102nd'!I36) -> 8024.5 | J36: =SUM('1Wall#831:248-250W102nd'!J36) -> 3140.45 | K36: =SUM('1Wall#831:248-250W102nd'!K36) -> 14560.22 | L36: =SUM('1Wall#831:248-250W102nd'!L36) -> 3080.66 | M36: =SUM('1Wall#831:248-250W102nd'!M36) -> 3949.2 | N36: =SUM('1Wall#831:248-250W102nd'!N36) -> 4685.5 | O36: =SUM('1Wall#831:248-250W102nd'!O36) -> 4487.5 | ... S36: =SUM('1Wall#831:248-250W102nd'!S36) -> 7972.87 | U36: =SUM('1Wall#831:248-250W102nd'!U36) -> 8011.55 | V36: =SUM('1Wall#831:248-250W102nd'!V36) -> 7939.96 | W36: =SUM('1Wall#831:248-250W102nd'!W36) -> 9416.4 | X36: =SUM('1Wall#831:248-250W102nd'!X36) -> 9401.96 | Y36: =SUM('1Wall#831:248-250W102nd'!Y36) -> 7783.89 | Z36: =SUM('1Wall#831:248-250W102nd'!Z36) -> 9363.12 | AA36: =SUM('1Wall#831:248-250W102nd'!AA36) -> 9482.16 | AB36: =SUM('1Wall#831:248-250W102nd'!AB36) -> 8921.87 | ... AF36: =SUM('1Wall#831:248-250W102nd'!AF36) -> 0
A37: 諸経費(税金、募集経費等)(ドル) | C37: =SUM('1Wall#831:248-250W102nd'!C37) -> 2980.36 | D37: =SUM('1Wall#831:248-250W102nd'!D37) -> 15580.58 | E37: =SUM('1Wall#831:248-250W102nd'!E37) -> 7073.44 | F37: =SUM('1Wall#831:248-250W102nd'!F37) -> 12751.98 | H37: =SUM('1Wall#831:248-250W102nd'!H37) -> 14897.95 | I37: =SUM('1Wall#831:248-250W102nd'!I37) -> 11965.04 | J37: =SUM('1Wall#831:248-250W102nd'!J37) -> 19778.43 | K37: =SUM('1Wall#831:248-250W102nd'!K37) -> 22620.56 | L37: =SUM('1Wall#831:248-250W102nd'!L37) -> 28493.85 | M37: =SUM('1Wall#831:248-250W102nd'!M37) -> 21680.71 | N37: =SUM('1Wall#831:248-250W102nd'!N37) -> 34760.48 | O37: =SUM('1Wall#831:248-250W102nd'!O37) -> 36877.95 | ... S37: =SUM('1Wall#831:248-250W102nd'!S37) -> 60431.17 | U37: =SUM('1Wall#831:248-250W102nd'!U37) -> 76664.81 | V37: =SUM('1Wall#831:248-250W102nd'!V37) -> 84221.85 | W37: =SUM('1Wall#831:248-250W102nd'!W37) -> 95828.08 | X37: =SUM('1Wall#831:248-250W102nd'!X37) -> 62121.19 | Y37: =SUM('1Wall#831:248-250W102nd'!Y37) -> 63836.76 | Z37: =SUM('1Wall#831:248-250W102nd'!Z37) -> 79116.69 | AA37: =SUM('1Wall#831:248-250W102nd'!AA37) -> 70510.58 | AB37: =SUM('1Wall#831:248-250W102nd'!AB37) -> 27180.35 | ... AF37: =SUM('1Wall#831:248-250W102nd'!AF37) -> 0
A38: ネット賃貸収入利回り(円)
A39: ネット賃貸収入利回り(ドル)
A40: 取得時簿価利回り(円)
A41: 取得時簿価利回り(ドル)
...

Sheet 1Wall#831
A1: 1 Wall Street #831 | B1: 2024 | C1: 45412 | D1: 45443 | E1: 45473 | F1: 45504 | G1: 2025 | H1: 45535 | I1: 45565 | J1: 45596 | K1: 45626 | L1: 45657 | M1: 45688 | N1: 45716 | O1: 45747 | P1: 45777 | Q1: 45808 | R1: 45838 | S1: 45869 | T1: 2026 | U1: 45900 | V1: 45930 | W1: 45961 | X1: 45991 | Y1: 46022 | Z1: 46053 | AA1: 46081 | AB1: 46112 | AC1: 46142 | AD1: 46173 | AE1: 46203 | AF1: 46234
A2: 取得簿価(円) | B2: =B3*B5 -> 210000000
A3: 取得簿価(ドル) | B3: 1400000
A4: 賃料収入(円) | B4: =B6*B5 -> 975000 | C4: =C5*C6 -> 0 | D4: =D5*D6 -> 0 | E4: =E5*E6 -> 0 | F4: =F5*F6 -> 4573.2 | H4: =H5*H6 -> 0 | I4: =I5*I6 -> 465493.91 | J4: =J5*J6 -> 952568 | K4: =K5*K6 -> 934588 | L4: =L5*L6 -> 980716 | M4: =M5*M6 -> 957466 | N4: =N5*N6 -> 927954 | O4: =O5*O6 -> 927024 | ... S4: =S5*S6 -> 926218 | U4: =U5*U6 -> 718739.99 | V4: =V5*V6 -> 316228.56 | W4: =W5*W6 -> 395170.96 | X4: =X5*X6 -> 1020444.4 | Y4: =Y5*Y6 -> 1017640 | Z4: =Z5*Z6 -> 998790 | AA4: =AA5*AA6 -> 1012765 | AB4: =AB5*AB6 -> 1039220 | ... AF4: =AF5*AF6 -> 0
A5: 為替レート(ドル円)TTM | B5: 150 | C5: ='NY不動産(総計)'!C5 -> 156.9 | D5: ='NY不動産(総計)'!D5 -> 156.74 | E5: ='NY不動産(総計)'!E5 -> 161.07 | F5: ='NY不動産(総計)'!F5 -> 152.44 | H5: ='NY不動産(総計)'!H5 -> 144.8 | I5: ='NY不動産(総計)'!I5 -> 142.73 | J5: ='NY不動産(総計)'!J5 -> 153.64 | K5: ='NY不動産(総計)'!K5 -> 150.74 | L5: ='NY不動産(総計)'!L5 -> 158.18 | M5: ='NY不動産(総計)'!M5 -> 154.43 | N5: ='NY不動産(総計)'!N5 -> 149.67 | O5: ='NY不動産(総計)'!O5 -> 149.52 | ... S5: ='NY不動産(総計)'!S5 -> 149.39 | U5: ='NY不動産(総計)'!U5 -> 146.92 | V5: ='NY不動産(総計)'!V5 -> 148.88 | W5: ='NY不動産(総計)'!W5 -> 154.1 | X5: ='NY不動産(総計)'!X5 -> 156.63 | Y5: ='NY不動産(総計)'!Y5 -> 156.56 | Z5: ='NY不動産(総計)'!Z5 -> 153.66 | AA5: ='NY不動産(総計)'!AA5 -> 155.81 | AB5: ='NY不動産(総計)'!AB5 -> 159.88 | ... AF5: ='NY不動産(総計)'!AF5 -> 0
A6: 賃料収入(ドル) | B6: 6500 | C6: 0 | D6: 0 | E6: 0 | F6: 30 | H6: 0 | I6: 3261.36 | J6: 6200 | K6: 6200 | L6: 6200 | M6: 6200 | N6: 6200 | O6: 6200 | P6: 7549.88 | Q6: 6350.12 | R6: 6200 | S6: 6200 | U6: 4892.05 | V6: 2124.05 | W6: 2564.38 | X6: 6515 | Y6: 6500 | Z6: 6500 | AA6: 6500 | AB6: 6500
A7: 減価償却費(円) | B7: 190636233 | C7: 1779271 | D7: 1779271 | E7: 1779271 | F7: 1779273 | H7: 1779271 | I7: 1779271 | J7: 1779271 | K7: 1779271 | L7: 1779271 | M7: 1779274 | N7: 1779271 | O7: 1779271 | P7: 1779271 | Q7: 1779271 | R7: 1779271 | S7: 1779274 | U7: 1779271 | V7: 1779271 | W7: 1779271 | X7: 1779271 | Y7: 1779271 | Z7: 1779274 | AA7: 1779271 | AB7: 1779271 | AC7: 1779271 | AD7: 1779271 | AE7: 1779271 | AF7: 1779274
A8: 減価償却費(ドル)
A9: 残存簿価(円) | B9: =SUM(B7-C7) -> 188856962 | C9: =B9-C7 -> 187077691 | D9: =C9-D7 -> 185298420 | E9: =D9-E7 -> 183519149 | F9: =E9-F7 -> 181739876 | H9: =F9-H7 -> 179960605 | I9: =H9-I7 -> 178181334 | J9: =I9-J7 -> 176402063 | K9: =J9-K7 -> 174622792 | L9: =K9-L7 -> 172843521 | M9: =L9-M7 -> 171064247 | N9: =M9-N7 -> 169284976 | O9: =N9-O7 -> 167505705 | P9: =O9-P7 -> 165726434 | ... S9: =R9-S7 -> 160388618 | U9: =S9-U7 -> 158609347 | V9: =U9-V7 -> 156830076 | W9: =V9-W7 -> 155050805 | X9: =W9-X7 -> 153271534 | Y9: =X9-Y7 -> 151492263 | Z9: =Y9-Z7 -> 149712989 | AA9: =Z9-AA7 -> 147933718 | AB9: =AA9-AB7 -> 146154447 | AC9: =AB9-AC7 -> 144375176 | ... AF9: =AE9-AF7 -> 139037360
A10: 残存簿価(ドル)
A11: 管理費(ドル) | C11: 600 | D11: 100 | E11: 100 | F11: 100 | H11: 100 | I11: 6696 | J11: 496 | K11: 496 | L11: 496 | M11: 496 | N11: 496 | O11: 496 | P11: 496 | Q11: 496 | R11: 496 | S11: 434 | U11: 434 | V11: 217 | W11: 217 | X11: 455 | Y11: 455 | Z11: 455 | AA11: 455 | AB11: 455 | AG11: =SUM(C11:AF11) -> 15737 | AH11: 管理費
A12: 諸経費(税金、募集経費等)(ドル) | B12: -357.58 | C12: 1177.47 | D12: 4722.81 | E12: 6463.43 | F12: 1357.32 | H12: 2269.82 | I12: 16185.79 | J12: 1327.92 | K12: 1327.82 | L12: 2106.78 | M12: 1327.82 | N12: 2093.94 | O12: 1350.96 | P12: 1349.88 | Q12: 1350.3 | R12: 22239.29 | S12: 1350.31 | U12: 1350.26 | V12: 1350.26 | W12: 12157.45 | X12: 1365.21 | Y12: 1350.21 | Z12: 1363.76 | AA12: 1363.76 | AB12: 2112.71 | AG12: 20067.72 | AH12: コモンチャージ
A13: ネット賃貸収入利回り(円) | AG13: 45276.83 | AH13: 固定資産税
A14: ネット賃貸収入利回り(ドル) | AG14: 2657.11 | AH14: 修繕・雑費・その他支出
A15: 取得時簿価利回り(円) | B15: =B13/B2 -> 0 | AG15: =SUM(AG11:AG14) -> 83738.66 | AH15: 合計
A16: 取得時簿価利回り(ドル)
A17: 残存簿価利回り(円) | B17: =B13/B9 -> 0
A18: 残存簿価利回り(ドル)
A19: CF(円) | C19: =SUM(C5*C20) -> -278885.04 | D19: =SUM(D5*D20) -> -755927.24 | E19: =SUM(E5*E20) -> -1057171.7 | F19: =SUM(F5*F20) -> -217580.66 | H19: =SUM(H5*H20) -> -343149.94 | I19: =SUM(I5*I20) -> -2800424 | J19: =SUM(J5*J20) -> 672340.93 | K19: =SUM(K5*K20) -> 659665.37 | L19: =SUM(L5*L20) -> 569008.26 | M19: =SUM(M5*M20) -> 675813.48 | N19: =SUM(N5*N20) -> 540317.68 | O19: =SUM(O5*O20) -> 650866.54 | ... S19: =SUM(S5*S20) -> 659659.93 | U19: =SUM(U5*U20) -> 456596.51 | V19: =SUM(V5*V20) -> 82894.895 | W19: =SUM(W5*W20) -> -1511731.8 | X19: =SUM(X5*X20) -> 735344.96 | Y19: =SUM(Y5*Y20) -> 735016.32 | Z19: =SUM(Z5*Z20) -> 719319.34 | AA19: =SUM(AA5*AA20) -> 729384 | AB19: =SUM(AB5*AB20) -> 628694.53 | ... AF19: =SUM(AF5*AF20) -> 0
A20: CF(ドル) | C20: =SUM(C6-C11-C12) -> -1777.47 | D20: =SUM(D6-D11-D12) -> -4822.81 | E20: =SUM(E6-E11-E12) -> -6563.43 | F20: =SUM(F6-F11-F12) -> -1427.32 | H20: =SUM(H6-H11-H12) -> -2369.82 | I20: =SUM(I6-I11-I12) -> -19620.43 | J20: =SUM(J6-J11-J12) -> 4376.08 | K20: =SUM(K6-K11-K12) -> 4376.18 | L20: =SUM(L6-L11-L12) -> 3597.22 | M20: =SUM(M6-M11-M12) -> 4376.18 | N20: =SUM(N6-N11-N12) -> 3610.06 | O20: =SUM(O6-O11-O12) -> 4353.04 | ... S20: =SUM(S6-S11-S12) -> 4415.69 | U20: =SUM(U6-U11-U12) -> 3107.79 | V20: =SUM(V6-V11-V12) -> 556.79 | W20: =SUM(W6-W11-W12) -> -9810.07 | X20: =SUM(X6-X11-X12) -> 4694.79 | Y20: =SUM(Y6-Y11-Y12) -> 4694.79 | Z20: =SUM(Z6-Z11-Z12) -> 4681.24 | AA20: =SUM(AA6-AA11-AA12) -> 4681.24 | AB20: =SUM(AB6-AB11-AB12) -> 3932.29 | ... AF20: =SUM(AF6-AF11-AF12) -> 0
A21: PL(円)
A22: PL(ドル)
A23: 更新日 | B23: 46265
A24: 購入日 | B24: 45379
A25: 下記表は固都税を各月の諸経費に分散して計上した表です
A26: 1 Wall Street #831 | B26: 2024 | C26: 45412 | D26: 45443 | E26: 45473 | F26: 45504 | G26: 2025 | H26: 45535 | I26: 45565 | J26: 45596 | K26: 45626 | L26: 45657 | M26: 45688 | N26: 45716 | O26: 45747 | P26: 45777 | Q26: 45808 | R26: 45838 | S26: 45869 | T26: 2026 | U26: 45900 | V26: 45930 | W26: 45961 | X26: 45991 | Y26: 46022 | Z26: 46053 | AA26: 46081 | AB26: 46112 | AC26: 46142 | AD26: 46173 | AE26: 46203 | AF26: 46234
A27: 取得簿価(円) | B27: =B28*B30 -> 210000000
A28: 取得簿価(ドル) | B28: 1400000
A29: 賃料収入(円) | B29: =B31*B30 -> 930000 | C29: =C30*C31 -> 0 | D29: =D30*D31 -> 0 | E29: =E30*E31 -> 0 | F29: =F30*F31 -> 4573.2 | H29: =H30*H31 -> 0 | I29: =I30*I31 -> 465493.91 | J29: =J30*J31 -> 952568 | K29: =K30*K31 -> 934588 | L29: =L30*L31 -> 980716 | M29: =M30*M31 -> 957466 | N29: =N30*N31 -> 927954 | O29: =O30*O31 -> 927024 | ... S29: =S30*S31 -> 926218 | U29: =U30*U31 -> 718739.99 | V29: =V30*V31 -> 316228.56 | W29: =W30*W31 -> 395170.96 | X29: =X30*X31 -> 1020444.4 | Y29: =Y30*Y31 -> 1017640 | Z29: =Z30*Z31 -> 998790 | AA29: =AA30*AA31 -> 1012765 | AB29: =AB30*AB31 -> 1039220 | ... AF29: =AF30*AF31 -> 0
A30: 為替レート(ドル円)TTM | B30: ='NY不動産(総計)'!B30 -> 150 | C30: ='NY不動産(総計)'!C30 -> 156.9 | D30: ='NY不動産(総計)'!D30 -> 156.74 | E30: ='NY不動産(総計)'!E30 -> 161.07 | F30: ='NY不動産(総計)'!F30 -> 152.44 | H30: ='NY不動産(総計)'!H30 -> 144.8 | I30: ='NY不動産(総計)'!I30 -> 142.73 | J30: ='NY不動産(総計)'!J30 -> 153.64 | K30: ='NY不動産(総計)'!K30 -> 150.74 | L30: ='NY不動産(総計)'!L30 -> 158.18 | M30: ='NY不動産(総計)'!M30 -> 154.43 | N30: ='NY不動産(総計)'!N30 -> 149.67 | O30: ='NY不動産(総計)'!O30 -> 149.52 | ... S30: ='NY不動産(総計)'!S30 -> 149.39 | U30: ='NY不動産(総計)'!U30 -> 146.92 | V30: ='NY不動産(総計)'!V30 -> 148.88 | W30: ='NY不動産(総計)'!W30 -> 154.1 | X30: ='NY不動産(総計)'!X30 -> 156.63 | Y30: ='NY不動産(総計)'!Y30 -> 156.56 | Z30: ='NY不動産(総計)'!Z30 -> 153.66 | AA30: ='NY不動産(総計)'!AA30 -> 155.81 | AB30: ='NY不動産(総計)'!AB30 -> 159.88 | ... AF30: ='NY不動産(総計)'!AF30 -> 0
A31: 賃料収入(ドル) | B31: 6200 | C31: 0 | D31: 0 | E31: 0 | F31: 30 | H31: 0 | I31: 3261.36 | J31: 6200 | K31: 6200 | L31: 6200 | M31: 6200 | N31: 6200 | O31: 6200 | P31: 7549.88 | Q31: 6350.12 | R31: 6200 | S31: 6200 | U31: 4892.05 | V31: 2124.05 | W31: 2564.38 | X31: 6515 | Y31: 6500 | Z31: 6500 | AA31: 6500 | AB31: 6500
A32: 減価償却費(円) | B32: 190636233 | C32: 1779271 | D32: 1779271 | E32: 1779271 | F32: 1779273 | H32: 1779271 | I32: 1779271 | J32: 1779271 | K32: 1779271 | L32: 1779271 | M32: 1779274 | N32: 1779271 | O32: 1779271 | P32: 1779271 | Q32: 1779271 | R32: 1779271 | S32: 1779274 | U32: 1779271 | V32: 1779271 | W32: 1779271 | X32: 1779271 | Y32: 1779271 | Z32: 1779274 | AA32: 1779271 | AB32: 1779271 | AC32: 1779271 | AD32: 1779271 | AE32: 1779271 | AF32: 1779274
A33: 減価償却費(ドル)
A34: 残存簿価(円) | B34: =SUM(B32-C32) -> 188856962 | C34: =B34-C32 -> 187077691 | D34: =C34-D32 -> 185298420 | E34: =D34-E32 -> 183519149 | F34: =E34-F32 -> 181739876 | H34: =F34-H32 -> 179960605 | I34: =H34-I32 -> 178181334 | J34: =I34-J32 -> 176402063 | K34: =J34-K32 -> 174622792 | L34: =K34-L32 -> 172843521 | M34: =L34-M32 -> 171064247 | N34: =M34-N32 -> 169284976 | O34: =N34-O32 -> 167505705 | P34: =O34-P32 -> 165726434 | ... S34: =R34-S32 -> 160388618 | U34: =S34-U32 -> 158609347 | V34: =U34-V32 -> 156830076 | W34: =V34-W32 -> 155050805 | X34: =W34-X32 -> 153271534 | Y34: =X34-Y32 -> 151492263 | Z34: =Y34-Z32 -> 149712989 | AA34: =Z34-AA32 -> 147933718 | AB34: =AA34-AB32 -> 146154447 | AC34: =AB34-AC32 -> 144375176 | ... AF34: =AE34-AF32 -> 139037360
A35: 残存簿価(ドル)
A36: 管理費(ドル) | C36: 600 | D36: 100 | E36: 100 | F36: 100 | H36: 100 | I36: 6696 | J36: 496 | K36: 496 | L36: 496 | M36: 496 | N36: 496 | O36: 496 | P36: 496 | Q36: 496 | R36: 496 | S36: 434 | U36: 434 | V36: 217 | W36: 217 | X36: 455 | Y36: 455 | Z36: 455 | AA36: 455 | AB36: 455
A37: 諸経費(税金、募集経費等)(ドル) | B37: -357.58 | C37: 1177.47 | D37: 4722.81 | E37: 3039.35 | F37: 3069.36 | H37: 3981.86 | I37: 2978.75 | J37: 2978.8 | K37: 2978.7 | L37: 3757.66 | M37: 2978.7 | N37: 3744.82 | O37: 3001.84 | P37: 3000.76 | Q37: 3001.18 | R37: 3091.05 | S37: 3091.05 | U37: 3091.01 | V37: 3091.01 | W37: 13898.2 | X37: 3105.96 | Y37: 3090.96 | Z37: 3104.51 | AA37: 3104.51 | AB37: 1740.75 | AC37: 1740.75 | AD37: 1740.75
A38: ネット賃貸収入利回り(円)
A39: ネット賃貸収入利回り(ドル)
A40: 取得時簿価利回り(円) | B40: =B38/B27 -> 0
...

Sheet 111W56th#34D
A1: 111 West 56th #34D | B1: 2024 | C1: 45412 | D1: 45443 | E1: 45473 | F1: 45504 | G1: 2025 | H1: 45535 | I1: 45565 | J1: 45596 | K1: 45626 | L1: 45657 | M1: 45688 | N1: 45716 | O1: 45747 | P1: 45777 | Q1: 45808 | R1: 45838 | S1: 45869 | T1: 2026 | U1: 45900 | V1: 45930 | W1: 45961 | X1: 45991 | Y1: 46022 | Z1: 46053 | AA1: 46081 | AB1: 46112 | AC1: 46142 | AD1: 46173 | AE1: 46203 | AF1: 46234
A2: 取得簿価(円) | B2: =B3*150 -> 168750000
A3: 取得簿価(ドル) | B3: 1125000
A4: 賃料収入(円) | B4: =B6*B5 -> 900000 | C4: =C5*C6 -> 0 | D4: =D5*D6 -> 2351.1 | E4: =E5*E6 -> 4832.1 | F4: =F5*F6 -> 4573.2 | H4: =H5*H6 -> 273731.37 | I4: =I5*I6 -> 820697.5 | J4: =J5*J6 -> 883430 | K4: =K5*K6 -> 866755 | L4: =L5*L6 -> 909535 | M4: =M5*M6 -> 895267.77 | N4: =N5*N6 -> 878812.85 | O4: =O5*O6 -> 870209.39 | ... S4: =S5*S6 -> 867736.3 | U4: =U5*U6 -> 250686.66 | V4: =V5*V6 -> 13988.765 | W4: =W5*W6 -> 925740.34 | X4: =X5*X6 -> 939780 | Y4: =Y5*Y6 -> 939360 | Z4: =Z5*Z6 -> 925666.28 | AA4: =AA5*AA6 -> 938668 | AB4: =AB5*AB6 -> 964476.1 | ... AF4: =AF5*AF6 -> 0
A5: 為替レート(ドル円)TTM | B5: 150 | C5: ='NY不動産(総計)'!C5 -> 156.9 | D5: ='NY不動産(総計)'!D5 -> 156.74 | E5: ='NY不動産(総計)'!E5 -> 161.07 | F5: ='NY不動産(総計)'!F5 -> 152.44 | H5: ='NY不動産(総計)'!H5 -> 144.8 | I5: ='NY不動産(総計)'!I5 -> 142.73 | J5: ='NY不動産(総計)'!J5 -> 153.64 | K5: ='NY不動産(総計)'!K5 -> 150.74 | L5: ='NY不動産(総計)'!L5 -> 158.18 | M5: ='NY不動産(総計)'!M5 -> 154.43 | N5: ='NY不動産(総計)'!N5 -> 149.67 | O5: ='NY不動産(総計)'!O5 -> 149.52 | ... S5: ='NY不動産(総計)'!S5 -> 149.39 | U5: ='NY不動産(総計)'!U5 -> 146.92 | V5: ='NY不動産(総計)'!V5 -> 148.88 | W5: ='NY不動産(総計)'!W5 -> 154.1 | X5: ='NY不動産(総計)'!X5 -> 156.63 | Y5: ='NY不動産(総計)'!Y5 -> 156.56 | Z5: ='NY不動産(総計)'!Z5 -> 153.66 | AA5: ='NY不動産(総計)'!AA5 -> 155.81 | AB5: ='NY不動産(総計)'!AB5 -> 159.88 | ... AF5: ='NY不動産(総計)'!AF5 -> 0
A6: 賃料収入(ドル) | B6: 6000 | C6: 0 | D6: 15 | E6: 30 | F6: 30 | H6: 1890.41 | I6: 5750 | J6: 5750 | K6: 5750 | L6: 5750 | M6: 5797.24 | N6: 5871.67 | O6: 5820.02 | P6: 5813.94 | Q6: 5849.56 | R6: 5837.73 | S6: 5808.53 | U6: 1706.28 | V6: 93.96 | W6: 6007.4 | X6: 6000 | Y6: 6000 | Z6: 6024.12 | AA6: 6024.44 | AB6: 6032.5
A7: 減価償却費(円) | B7: 87233222 | C7: 814176 | D7: 814176 | E7: 814176 | F7: 814179 | H7: 814176 | I7: 814176 | J7: 814176 | K7: 814176 | L7: 814176 | M7: 814180 | N7: 814176 | O7: 814176 | P7: 814176 | Q7: 814176 | R7: 814176 | S7: 814180 | U7: 814176 | V7: 814176 | W7: 814176 | X7: 814176 | Y7: 814176 | Z7: 814180 | AA7: 814176 | AB7: 814176 | AC7: 814176 | AD7: 814176 | AE7: 814176 | AF7: 814180
A8: 減価償却費(ドル)
A9: 残存簿価(円) | B9: =SUM(B7-C7) -> 86419046 | C9: =SUM(B9-C7) -> 85604870 | D9: =SUM(C9-D7) -> 84790694 | E9: =SUM(D9-E7) -> 83976518 | F9: =SUM(E9-F7) -> 83162339 | H9: =SUM(F9-H7) -> 82348163 | I9: =SUM(H9-I7) -> 81533987 | J9: =SUM(I9-J7) -> 80719811 | K9: =SUM(J9-K7) -> 79905635 | L9: =SUM(K9-L7) -> 79091459 | M9: =SUM(L9-M7) -> 78277279 | N9: =SUM(M9-N7) -> 77463103 | O9: =SUM(N9-O7) -> 76648927 | P9: =SUM(O9-P7) -> 75834751 | ... S9: =SUM(R9-S7) -> 73392219 | U9: =SUM(S9-U7) -> 72578043 | V9: =SUM(U9-V7) -> 71763867 | W9: =SUM(V9-W7) -> 70949691 | X9: =SUM(W9-X7) -> 70135515 | Y9: =SUM(X9-Y7) -> 69321339 | Z9: =SUM(Y9-Z7) -> 68507159 | AA9: =SUM(Z9-AA7) -> 67692983 | AB9: =SUM(AA9-AB7) -> 66878807 | AC9: =SUM(AB9-AC7) -> 66064631 | ... AF9: =SUM(AE9-AF7) -> 63622099
A10: 残存簿価(ドル)
A11: 管理費(ドル) | C11: 600 | D11: 100 | E11: 100 | F11: 100 | H11: 5980 | I11: 460 | J11: 460 | K11: 460 | L11: 460 | M11: 460 | N11: 460 | O11: 460 | P11: 460 | Q11: 460 | R11: 460 | S11: 402.5 | U11: 201.25 | V11: 201.25 | W11: 420 | X11: 420 | Y11: 420 | Z11: 420 | AA11: 420 | AB11: 420 | AG11: =SUM(C11:AF11) -> 14805 | AH11: 管理費
A12: 諸経費(税金、募集経費等)(ドル) | B12: 51904.57 | C12: 1173.44 | D12: 1091.12 | E12: 1194.44 | F12: 1191.44 | H12: 4190.76 | I12: 7929.68 | J12: 1232.81 | K12: 1189.2 | L12: 1205.54 | M12: 1202.44 | N12: 1713.14 | O12: 1145.04 | P12: 1180.08 | Q12: 1168.25 | R12: 10730.52 | S12: 1146.74 | U12: 1144.67 | V12: 1173.91 | W12: 7730.82 | X12: 3369.8 | Y12: 1109.42 | Z12: 1163.36 | AA12: 1161.42 | AB12: 1762.86 | AG12: 18055.1 | AH12: コモンチャージ
A13: ネット賃貸収入利回り(円) | AG13: 15631.24 | AH13: 固定資産税
A14: ネット賃貸収入利回り(ドル) | AG14: 4998.3 | AH14: 修繕・雑費・その他支出
A15: 取得時簿価利回り(円) | B15: =B13/B2 -> 0 | AG15: =SUM(AG11:AG14) -> 53489.64 | AH15: 合計
A16: 取得時簿価利回り(ドル)
A17: 残存簿価利回り(円) | B17: =B13/B9 -> 0
A18: 残存簿価利回り(ドル)
A19: CF(円) | C19: =SUM(C20*C5) -> -278252.74 | D19: =SUM(D20*D5) -> -184345.05 | E19: =SUM(E20*E5) -> -203663.35 | F19: =SUM(F20*F5) -> -192293.91 | H19: =SUM(H20*H5) -> -1198994.7 | I19: =SUM(I20*I5) -> -376761.53 | J19: =SUM(J20*J5) -> 623346.67 | K19: =SUM(K20*K5) -> 618154.59 | L19: =SUM(L20*L5) -> 646079.88 | M19: =SUM(M20*M5) -> 638537.16 | N19: =SUM(N20*N5) -> 553558.99 | O19: =SUM(O20*O5) -> 630223.81 | ... S19: =SUM(S20*S5) -> 636295.33 | U19: =SUM(U20*U5) -> 52944.091 | V19: =SUM(V20*V5) -> -190745.06 | W19: =SUM(W20*W5) -> -330301.02 | X19: =SUM(X20*X5) -> 346183.63 | Y19: =SUM(Y20*Y5) -> 699914 | Z19: =SUM(Z20*Z5) -> 682367.18 | AA19: =SUM(AA20*AA5) -> 692266.95 | AB19: =SUM(AB20*AB5) -> 615480.44 | ... AF19: =SUM(AF20*AF5) -> 0
A20: CF(ドル) | C20: =SUM(C6-C11-C12) -> -1773.44 | D20: =SUM(D6-D11-D12) -> -1176.12 | E20: =SUM(E6-E11-E12) -> -1264.44 | F20: =SUM(F6-F11-F12) -> -1261.44 | H20: =SUM(H6-H11-H12) -> -8280.35 | I20: =SUM(I6-I11-I12) -> -2639.68 | J20: =SUM(J6-J11-J12) -> 4057.19 | K20: =SUM(K6-K11-K12) -> 4100.8 | L20: =SUM(L6-L11-L12) -> 4084.46 | M20: =SUM(M6-M11-M12) -> 4134.8 | N20: =SUM(N6-N11-N12) -> 3698.53 | O20: =SUM(O6-O11-O12) -> 4214.98 | ... S20: =SUM(S6-S11-S12) -> 4259.29 | U20: =SUM(U6-U11-U12) -> 360.36 | V20: =SUM(V6-V11-V12) -> -1281.2 | W20: =SUM(W6-W11-W12) -> -2143.42 | X20: =SUM(X6-X11-X12) -> 2210.2 | Y20: =SUM(Y6-Y11-Y12) -> 4470.58 | Z20: =SUM(Z6-Z11-Z12) -> 4440.76 | AA20: =SUM(AA6-AA11-AA12) -> 4443.02 | AB20: =SUM(AB6-AB11-AB12) -> 3849.64 | ... AF20: =SUM(AF6-AF11-AF12) -> 0
A21: PL(円)
A22: PL(ドル)
A24: 購入日 | B24: 45380
A25: 下記表は固都税を各月の諸経費に分散して計上した表です
A26: 111 West 56th #34D | B26: 2024 | C26: 45412 | D26: 45443 | E26: 45473 | F26: 45504 | G26: 2025 | H26: 45535 | I26: 45565 | J26: 45596 | K26: 45626 | L26: 45657 | M26: 45688 | N26: 45716 | O26: 45747 | P26: 45777 | Q26: 45808 | R26: 45838 | S26: 45869 | T26: 2026 | U26: 45535 | V26: 45565 | W26: 45596 | X26: 45626 | Y26: 45657 | Z26: 45688 | AA26: 45716 | AB26: 45747 | AC26: 45777 | AD26: 45808 | AE26: 45838 | AF26: 45869
A27: 取得簿価(円) | B27: =B28*150 -> 168750000
A28: 取得簿価(ドル) | B28: 1125000
A29: 賃料収入(円) | B29: =B31*B30 -> 862500 | C29: =C30*C31 -> 0 | D29: =D30*D31 -> 2351.1 | E29: =E30*E31 -> 4832.1 | F29: =F30*F31 -> 4573.2 | H29: =H30*H31 -> 273731.37 | I29: =I30*I31 -> 820697.5 | J29: =J30*J31 -> 883430 | K29: =K30*K31 -> 866755 | L29: =L30*L31 -> 909535 | M29: =M30*M31 -> 895267.77 | N29: =N30*N31 -> 878812.85 | O29: =O30*O31 -> 870209.39 | ... S29: =S30*S31 -> 867736.3 | U29: =U30*U31 -> 250686.66 | V29: =V30*V31 -> 13988.765 | W29: =W30*W31 -> 925740.34 | X29: =X30*X31 -> 939780 | Y29: =Y30*Y31 -> 939360 | Z29: =Z30*Z31 -> 925666.28 | AA29: =AA30*AA31 -> 938668 | AB29: =AB30*AB31 -> 964476.1 | ... AF29: =AF30*AF31 -> 0
A30: 為替レート(ドル円)TTM | B30: 150 | C30: ='NY不動産(総計)'!C30 -> 156.9 | D30: ='NY不動産(総計)'!D30 -> 156.74 | E30: ='NY不動産(総計)'!E30 -> 161.07 | F30: ='NY不動産(総計)'!F30 -> 152.44 | H30: ='NY不動産(総計)'!H30 -> 144.8 | I30: ='NY不動産(総計)'!I30 -> 142.73 | J30: ='NY不動産(総計)'!J30 -> 153.64 | K30: ='NY不動産(総計)'!K30 -> 150.74 | L30: ='NY不動産(総計)'!L30 -> 158.18 | M30: ='NY不動産(総計)'!M30 -> 154.43 | N30: ='NY不動産(総計)'!N30 -> 149.67 | O30: ='NY不動産(総計)'!O30 -> 149.52 | ... S30: ='NY不動産(総計)'!S30 -> 149.39 | U30: ='NY不動産(総計)'!U30 -> 146.92 | V30: ='NY不動産(総計)'!V30 -> 148.88 | W30: ='NY不動産(総計)'!W30 -> 154.1 | X30: ='NY不動産(総計)'!X30 -> 156.63 | Y30: ='NY不動産(総計)'!Y30 -> 156.56 | Z30: ='NY不動産(総計)'!Z30 -> 153.66 | AA30: ='NY不動産(総計)'!AA30 -> 155.81 | AB30: ='NY不動産(総計)'!AB30 -> 159.88 | ... AF30: ='NY不動産(総計)'!AF30 -> 0
A31: 賃料収入(ドル) | B31: 5750 | C31: 0 | D31: 15 | E31: 30 | F31: 30 | H31: 1890.41 | I31: 5750 | J31: 5750 | K31: 5750 | L31: 5750 | M31: 5797.24 | N31: 5871.67 | O31: 5820.02 | P31: 5813.94 | Q31: 5849.56 | R31: 5837.73 | S31: 5808.53 | U31: 1706.28 | V31: 93.96 | W31: 6007.4 | X31: 6000 | Y31: 6000 | Z31: 6024.12 | AA31: 6024.44 | AB31: 6032.5
A32: 減価償却費(円) | B32: 87233222 | C32: 814176 | D32: 814176 | E32: 814176 | F32: 814179 | H32: 814176 | I32: 814176 | J32: 814176 | K32: 814176 | L32: 814176 | M32: 814180 | N32: 814176 | O32: 814176 | P32: 814176 | Q32: 814176 | R32: 814176 | S32: 814180 | U32: 814176 | V32: 814176 | W32: 814176 | X32: 814176 | Y32: 814176 | Z32: 814180 | AA32: 814176 | AB32: 814176 | AC32: 814176 | AD32: 814176 | AE32: 814176 | AF32: 814180
A33: 減価償却費(ドル)
A34: 残存簿価(円) | B34: =SUM(B32-C32) -> 86419046 | C34: =SUM(B34-C32) -> 85604870 | D34: =SUM(C34-D32) -> 84790694 | E34: =SUM(D34-E32) -> 83976518 | F34: =SUM(E34-F32) -> 83162339 | H34: =SUM(F34-H32) -> 82348163 | I34: =SUM(H34-I32) -> 81533987 | J34: =SUM(I34-J32) -> 80719811 | K34: =SUM(J34-K32) -> 79905635 | L34: =SUM(K34-L32) -> 79091459 | M34: =SUM(L34-M32) -> 78277279 | N34: =SUM(M34-N32) -> 77463103 | O34: =SUM(N34-O32) -> 76648927 | P34: =SUM(O34-P32) -> 75834751 | ... S34: =SUM(R34-S32) -> 73392219 | U34: =SUM(S34-U32) -> 72578043 | V34: =SUM(U34-V32) -> 71763867 | W34: =SUM(V34-W32) -> 70949691 | X34: =SUM(W34-X32) -> 70135515 | Y34: =SUM(X34-Y32) -> 69321339 | Z34: =SUM(Y34-Z32) -> 68507159 | AA34: =SUM(Z34-AA32) -> 67692983 | AB34: =SUM(AA34-AB32) -> 66878807 | AC34: =SUM(AB34-AC32) -> 66064631 | ... AF34: =SUM(AE34-AF32) -> 63622099
A35: 残存簿価(ドル)
A36: 管理費(ドル) | C36: 600 | D36: 100 | E36: 100 | F36: 100 | H36: 5980 | I36: 460 | J36: 460 | K36: 460 | L36: 460 | M36: 460 | N36: 460 | O36: 460 | P36: 460 | Q36: 460 | R36: 460 | S36: 402.5 | U36: 201.25 | V36: 201.25 | W36: 420 | X36: 420 | Y36: 420 | Z36: 420 | AA36: 420
A37: 諸経費(税金、募集経費等)(ドル) | B37: 51904.57 | C37: 1173.44 | D37: 1091.12 | E37: 1191.44 | F37: 1191.44 | H37: 4190.76 | I37: 2251.28 | J37: 1942.61 | K37: 1899 | L37: 1915.34 | M37: 1912.24 | N37: 2422.94 | O37: 1854.84 | P37: 1889.88 | Q37: 1878.05 | R37: 2257.66 | S37: 1917 | U37: 1914.93 | V37: 1944.17 | W37: 8501.08 | X37: 4140.06 | Y37: 1879.68 | Z37: 1933.62 | AA37: 1931.68 | AB37: 770.26 | AC37: 770.26 | AD37: 770.26
A38: ネット賃貸収入利回り(円)
A39: ネット賃貸収入利回り(ドル)
A40: 取得時簿価利回り(円) | B40: =B38/B27 -> 0
A41: 取得時簿価利回り(ドル)
...

Sheet 88Gr#1512
A1: 88 Greenwich #1512 | B1: 2024 | C1: 45412 | D1: 45443 | E1: 45473 | F1: 45504 | G1: 2025 | H1: 45535 | I1: 45565 | J1: 45596 | K1: 45626 | L1: 45657 | M1: 45688 | N1: 45716 | O1: 45747 | P1: 45777 | Q1: 45808 | R1: 45838 | S1: 45869 | T1: 2026 | U1: 45900 | V1: 45930 | W1: 45961 | X1: 45991 | Y1: 46022 | Z1: 46053 | AA1: 46081 | AB1: 46112 | AC1: 46142 | AD1: 46173 | AE1: 46203 | AF1: 46234
A2: 取得簿価(円) | B2: =B3*150 -> 126225000
A3: 取得簿価(ドル) | B3: 841500
A4: 賃料収入(円) | B4: =B6*B5 -> 660000 | C4: =C5*C6 -> 0 | D4: =D5*D6 -> 78370 | E4: =E5*E6 -> 0 | F4: =F5*F6 -> 655492 | H4: =H5*H6 -> 622640 | I4: =I5*I6 -> 613739 | J4: =J5*J6 -> 660652 | K4: =K5*K6 -> 648182 | L4: =L5*L6 -> 680174 | M4: =M5*M6 -> 664049 | N4: =N5*N6 -> 643581 | O4: =O5*O6 -> 642936 | ... S4: =S5*S6 -> 657316 | U4: =U5*U6 -> 646448 | V4: =V5*V6 -> 655072 | W4: =W5*W6 -> 678040 | X4: =X5*X6 -> 689172 | Y4: =Y5*Y6 -> 688864 | Z4: =Z5*Z6 -> 676104 | AA4: =AA5*AA6 -> 685564 | AB4: =AB5*AB6 -> 703472 | ... AF4: =AF5*AF6 -> 0
A5: 為替レート(ドル円)TTM | B5: 150 | C5: ='NY不動産(総計)'!C5 -> 156.9 | D5: ='NY不動産(総計)'!D5 -> 156.74 | E5: ='NY不動産(総計)'!E5 -> 161.07 | F5: ='NY不動産(総計)'!F5 -> 152.44 | H5: ='NY不動産(総計)'!H5 -> 144.8 | I5: ='NY不動産(総計)'!I5 -> 142.73 | J5: ='NY不動産(総計)'!J5 -> 153.64 | K5: ='NY不動産(総計)'!K5 -> 150.74 | L5: ='NY不動産(総計)'!L5 -> 158.18 | M5: ='NY不動産(総計)'!M5 -> 154.43 | N5: ='NY不動産(総計)'!N5 -> 149.67 | O5: ='NY不動産(総計)'!O5 -> 149.52 | ... S5: ='NY不動産(総計)'!S5 -> 149.39 | U5: ='NY不動産(総計)'!U5 -> 146.92 | V5: ='NY不動産(総計)'!V5 -> 148.88 | W5: ='NY不動産(総計)'!W5 -> 154.1 | X5: ='NY不動産(総計)'!X5 -> 156.63 | Y5: ='NY不動産(総計)'!Y5 -> 156.56 | Z5: ='NY不動産(総計)'!Z5 -> 153.66 | AA5: ='NY不動産(総計)'!AA5 -> 155.81 | AB5: ='NY不動産(総計)'!AB5 -> 159.88 | ... AF5: ='NY不動産(総計)'!AF5 -> 0
A6: 賃料収入(ドル) | B6: 4400 | C6: 0 | D6: 500 | E6: 0 | F6: 4300 | H6: 4300 | I6: 4300 | J6: 4300 | K6: 4300 | L6: 4300 | M6: 4300 | N6: 4300 | O6: 4300 | P6: 4300 | Q6: 4300 | R6: 4300 | S6: 4400 | U6: 4400 | V6: 4400 | W6: 4400 | X6: 4400 | Y6: 4400 | Z6: 4400 | AA6: 4400 | AB6: 4400 | AC6: 4400
A7: 減価償却費(円) | B7: 115159974 | C7: 1074826 | D7: 1074826 | E7: 1074826 | F7: 1074827 | H7: 1074826 | I7: 1074826 | J7: 1074826 | K7: 1074826 | L7: 1074826 | M7: 1074828 | N7: 1074826 | O7: 1074826 | P7: 1074826 | Q7: 1074826 | R7: 1074826 | S7: 1074829 | U7: 1074826 | V7: 1074826 | W7: 1074826 | X7: 1074826 | Y7: 1074826 | Z7: 1074828 | AA7: 1074826 | AB7: 1074826 | AC7: 1074826 | AD7: 1074826 | AE7: 1074826 | AF7: 1074829
A8: 減価償却費(ドル)
A9: 残存簿価(円) | B9: 115159974 | C9: =SUM(B7-C7) -> 114085148 | D9: =SUM(C9-D7) -> 113010322 | E9: =SUM(D9-E7) -> 111935496 | F9: =SUM(E9-F7) -> 110860669 | H9: =SUM(F9-H7) -> 109785843 | I9: =SUM(H9-I7) -> 108711017 | J9: =SUM(I9-J7) -> 107636191 | K9: =SUM(J9-K7) -> 106561365 | L9: =SUM(K9-L7) -> 105486539 | M9: =SUM(L9-M7) -> 104411711 | N9: =SUM(M9-N7) -> 103336885 | O9: =SUM(N9-O7) -> 102262059 | P9: =SUM(O9-P7) -> 101187233 | ... S9: =SUM(R9-S7) -> 97962752 | U9: =SUM(S9-U7) -> 96887926 | V9: =SUM(U9-V7) -> 95813100 | W9: =SUM(V9-W7) -> 94738274 | X9: =SUM(W9-X7) -> 93663448 | Y9: =SUM(X9-Y7) -> 92588622 | Z9: =SUM(Y9-Z7) -> 91513794 | AA9: =SUM(Z9-AA7) -> 90438968 | AB9: =SUM(AA9-AB7) -> 89364142 | AC9: =SUM(AB9-AC7) -> 88289316 | ... AF9: =SUM(AE9-AF7) -> 85064835
A10: 残存簿価(ドル)
A11: 管理費(ドル) | C11: 63.27 | D11: 100 | E11: 100 | F11: 258 | H11: 258 | I11: 258 | J11: 258 | K11: 258 | L11: 258 | M11: 258 | N11: 258 | O11: 258 | P11: 258 | Q11: 258 | R11: 258 | S11: 264 | U11: 264 | V11: 264 | W11: 264 | X11: 264 | Y11: 264 | Z11: 264 | AA11: 264 | AB11: 264 | AC11: 264 | AG11: =SUM(C11:AF11) -> 5999.27 | AH11: 管理費
A12: 諸経費(税金、募集経費等)(ドル) | B12: 13867.33 | C12: 629.45 | D12: 9730.09 | E12: 1709.27 | F12: 6857.32 | H12: 1960.99 | I12: 9204.75 | J12: 1043 | K12: 1043 | L12: 1043 | M12: 1043 | N12: 1043 | O12: 1147.3 | P12: 1147.3 | Q12: 1147.3 | R12: 12390.93 | S12: 4703.98 | U12: 1193.96 | V12: 1193.96 | W12: 1263.96 | X12: 1395.55 | Y12: 1395.55 | Z12: 1395.55 | AA12: 1395.55 | AB12: 1395.55 | AC12: 1395.55 | AG12: 16077.93 | AH12: コモンチャージ
A13: ネット賃貸収入利回り(円) | AG13: 19156.25 | AH13: 固定資産税
A14: ネット賃貸収入利回り(ドル) | AG14: 20609.5 | AH14: 修繕・雑費・その他支出
A15: 取得時簿価利回り(円) | B15: =B13/B2 -> 0 | AG15: =SUM(AG11:AG14) -> 61842.95 | AH15: 合計
A16: 取得時簿価利回り(ドル)
A17: 残存簿価利回り(円) | B17: =B13/B9 -> 0
A18: 残存簿価利回り(ドル)
A19: CF(円) | C19: =SUM(C20*C5) -> -108687.77 | D19: =SUM(D20*D5) -> -1462398.3 | E19: =SUM(E20*E5) -> -291419.12 | F19: =SUM(F20*F5) -> -429167.38 | H19: =SUM(H20*H5) -> 301330.25 | I19: =SUM(I20*I5) -> -736879.31 | J19: =SUM(J20*J5) -> 460766.36 | K19: =SUM(K20*K5) -> 452069.26 | L19: =SUM(L20*L5) -> 474381.82 | M19: =SUM(M20*M5) -> 463135.57 | N19: =SUM(N20*N5) -> 448860.33 | O19: =SUM(O20*O5) -> 432815.54 | ... S19: =SUM(S20*S5) -> -84850.532 | U19: =SUM(U20*U5) -> 432244.52 | V19: =SUM(V20*V5) -> 438010.92 | W19: =SUM(W20*W5) -> 442581.36 | X19: =SUM(X20*X5) -> 429236.68 | Y19: =SUM(Y20*Y5) -> 429044.85 | Z19: =SUM(Z20*Z5) -> 421097.55 | AA19: =SUM(AA20*AA5) -> 426989.51 | AB19: =SUM(AB20*AB5) -> 438143.15 | ... AF19: =SUM(AF20*AF5) -> 0
A20: CF(ドル) | C20: =SUM(C6-C11-C12) -> -692.72 | D20: =SUM(D6-D11-D12) -> -9330.09 | E20: =SUM(E6-E11-E12) -> -1809.27 | F20: =SUM(F6-F11-F12) -> -2815.32 | H20: =SUM(H6-H11-H12) -> 2081.01 | I20: =SUM(I6-I11-I12) -> -5162.75 | J20: =SUM(J6-J11-J12) -> 2999 | K20: =SUM(K6-K11-K12) -> 2999 | L20: =SUM(L6-L11-L12) -> 2999 | M20: =SUM(M6-M11-M12) -> 2999 | N20: =SUM(N6-N11-N12) -> 2999 | O20: =SUM(O6-O11-O12) -> 2894.7 | ... S20: =SUM(S6-S11-S12) -> -567.98 | U20: =SUM(U6-U11-U12) -> 2942.04 | V20: =SUM(V6-V11-V12) -> 2942.04 | W20: =SUM(W6-W11-W12) -> 2872.04 | X20: =SUM(X6-X11-X12) -> 2740.45 | Y20: =SUM(Y6-Y11-Y12) -> 2740.45 | Z20: =SUM(Z6-Z11-Z12) -> 2740.45 | AA20: =SUM(AA6-AA11-AA12) -> 2740.45 | AB20: =SUM(AB6-AB11-AB12) -> 2740.45 | ... AF20: =SUM(AF6-AF11-AF12) -> 0
A21: PL(円)
A22: PL(ドル)
A24: 購入日 | B24: 45394
A25: 下記表は固都税を各月の諸経費に分散して計上した表です
A26: 88 Greenwich #1512 | B26: 2024 | C26: 45412 | D26: 45443 | E26: 45473 | F26: 45504 | G26: 2025 | H26: 45535 | I26: 45565 | J26: 45596 | K26: 45626 | L26: 45657 | M26: 45688 | N26: 45716 | O26: 45747 | P26: 45777 | Q26: 45808 | R26: 45838 | S26: 45869 | T26: 2026 | U26: 45535 | V26: 45565 | W26: 45596 | X26: 45626 | Y26: 45657 | Z26: 45688 | AA26: 45716 | AB26: 45747 | AC26: 45777 | AD26: 45808 | AE26: 45838 | AF26: 45869
A27: 取得簿価(円) | B27: =B28*150 -> 126225000
A28: 取得簿価(ドル) | B28: 841500
A29: 賃料収入(円) | B29: =B31*B30 -> 645000 | C29: =C30*C31 -> 0 | D29: =D30*D31 -> 78370 | E29: =E30*E31 -> 0 | F29: =F30*F31 -> 655492 | H29: =H30*H31 -> 622640 | I29: =I30*I31 -> 613739 | J29: =J30*J31 -> 660652 | K29: =K30*K31 -> 648182 | L29: =L30*L31 -> 680174 | M29: =M30*M31 -> 664049 | N29: =N30*N31 -> 643581 | O29: =O30*O31 -> 642936 | ... S29: =S30*S31 -> 657316 | U29: =U30*U31 -> 646448 | V29: =V30*V31 -> 655072 | W29: =W30*W31 -> 678040 | X29: =X30*X31 -> 689172 | Y29: =Y30*Y31 -> 688864 | Z29: =Z30*Z31 -> 676104 | AA29: =AA30*AA31 -> 685564 | AB29: =AB30*AB31 -> 703472 | ... AF29: =AF30*AF31 -> 0
A30: 為替レート(ドル円)TTM | B30: 150 | C30: ='NY不動産(総計)'!C30 -> 156.9 | D30: ='NY不動産(総計)'!D30 -> 156.74 | E30: ='NY不動産(総計)'!E30 -> 161.07 | F30: ='NY不動産(総計)'!F30 -> 152.44 | H30: ='NY不動産(総計)'!H30 -> 144.8 | I30: ='NY不動産(総計)'!I30 -> 142.73 | J30: ='NY不動産(総計)'!J30 -> 153.64 | K30: ='NY不動産(総計)'!K30 -> 150.74 | L30: ='NY不動産(総計)'!L30 -> 158.18 | M30: ='NY不動産(総計)'!M30 -> 154.43 | N30: ='NY不動産(総計)'!N30 -> 149.67 | O30: ='NY不動産(総計)'!O30 -> 149.52 | ... S30: ='NY不動産(総計)'!S30 -> 149.39 | U30: ='NY不動産(総計)'!U30 -> 146.92 | V30: ='NY不動産(総計)'!V30 -> 148.88 | W30: ='NY不動産(総計)'!W30 -> 154.1 | X30: ='NY不動産(総計)'!X30 -> 156.63 | Y30: ='NY不動産(総計)'!Y30 -> 156.56 | Z30: ='NY不動産(総計)'!Z30 -> 153.66 | AA30: ='NY不動産(総計)'!AA30 -> 155.81 | AB30: ='NY不動産(総計)'!AB30 -> 159.88 | ... AF30: ='NY不動産(総計)'!AF30 -> 0
A31: 賃料収入(ドル) | B31: 4300 | C31: 0 | D31: 500 | E31: 0 | F31: 4300 | H31: 4300 | I31: 4300 | J31: 4300 | K31: 4300 | L31: 4300 | M31: 4300 | N31: 4300 | O31: 4300 | P31: 4300 | Q31: 4300 | R31: 4300 | S31: 4400 | U31: 4400 | V31: 4400 | W31: 4400 | X31: 4400 | Y31: 4400 | Z31: 4400 | AA31: 4400 | AB31: 4400 | AC31: 4400
A32: 減価償却費(円) | B32: 115159974 | C32: 1074826 | D32: 1074826 | E32: 1074826 | F32: 1074827 | H32: 1074826 | I32: 1074826 | J32: 1074826 | K32: 1074826 | L32: 1074826 | M32: 1074828 | N32: 1074826 | O32: 1074826 | P32: 1074826 | Q32: 1074826 | R32: 1074826 | S32: 1074829 | U32: 1074826 | V32: 1074826 | W32: 1074826 | X32: 1074826 | Y32: 1074826 | Z32: 1074828 | AA32: 1074826 | AB32: 1074826 | AC32: 1074826 | AD32: 1074826 | AE32: 1074826 | AF32: 1074829
A33: 減価償却費(ドル)
A34: 残存簿価(円) | B34: 115159974 | C34: =SUM(B32-C32) -> 114085148 | D34: =SUM(C34-D32) -> 113010322 | E34: =SUM(D34-E32) -> 111935496 | F34: =SUM(E34-F32) -> 110860669 | H34: =SUM(F34-H32) -> 109785843 | I34: =SUM(H34-I32) -> 108711017 | J34: =SUM(I34-J32) -> 107636191 | K34: =SUM(J34-K32) -> 106561365 | L34: =SUM(K34-L32) -> 105486539 | M34: =SUM(L34-M32) -> 104411711 | N34: =SUM(M34-N32) -> 103336885 | O34: =SUM(N34-O32) -> 102262059 | P34: =SUM(O34-P32) -> 101187233 | ... S34: =SUM(R34-S32) -> 97962752 | U34: =SUM(S34-U32) -> 96887926 | V34: =SUM(U34-V32) -> 95813100 | W34: =SUM(V34-W32) -> 94738274 | X34: =SUM(W34-X32) -> 93663448 | Y34: =SUM(X34-Y32) -> 92588622 | Z34: =SUM(Y34-Z32) -> 91513794 | AA34: =SUM(Z34-AA32) -> 90438968 | AB34: =SUM(AA34-AB32) -> 89364142 | AC34: =SUM(AB34-AC32) -> 88289316 | ... AF34: =SUM(AE34-AF32) -> 85064835
A35: 残存簿価(ドル)
A36: 管理費(ドル) | C36: 63.27 | D36: 100 | E36: 100 | F36: 258 | H36: 258 | I36: 258 | J36: 258 | K36: 258 | L36: 258 | M36: 258 | N36: 258 | O36: 258 | P36: 258 | Q36: 258 | R36: 258 | S36: 264 | U36: 264 | V36: 264 | W36: 264 | X36: 264 | Y36: 264 | Z36: 264 | AA36: 264 | AB36: 264 | AC36: 264
A37: 諸経費(税金、募集経費等)(ドル) | B37: 13867.33 | C37: 629.45 | D37: 9730.09 | E37: 1709.27 | F37: 6857.32 | H37: 1960.99 | I37: 1993.47 | J37: 1944.41 | K37: 1944.41 | L37: 1944.41 | M37: 1944.41 | N37: 1944.41 | O37: 2048.71 | P37: 2048.71 | Q37: 2048.71 | R37: 2267.63 | S37: 5624.28 | U37: 2114.26 | V37: 2114.26 | W37: 2184.26 | X37: 2315.85 | Y37: 2315.85 | Z37: 2315.85 | AA37: 2315.85 | AB37: 920.3 | AC37: 920.3 | AD37: 920.3
A38: ネット賃貸収入利回り(円)
A39: ネット賃貸収入利回り(ドル)
A40: 取得時簿価利回り(円) | B40: =B38/B27 -> 0
A41: 取得時簿価利回り(ドル)
...

Sheet 88Gr#3101
A1: 88 Greenwich #3101 | B1: 2024 | C1: 45412 | D1: 45443 | E1: 45473 | F1: 45504 | G1: 2025 | H1: 45535 | I1: 45565 | J1: 45596 | K1: 45626 | L1: 45657 | M1: 45688 | N1: 45716 | O1: 45747 | P1: 45777 | Q1: 45808 | R1: 45838 | S1: 45869 | T1: 2026 | U1: 45900 | V1: 45930 | W1: 45961 | X1: 45991 | Y1: 46022 | Z1: 46053 | AA1: 46081 | AB1: 46112 | AC1: 46142 | AD1: 46173 | AE1: 46203 | AF1: 46234
A2: 取得簿価(円) | B2: =B3*150 -> 149850000
A3: 取得簿価(ドル) | B3: 999000
A4: 賃料収入(円) | B4: =B6*B5 -> 697500 | C4: =C5*C6 -> 0 | D4: =D5*D6 -> 22752.378 | E4: =E5*E6 -> 724815 | F4: =F5*F6 -> 685980 | H4: =H5*H6 -> 651600 | I4: =I5*I6 -> 652989.75 | J4: =J5*J6 -> 702903 | K4: =K5*K6 -> 689635.5 | L4: =L5*L6 -> 723673.5 | M4: =M5*M6 -> 706517.25 | N4: =N5*N6 -> 684740.25 | O4: =O5*O6 -> 684054 | ... S4: =S5*S6 -> 683459.25 | U4: =U5*U6 -> 672159 | V4: =V5*V6 -> 692292 | W4: =W5*W6 -> 716565 | X4: =X5*X6 -> 728329.5 | Y4: =Y5*Y6 -> 728004 | Z4: =Z5*Z6 -> 714519 | AA4: =AA5*AA6 -> 724516.5 | AB4: =AB5*AB6 -> 743442 | ... AF4: =AF5*AF6 -> 0
A5: 為替レート(ドル円)TTM | B5: 150 | C5: ='NY不動産(総計)'!C5 -> 156.9 | D5: ='NY不動産(総計)'!D5 -> 156.74 | E5: ='NY不動産(総計)'!E5 -> 161.07 | F5: ='NY不動産(総計)'!F5 -> 152.44 | H5: ='NY不動産(総計)'!H5 -> 144.8 | I5: ='NY不動産(総計)'!I5 -> 142.73 | J5: ='NY不動産(総計)'!J5 -> 153.64 | K5: ='NY不動産(総計)'!K5 -> 150.74 | L5: ='NY不動産(総計)'!L5 -> 158.18 | M5: ='NY不動産(総計)'!M5 -> 154.43 | N5: ='NY不動産(総計)'!N5 -> 149.67 | O5: ='NY不動産(総計)'!O5 -> 149.52 | ... S5: ='NY不動産(総計)'!S5 -> 149.39 | U5: ='NY不動産(総計)'!U5 -> 146.92 | V5: ='NY不動産(総計)'!V5 -> 148.88 | W5: ='NY不動産(総計)'!W5 -> 154.1 | X5: ='NY不動産(総計)'!X5 -> 156.63 | Y5: ='NY不動産(総計)'!Y5 -> 156.56 | Z5: ='NY不動産(総計)'!Z5 -> 153.66 | AA5: ='NY不動産(総計)'!AA5 -> 155.81 | AB5: ='NY不動産(総計)'!AB5 -> 159.88 | ... AF5: ='NY不動産(総計)'!AF5 -> 0
A6: 賃料収入(ドル) | B6: 4650 | D6: 145.16 | E6: 4500 | F6: 4500 | H6: 4500 | I6: 4575 | J6: 4575 | K6: 4575 | L6: 4575 | M6: 4575 | N6: 4575 | O6: 4575 | P6: 4575 | Q6: 4575 | R6: 4575 | S6: 4575 | U6: 4575 | V6: 4650 | W6: 4650 | X6: 4650 | Y6: 4650 | Z6: 4650 | AA6: 4650 | AB6: 4650 | AC6: 4650
A7: 減価償却費(円) | B7: 136057268 | D7: 1269867 | E7: 1269867 | F7: 1269869 | H7: 1269867 | I7: 1269867 | J7: 1269867 | K7: 1269867 | L7: 1269867 | M7: 1269872 | N7: 1269867 | O7: 1269867 | P7: 1269867 | Q7: 1269867 | R7: 1269867 | S7: 1269872 | U7: 1269867 | V7: 1269867 | W7: 1269867 | X7: 1269867 | Y7: 1269867 | Z7: 1269872 | AA7: 1269867 | AB7: 1269867 | AC7: 1269867 | AD7: 1269867 | AE7: 1269867 | AF7: 1269872
A8: 減価償却費(ドル)
A9: 残存簿価(円) | B9: 136057268 | D9: =SUM(B9-D7) -> 134787401 | E9: =SUM(D9-E7) -> 133517534 | F9: =SUM(E9-F7) -> 132247665 | H9: =SUM(F9-H7) -> 130977798 | I9: =SUM(H9-I7) -> 129707931 | J9: =SUM(I9-J7) -> 128438064 | K9: =SUM(J9-K7) -> 127168197 | L9: =SUM(K9-L7) -> 125898330 | M9: =SUM(L9-M7) -> 124628458 | N9: =SUM(M9-N7) -> 123358591 | O9: =SUM(N9-O7) -> 122088724 | P9: =SUM(O9-P7) -> 120818857 | ... S9: =SUM(R9-S7) -> 117009251 | U9: =SUM(S9-U7) -> 115739384 | V9: =SUM(U9-V7) -> 114469517 | W9: =SUM(V9-W7) -> 113199650 | X9: =SUM(W9-X7) -> 111929783 | Y9: =SUM(X9-Y7) -> 110659916 | Z9: =SUM(Y9-Z7) -> 109390044 | AA9: =SUM(Z9-AA7) -> 108120177 | AB9: =SUM(AA9-AB7) -> 106850310 | AC9: =SUM(AB9-AC7) -> 105580443 | ... AF9: =SUM(AE9-AF7) -> 101770837
A10: 残存簿価(ドル)
A11: 管理費(ドル) | F11: 270 | H11: 270 | I11: 274.5 | J11: 274.5 | K11: 274.5 | L11: 274.5 | M11: 274.5 | N11: 274.5 | O11: 274.5 | P11: 274.5 | Q11: 274.5 | R11: 274.5 | S11: 274.5 | U11: 274.5 | V11: 279 | W11: 279 | X11: 279 | Y11: 279 | Z11: 279 | AA11: 279 | AB11: 279 | AC11: 279 | AG11: =SUM(C36:AF36) -> 6066 | AH11: 管理費
A12: 諸経費(税金、募集経費等)(ドル) | B12: 16101.33 | D12: 36.56 | E12: 1133.38 | F12: 1176.9 | H12: 3932 | I12: 10500.82 | J12: 1489.41 | K12: 1189.41 | L12: 1189.41 | M12: 1189.41 | N12: 1189.41 | O12: 1308.35 | P12: 1847.28 | Q12: 1308.35 | R12: 25883.43 | S12: 1308.35 | U12: 2307 | V12: 1361.56 | W12: 1431.56 | X12: 1591.44 | Y12: 1591.44 | Z12: 1591.44 | AA12: 1591.44 | AB12: 1591.44 | AC12: 1591.44 | AG12: 16520.21 | AH12: コモンチャージ
A13: ネット賃貸収入利回り(円) | AG13: 21854.74 | AH13: 固定資産税
A14: ネット賃貸収入利回り(ドル) | AG14: 16307.52 | AH14: 修繕・雑費・その他支出
A15: 取得時簿価利回り(円) | B15: =B13/B2 -> 0 | AG15: =SUM(AG11:AG14) -> 60748.47 | AH15: 合計
A16: 取得時簿価利回り(ドル)
A17: 残存簿価利回り(円) | B17: =B13/B9 -> 0
A18: 残存簿価利回り(ドル)
A19: CF(円) | C19: =SUM(C5*C20) -> 0 | D19: =SUM(D5*D20) -> 17021.964 | E19: =SUM(E5*E20) -> 542261.48 | F19: =SUM(F5*F20) -> 465414.56 | H19: =SUM(H5*H20) -> 43150.4 | I19: =SUM(I5*I20) -> -884971.67 | J19: =SUM(J5*J20) -> 431895.87 | K19: =SUM(K5*K20) -> 468965.71 | L19: =SUM(L5*L20) -> 492112.22 | M19: =SUM(M5*M20) -> 480445.63 | N19: =SUM(N5*N20) -> 465636.84 | O19: =SUM(O5*O20) -> 447386.27 | ... S19: =SUM(S5*S20) -> 446997.29 | U19: =SUM(U5*U20) -> 292885.02 | V19: =SUM(V5*V20) -> 448045.43 | W19: =SUM(W5*W20) -> 452967.7 | X19: =SUM(X5*X20) -> 435362.48 | Y19: =SUM(Y5*Y20) -> 435167.91 | Z19: =SUM(Z5*Z20) -> 427107.19 | AA19: =SUM(AA5*AA20) -> 433083.24 | AB19: =SUM(AB5*AB20) -> 444396.05 | ... AF19: =SUM(AF5*AF20) -> 0
A20: CF(ドル) | C20: =SUM(C6-C11-C12) -> 0 | D20: =SUM(D6-D11-D12) -> 108.6 | E20: =SUM(E6-E11-E12) -> 3366.62 | F20: =SUM(F6-F11-F12) -> 3053.1 | H20: =SUM(H6-H11-H12) -> 298 | I20: =SUM(I6-I11-I12) -> -6200.32 | J20: =SUM(J6-J11-J12) -> 2811.09 | K20: =SUM(K6-K11-K12) -> 3111.09 | L20: =SUM(L6-L11-L12) -> 3111.09 | M20: =SUM(M6-M11-M12) -> 3111.09 | N20: =SUM(N6-N11-N12) -> 3111.09 | O20: =SUM(O6-O11-O12) -> 2992.15 | ... S20: =SUM(S6-S11-S12) -> 2992.15 | U20: =SUM(U6-U11-U12) -> 1993.5 | V20: =SUM(V6-V11-V12) -> 3009.44 | W20: =SUM(W6-W11-W12) -> 2939.44 | X20: =SUM(X6-X11-X12) -> 2779.56 | Y20: =SUM(Y6-Y11-Y12) -> 2779.56 | Z20: =SUM(Z6-Z11-Z12) -> 2779.56 | AA20: =SUM(AA6-AA11-AA12) -> 2779.56 | AB20: =SUM(AB6-AB11-AB12) -> 2779.56 | ... AF20: =SUM(AF6-AF11-AF12) -> 0
A21: PL(円)
A22: PL(ドル)
A24: 購入日 | B24: 45443
A25: 下記表は固都税を各月の諸経費に分散して計上した表です
A26: 88 Greenwich #3101 | B26: 2024 | C26: 45412 | D26: 45443 | E26: 45473 | F26: 45504 | G26: 2025 | H26: 45535 | I26: 45565 | J26: 45596 | K26: 45626 | L26: 45657 | M26: 45688 | N26: 45716 | O26: 45747 | P26: 45777 | Q26: 45808 | R26: 45838 | S26: 45869 | T26: 2026 | U26: 45900 | V26: 45930 | W26: 45961 | X26: 45991 | Y26: 46022 | Z26: 46053 | AA26: 46081 | AB26: 46112 | AC26: 46142 | AD26: 46173 | AE26: 46203 | AF26: 46234
A27: 取得簿価(円) | B27: =B28*150 -> 149850000
A28: 取得簿価(ドル) | B28: 999000
A29: 賃料収入(円) | B29: =B31*B30 -> 686250 | C29: =C30*C31 -> 0 | D29: =D30*D31 -> 22752.378 | E29: =E30*E31 -> 724815 | F29: =F30*F31 -> 685980 | H29: =H30*H31 -> 651600 | I29: =I30*I31 -> 652989.75 | J29: =J30*J31 -> 702903 | K29: =K30*K31 -> 689635.5 | L29: =L30*L31 -> 723673.5 | M29: =M30*M31 -> 706517.25 | N29: =N30*N31 -> 684740.25 | O29: =O30*O31 -> 684054 | ... S29: =S30*S31 -> 683459.25 | U29: =U30*U31 -> 672159 | V29: =V30*V31 -> 692292 | W29: =W30*W31 -> 716565 | X29: =X30*X31 -> 728329.5 | Y29: =Y30*Y31 -> 728004 | Z29: =Z30*Z31 -> 714519 | AA29: =AA30*AA31 -> 724516.5 | AB29: =AB30*AB31 -> 743442 | ... AF29: =AF30*AF31 -> 0
A30: 為替レート(ドル円)TTM | B30: 150 | C30: ='NY不動産(総計)'!C30 -> 156.9 | D30: ='NY不動産(総計)'!D30 -> 156.74 | E30: ='NY不動産(総計)'!E30 -> 161.07 | F30: ='NY不動産(総計)'!F30 -> 152.44 | H30: ='NY不動産(総計)'!H30 -> 144.8 | I30: ='NY不動産(総計)'!I30 -> 142.73 | J30: ='NY不動産(総計)'!J30 -> 153.64 | K30: ='NY不動産(総計)'!K30 -> 150.74 | L30: ='NY不動産(総計)'!L30 -> 158.18 | M30: ='NY不動産(総計)'!M30 -> 154.43 | N30: ='NY不動産(総計)'!N30 -> 149.67 | O30: ='NY不動産(総計)'!O30 -> 149.52 | ... S30: ='NY不動産(総計)'!S30 -> 149.39 | U30: ='NY不動産(総計)'!U30 -> 146.92 | V30: ='NY不動産(総計)'!V30 -> 148.88 | W30: ='NY不動産(総計)'!W30 -> 154.1 | X30: ='NY不動産(総計)'!X30 -> 156.63 | Y30: ='NY不動産(総計)'!Y30 -> 156.56 | Z30: ='NY不動産(総計)'!Z30 -> 153.66 | AA30: ='NY不動産(総計)'!AA30 -> 155.81 | AB30: ='NY不動産(総計)'!AB30 -> 159.88 | ... AF30: ='NY不動産(総計)'!AF30 -> 0
A31: 賃料収入(ドル) | B31: 4575 | D31: 145.16 | E31: 4500 | F31: 4500 | H31: 4500 | I31: 4575 | J31: 4575 | K31: 4575 | L31: 4575 | M31: 4575 | N31: 4575 | O31: 4575 | P31: 4575 | Q31: 4575 | R31: 4575 | S31: 4575 | U31: 4575 | V31: 4650 | W31: 4650 | X31: 4650 | Y31: 4650 | Z31: 4650 | AA31: 4650 | AB31: 4650 | AC31: 4650
A32: 減価償却費(円) | B32: 136057268 | D32: 1269867 | E32: 1269867 | F32: 1269869 | H32: 1269867 | I32: 1269867 | J32: 1269867 | K32: 1269867 | L32: 1269867 | M32: 1269872 | N32: 1269867 | O32: 1269867 | P32: 1269867 | Q32: 1269867 | R32: 1269867 | S32: 1269872 | U32: 1269867 | V32: 1269867 | W32: 1269867 | X32: 1269867 | Y32: 1269867 | Z32: 1269872 | AA32: 1269867 | AB32: 1269867 | AC32: 1269867 | AD32: 1269867 | AE32: 1269867 | AF32: 1269872
A33: 減価償却費(ドル)
A34: 残存簿価(円) | B34: 136057268 | D34: =SUM(B34-D32) -> 134787401 | E34: =SUM(D34-E32) -> 133517534 | F34: =SUM(E34-F32) -> 132247665 | H34: =SUM(F34-H32) -> 130977798 | I34: =SUM(H34-I32) -> 129707931 | J34: =SUM(I34-J32) -> 128438064 | K34: =SUM(J34-K32) -> 127168197 | L34: =SUM(K34-L32) -> 125898330 | M34: =SUM(L34-M32) -> 124628458 | N34: =SUM(M34-N32) -> 123358591 | O34: =SUM(N34-O32) -> 122088724 | P34: =SUM(O34-P32) -> 120818857 | ... S34: =SUM(R34-S32) -> 117009251 | U34: =SUM(S34-U32) -> 115739384 | V34: =SUM(U34-V32) -> 114469517 | W34: =SUM(V34-W32) -> 113199650 | X34: =SUM(W34-X32) -> 111929783 | Y34: =SUM(X34-Y32) -> 110659916 | Z34: =SUM(Y34-Z32) -> 109390044 | AA34: =SUM(Z34-AA32) -> 108120177 | AB34: =SUM(AA34-AB32) -> 106850310 | AC34: =SUM(AB34-AC32) -> 105580443 | ... AF34: =SUM(AE34-AF32) -> 101770837
A35: 残存簿価(ドル)
A36: 管理費(ドル) | F36: 270 | H36: 270 | I36: 274.5 | J36: 274.5 | K36: 274.5 | L36: 274.5 | M36: 274.5 | N36: 274.5 | O36: 274.5 | P36: 274.5 | Q36: 274.5 | R36: 274.5 | S36: 274.5 | U36: 274.5 | V36: 279 | W36: 279 | X36: 279 | Y36: 279 | Z36: 279 | AA36: 279 | AB36: 279 | AC36: 279
A37: 諸経費(税金、募集経費等)(ドル) | B37: 16101.33 | D37: 36.56 | E37: 1133.38 | F37: 1176.9 | H37: 3932 | I37: 2273.78 | J37: 2517.79 | K37: 2217.79 | L37: 2217.79 | M37: 2217.79 | N37: 2217.79 | O37: 2336.73 | P37: 2875.66 | Q37: 2336.73 | R37: 14333.98 | S37: 2358.3 | U37: 3356.95 | V37: 2411.51 | W37: 2481.51 | X37: 2641.39 | Y37: 2641.39 | Z37: 2641.39 | AA37: 2641.39 | AB37: 1049.95 | AC37: 1049.95 | AD37: 1049.95
A38: ネット賃貸収入利回り(円)
A39: ネット賃貸収入利回り(ドル)
A40: 取得時簿価利回り(円) | B40: =B38/B27 -> 0
A41: 取得時簿価利回り(ドル)
...

Sheet 93Worth#206
A1: 93 Worth Street #206 | B1: 2024 | C1: 45412 | D1: 45443 | E1: 45473 | F1: 45504 | G1: 2025 | H1: 45535 | I1: 45565 | J1: 45596 | K1: 45626 | L1: 45657 | M1: 45688 | N1: 45716 | O1: 45747 | P1: 45777 | Q1: 45808 | R1: 45838 | S1: 45869 | T1: 2026 | U1: 45900 | V1: 45930 | W1: 45961 | X1: 45991 | Y1: 46022 | Z1: 46053 | AA1: 46081 | AB1: 46112 | AC1: 46142 | AD1: 46173 | AE1: 46203 | AF1: 46234
A2: 取得簿価(円) | B2: =B3*150 -> 146559000
A3: 取得簿価(ドル) | B3: 977060
